INFO:     Will watch for changes in these directories: ['/home/partner_portal']
ERROR:    [Errno 98] Address already in use
INFO:     Will watch for changes in these directories: ['/home/partner_portal']
INFO:     Uvicorn running on http://0.0.0.0:8123 (Press CTRL+C to quit)
INFO:     Started reloader process [4923] using statreload
INFO:     Started server process [4925]
INFO:     Waiting for application startup.
INFO:     Application startup complete.
INFO:     45.114.51.250:0 - "GET / HTTP/1.1" 200 OK
INFO:     45.114.51.250:0 - "GET / HTTP/1.1" 200 OK
INFO:     45.114.51.250:0 - "GET / HTTP/1.1" 200 OK
INFO:     45.114.51.250:0 - "GET / HTTP/1.1" 200 OK
INFO:     45.114.51.250:0 - "POST /login HTTP/1.1" 500 Internal Server Error
ERROR:    Exception in ASGI application
Traceback (most recent call last):
  File "/home/partner_portal/virtual_env/lib/python3.8/site-packages/sqlalchemy/engine/base.py", line 1702, in _execute_context
    context = constructor(
  File "/home/partner_portal/virtual_env/lib/python3.8/site-packages/sqlalchemy/engine/default.py", line 1000, in _init_compiled
    self.cursor = self.create_cursor()
  File "/home/partner_portal/virtual_env/lib/python3.8/site-packages/sqlalchemy/engine/default.py", line 1348, in create_cursor
    return self.create_default_cursor()
  File "/home/partner_portal/virtual_env/lib/python3.8/site-packages/sqlalchemy/engine/default.py", line 1351, in create_default_cursor
    return self._dbapi_connection.cursor()
  File "/home/partner_portal/virtual_env/lib/python3.8/site-packages/sqlalchemy/pool/base.py", line 1083, in cursor
    return self.dbapi_connection.cursor(*args, **kwargs)
  File "/home/partner_portal/virtual_env/lib/python3.8/site-packages/mysql/connector/connection_cext.py", line 571, in cursor
    raise errors.OperationalError("MySQL Connection not available.")
mysql.connector.errors.OperationalError: MySQL Connection not available.

The above exception was the direct cause of the following exception:

Traceback (most recent call last):
  File "/home/partner_portal/virtual_env/lib/python3.8/site-packages/uvicorn/protocols/http/h11_impl.py", line 373, in run_asgi
    result = await app(self.scope, self.receive, self.send)
  File "/home/partner_portal/virtual_env/lib/python3.8/site-packages/uvicorn/middleware/proxy_headers.py", line 75, in __call__
    return await self.app(scope, receive, send)
  File "/home/partner_portal/virtual_env/lib/python3.8/site-packages/fastapi/applications.py", line 208, in __call__
    await super().__call__(scope, receive, send)
  File "/home/partner_portal/virtual_env/lib/python3.8/site-packages/starlette/applications.py", line 112, in __call__
    await self.middleware_stack(scope, receive, send)
  File "/home/partner_portal/virtual_env/lib/python3.8/site-packages/starlette/middleware/errors.py", line 181, in __call__
    raise exc
  File "/home/partner_portal/virtual_env/lib/python3.8/site-packages/starlette/middleware/errors.py", line 159, in __call__
    await self.app(scope, receive, _send)
  File "/home/partner_portal/virtual_env/lib/python3.8/site-packages/starlette/exceptions.py", line 82, in __call__
    raise exc
  File "/home/partner_portal/virtual_env/lib/python3.8/site-packages/starlette/exceptions.py", line 71, in __call__
    await self.app(scope, receive, sender)
  File "/home/partner_portal/virtual_env/lib/python3.8/site-packages/starlette/routing.py", line 656, in __call__
    await route.handle(scope, receive, send)
  File "/home/partner_portal/virtual_env/lib/python3.8/site-packages/starlette/routing.py", line 259, in handle
    await self.app(scope, receive, send)
  File "/home/partner_portal/virtual_env/lib/python3.8/site-packages/starlette/routing.py", line 61, in app
    response = await func(request)
  File "/home/partner_portal/virtual_env/lib/python3.8/site-packages/fastapi/routing.py", line 226, in app
    raw_response = await run_endpoint_function(
  File "/home/partner_portal/virtual_env/lib/python3.8/site-packages/fastapi/routing.py", line 161, in run_endpoint_function
    return await run_in_threadpool(dependant.call, **values)
  File "/home/partner_portal/virtual_env/lib/python3.8/site-packages/starlette/concurrency.py", line 39, in run_in_threadpool
    return await anyio.to_thread.run_sync(func, *args)
  File "/home/partner_portal/virtual_env/lib/python3.8/site-packages/anyio/to_thread.py", line 28, in run_sync
    return await get_asynclib().run_sync_in_worker_thread(func, *args, cancellable=cancellable,
  File "/home/partner_portal/virtual_env/lib/python3.8/site-packages/anyio/_backends/_asyncio.py", line 818, in run_sync_in_worker_thread
    return await future
  File "/home/partner_portal/virtual_env/lib/python3.8/site-packages/anyio/_backends/_asyncio.py", line 754, in run
    result = context.run(func, *args)
  File "/home/partner_portal/./main.py", line 65, in authenticate_user
    db_user = crud.get_user_by_username(db, email=user.email)
  File "/home/partner_portal/./app/crud.py", line 13, in get_user_by_username
    return db.query(models.UserInfo).filter(models.UserInfo.email == email).first()
  File "/home/partner_portal/virtual_env/lib/python3.8/site-packages/sqlalchemy/orm/query.py", line 2810, in first
    return self.limit(1)._iter().first()
  File "/home/partner_portal/virtual_env/lib/python3.8/site-packages/sqlalchemy/orm/query.py", line 2894, in _iter
    result = self.session.execute(
  File "/home/partner_portal/virtual_env/lib/python3.8/site-packages/sqlalchemy/orm/session.py", line 1689, in execute
    result = conn._execute_20(statement, params or {}, execution_options)
  File "/home/partner_portal/virtual_env/lib/python3.8/site-packages/sqlalchemy/engine/base.py", line 1614, in _execute_20
    return meth(self, args_10style, kwargs_10style, execution_options)
  File "/home/partner_portal/virtual_env/lib/python3.8/site-packages/sqlalchemy/sql/elements.py", line 325, in _execute_on_connection
    return connection._execute_clauseelement(
  File "/home/partner_portal/virtual_env/lib/python3.8/site-packages/sqlalchemy/engine/base.py", line 1481, in _execute_clauseelement
    ret = self._execute_context(
  File "/home/partner_portal/virtual_env/lib/python3.8/site-packages/sqlalchemy/engine/base.py", line 1708, in _execute_context
    self._handle_dbapi_exception(
  File "/home/partner_portal/virtual_env/lib/python3.8/site-packages/sqlalchemy/engine/base.py", line 2026, in _handle_dbapi_exception
    util.raise_(
  File "/home/partner_portal/virtual_env/lib/python3.8/site-packages/sqlalchemy/util/compat.py", line 207, in raise_
    raise exception
  File "/home/partner_portal/virtual_env/lib/python3.8/site-packages/sqlalchemy/engine/base.py", line 1702, in _execute_context
    context = constructor(
  File "/home/partner_portal/virtual_env/lib/python3.8/site-packages/sqlalchemy/engine/default.py", line 1000, in _init_compiled
    self.cursor = self.create_cursor()
  File "/home/partner_portal/virtual_env/lib/python3.8/site-packages/sqlalchemy/engine/default.py", line 1348, in create_cursor
    return self.create_default_cursor()
  File "/home/partner_portal/virtual_env/lib/python3.8/site-packages/sqlalchemy/engine/default.py", line 1351, in create_default_cursor
    return self._dbapi_connection.cursor()
  File "/home/partner_portal/virtual_env/lib/python3.8/site-packages/sqlalchemy/pool/base.py", line 1083, in cursor
    return self.dbapi_connection.cursor(*args, **kwargs)
  File "/home/partner_portal/virtual_env/lib/python3.8/site-packages/mysql/connector/connection_cext.py", line 571, in cursor
    raise errors.OperationalError("MySQL Connection not available.")
sqlalchemy.exc.OperationalError: (mysql.connector.errors.OperationalError) MySQL Connection not available.
[SQL: SELECT partners.id AS partners_id, partners.email AS partners_email, partners.name AS partners_name, partners.organization AS partners_organization, partners.password AS partners_password, partners.created_on AS partners_created_on, partners.email_varification_code AS partners_email_varification_code, partners.public_id AS partners_public_id, partners.is_active AS partners_is_active 
FROM partners 
WHERE partners.email = %(email_1)s 
 LIMIT %(param_1)s]
[parameters: [{}]]
(Background on this error at: https://sqlalche.me/e/14/e3q8)
INFO:     45.114.51.250:0 - "GET / HTTP/1.1" 200 OK
{'sub': 'd52f5c80-6ab4-489f-b2c4-c6bddd873da0'}
INFO:     45.114.51.250:0 - "POST /login HTTP/1.1" 200 OK
{'sub': 'd52f5c80-6ab4-489f-b2c4-c6bddd873da0'}
INFO:     45.114.51.250:0 - "POST /login HTTP/1.1" 200 OK
{'sub': 'd52f5c80-6ab4-489f-b2c4-c6bddd873da0'}
INFO:     45.114.51.250:0 - "POST /login HTTP/1.1" 200 OK
{'sub': 'd52f5c80-6ab4-489f-b2c4-c6bddd873da0'}
INFO:     45.114.51.250:0 - "POST /login HTTP/1.1" 200 OK
{'sub': 'd52f5c80-6ab4-489f-b2c4-c6bddd873da0'}
INFO:     45.114.51.250:0 - "POST /login HTTP/1.1" 200 OK
{'sub': 'd52f5c80-6ab4-489f-b2c4-c6bddd873da0'}
INFO:     45.114.51.250:0 - "POST /login HTTP/1.1" 200 OK
{'sub': 'd52f5c80-6ab4-489f-b2c4-c6bddd873da0'}
INFO:     45.114.51.250:0 - "POST /login HTTP/1.1" 200 OK
{'sub': 'd52f5c80-6ab4-489f-b2c4-c6bddd873da0'}
INFO:     45.114.51.250:0 - "POST /login HTTP/1.1" 200 OK
{'sub': 'd52f5c80-6ab4-489f-b2c4-c6bddd873da0'}
INFO:     45.114.51.250:0 - "POST /login HTTP/1.1" 200 OK
{'sub': 'd52f5c80-6ab4-489f-b2c4-c6bddd873da0'}
INFO:     45.114.51.250:0 - "POST /login HTTP/1.1" 200 OK
INFO:     45.114.51.250:0 - "OPTIONS / HTTP/1.1" 405 Method Not Allowed
INFO:     45.114.51.250:0 - "OPTIONS / HTTP/1.1" 405 Method Not Allowed
INFO:     45.114.51.250:0 - "OPTIONS /login HTTP/1.1" 405 Method Not Allowed
INFO:     45.114.51.250:0 - "OPTIONS /login HTTP/1.1" 405 Method Not Allowed
INFO:     45.114.51.250:0 - "OPTIONS /login HTTP/1.1" 405 Method Not Allowed
INFO:     45.114.51.250:0 - "OPTIONS /login HTTP/1.1" 405 Method Not Allowed
INFO:     45.114.51.250:0 - "OPTIONS /login HTTP/1.1" 405 Method Not Allowed
INFO:     45.114.51.250:0 - "OPTIONS /login HTTP/1.1" 405 Method Not Allowed
INFO:     45.114.51.250:0 - "OPTIONS /login HTTP/1.1" 405 Method Not Allowed
INFO:     45.114.51.250:0 - "OPTIONS /login HTTP/1.1" 405 Method Not Allowed
INFO:     45.114.51.250:0 - "OPTIONS /login HTTP/1.1" 405 Method Not Allowed
WARNING:  StatReload detected file change in 'main.py'. Reloading...
INFO:     Shutting down
INFO:     Waiting for application shutdown.
INFO:     Application shutdown complete.
INFO:     Finished server process [4925]
Process SpawnProcess-2:
Traceback (most recent call last):
  File "/usr/lib/python3.8/multiprocessing/process.py", line 315, in _bootstrap
    self.run()
  File "/usr/lib/python3.8/multiprocessing/process.py", line 108, in run
    self._target(*self._args, **self._kwargs)
  File "/home/partner_portal/virtual_env/lib/python3.8/site-packages/uvicorn/subprocess.py", line 76, in subprocess_started
    target(sockets=sockets)
  File "/home/partner_portal/virtual_env/lib/python3.8/site-packages/uvicorn/server.py", line 68, in run
    return asyncio.run(self.serve(sockets=sockets))
  File "/usr/lib/python3.8/asyncio/runners.py", line 44, in run
    return loop.run_until_complete(main)
  File "/usr/lib/python3.8/asyncio/base_events.py", line 616, in run_until_complete
    return future.result()
  File "/home/partner_portal/virtual_env/lib/python3.8/site-packages/uvicorn/server.py", line 76, in serve
    config.load()
  File "/home/partner_portal/virtual_env/lib/python3.8/site-packages/uvicorn/config.py", line 448, in load
    self.loaded_app = import_from_string(self.app)
  File "/home/partner_portal/virtual_env/lib/python3.8/site-packages/uvicorn/importer.py", line 21, in import_from_string
    module = importlib.import_module(module_str)
  File "/usr/lib/python3.8/importlib/__init__.py", line 127, in import_module
    return _bootstrap._gcd_import(name[level:], package, level)
  File "<frozen importlib._bootstrap>", line 1014, in _gcd_import
  File "<frozen importlib._bootstrap>", line 991, in _find_and_load
  File "<frozen importlib._bootstrap>", line 975, in _find_and_load_unlocked
  File "<frozen importlib._bootstrap>", line 671, in _load_unlocked
  File "<frozen importlib._bootstrap_external>", line 839, in exec_module
  File "<frozen importlib._bootstrap_external>", line 976, in get_code
  File "<frozen importlib._bootstrap_external>", line 906, in source_to_code
  File "<frozen importlib._bootstrap>", line 219, in _call_with_frames_removed
  File "/home/partner_portal/./main.py", line 20
    allow_origins=[*],
                    ^
SyntaxError: invalid syntax
WARNING:  StatReload detected file change in 'main.py'. Reloading...
INFO:     Started server process [19665]
INFO:     Waiting for application startup.
INFO:     Application startup complete.
INFO:     45.114.51.250:0 - "OPTIONS /login HTTP/1.1" 200 OK
INFO:     45.114.51.250:0 - "POST /login HTTP/1.1" 400 Bad Request
INFO:     45.114.51.250:0 - "POST /login HTTP/1.1" 400 Bad Request
INFO:     45.114.51.250:0 - "POST /login HTTP/1.1" 400 Bad Request
INFO:     45.114.51.250:0 - "POST /login HTTP/1.1" 400 Bad Request
INFO:     45.114.51.250:0 - "POST /login HTTP/1.1" 400 Bad Request
INFO:     45.114.51.250:0 - "POST /login HTTP/1.1" 400 Bad Request
INFO:     45.114.51.250:0 - "POST /login HTTP/1.1" 400 Bad Request
INFO:     45.114.51.250:0 - "OPTIONS /login HTTP/1.1" 200 OK
INFO:     45.114.51.250:0 - "POST /login HTTP/1.1" 400 Bad Request
INFO:     45.114.51.250:0 - "POST /login HTTP/1.1" 400 Bad Request
INFO:     45.114.51.250:0 - "POST /login HTTP/1.1" 400 Bad Request
INFO:     45.114.51.250:0 - "POST /login HTTP/1.1" 400 Bad Request
INFO:     45.114.51.250:0 - "POST /login HTTP/1.1" 400 Bad Request
INFO:     45.114.51.250:0 - "POST /login HTTP/1.1" 400 Bad Request
INFO:     45.114.51.250:0 - "POST /login HTTP/1.1" 400 Bad Request
INFO:     45.114.51.250:0 - "POST /login HTTP/1.1" 400 Bad Request
INFO:     45.114.51.250:0 - "POST /login HTTP/1.1" 400 Bad Request
INFO:     45.114.51.250:0 - "POST /login HTTP/1.1" 400 Bad Request
INFO:     45.114.51.250:0 - "POST /login HTTP/1.1" 400 Bad Request
INFO:     45.114.51.250:0 - "POST /login HTTP/1.1" 400 Bad Request
INFO:     45.114.51.250:0 - "POST /login HTTP/1.1" 400 Bad Request
INFO:     45.114.51.250:0 - "POST /login HTTP/1.1" 400 Bad Request
INFO:     45.114.51.250:0 - "POST /login HTTP/1.1" 400 Bad Request
INFO:     45.114.51.250:0 - "POST /login HTTP/1.1" 400 Bad Request
INFO:     45.114.51.250:0 - "POST /login HTTP/1.1" 400 Bad Request
{'sub': 'd52f5c80-6ab4-489f-b2c4-c6bddd873da0'}
INFO:     45.114.51.250:0 - "POST /login HTTP/1.1" 200 OK
INFO:     45.114.51.250:0 - "OPTIONS /login HTTP/1.1" 200 OK
INFO:     45.114.51.250:0 - "POST /login HTTP/1.1" 400 Bad Request
{'sub': 'd52f5c80-6ab4-489f-b2c4-c6bddd873da0'}
INFO:     45.114.51.250:0 - "POST /login HTTP/1.1" 200 OK
INFO:     45.114.51.250:0 - "OPTIONS /login HTTP/1.1" 200 OK
INFO:     45.114.51.250:0 - "OPTIONS /login HTTP/1.1" 200 OK
INFO:     45.114.51.250:0 - "OPTIONS /login HTTP/1.1" 200 OK
INFO:     45.114.51.250:0 - "OPTIONS /login HTTP/1.1" 200 OK
INFO:     45.114.51.250:0 - "POST /login HTTP/1.1" 400 Bad Request
INFO:     45.114.51.250:0 - "POST /login HTTP/1.1" 400 Bad Request
INFO:     45.114.51.250:0 - "POST /login HTTP/1.1" 400 Bad Request
INFO:     157.245.207.191:0 - "POST /login HTTP/1.1" 400 Bad Request
INFO:     157.245.207.191:0 - "POST /login HTTP/1.1" 400 Bad Request
INFO:     157.245.207.191:0 - "POST /login HTTP/1.1" 400 Bad Request
INFO:     157.245.207.191:0 - "POST /login HTTP/1.1" 400 Bad Request
INFO:     157.245.207.191:0 - "POST /login HTTP/1.1" 400 Bad Request
INFO:     157.245.207.191:0 - "OPTIONS /login HTTP/1.1" 200 OK
INFO:     157.245.207.191:0 - "POST /login HTTP/1.1" 400 Bad Request
INFO:     157.245.207.191:0 - "POST /login HTTP/1.1" 400 Bad Request
INFO:     157.245.207.191:0 - "POST /login HTTP/1.1" 400 Bad Request
INFO:     157.245.207.191:0 - "POST /login HTTP/1.1" 400 Bad Request
INFO:     157.245.207.191:0 - "POST /login HTTP/1.1" 400 Bad Request
INFO:     157.245.207.191:0 - "POST /login HTTP/1.1" 400 Bad Request
INFO:     157.245.207.191:0 - "POST /login HTTP/1.1" 400 Bad Request
INFO:     157.245.207.191:0 - "POST /login HTTP/1.1" 400 Bad Request
INFO:     157.245.207.191:0 - "POST /login HTTP/1.1" 400 Bad Request
INFO:     157.245.207.191:0 - "POST /login HTTP/1.1" 400 Bad Request
INFO:     157.245.207.191:0 - "POST /login HTTP/1.1" 400 Bad Request
INFO:     157.245.207.191:0 - "POST /login HTTP/1.1" 400 Bad Request
INFO:     157.245.207.191:0 - "POST /login HTTP/1.1" 400 Bad Request
INFO:     157.245.207.191:0 - "POST /login HTTP/1.1" 400 Bad Request
INFO:     157.245.207.191:0 - "POST /login HTTP/1.1" 400 Bad Request
INFO:     157.245.207.191:0 - "POST /login HTTP/1.1" 400 Bad Request
INFO:     157.245.207.191:0 - "POST /login HTTP/1.1" 400 Bad Request
INFO:     157.245.207.191:0 - "POST /login HTTP/1.1" 400 Bad Request
INFO:     157.245.207.191:0 - "POST /login HTTP/1.1" 400 Bad Request
INFO:     157.245.207.191:0 - "POST /login HTTP/1.1" 400 Bad Request
{'sub': 'd52f5c80-6ab4-489f-b2c4-c6bddd873da0'}
INFO:     45.114.51.250:0 - "POST /login HTTP/1.1" 200 OK
{'sub': 'd52f5c80-6ab4-489f-b2c4-c6bddd873da0'}
INFO:     45.114.51.250:0 - "POST /login HTTP/1.1" 200 OK
{'sub': 'd52f5c80-6ab4-489f-b2c4-c6bddd873da0'}
INFO:     45.114.51.250:0 - "POST /login HTTP/1.1" 200 OK
{'sub': 'd52f5c80-6ab4-489f-b2c4-c6bddd873da0'}
INFO:     45.114.51.250:0 - "POST /login HTTP/1.1" 200 OK
{'sub': 'd52f5c80-6ab4-489f-b2c4-c6bddd873da0'}
INFO:     45.114.51.250:0 - "POST /login HTTP/1.1" 200 OK
INFO:     45.114.51.250:0 - "OPTIONS /login HTTP/1.1" 200 OK
INFO:     45.114.51.250:0 - "POST /login HTTP/1.1" 400 Bad Request
INFO:     45.114.51.250:0 - "POST /login HTTP/1.1" 400 Bad Request
INFO:     45.114.51.250:0 - "POST /login HTTP/1.1" 400 Bad Request
INFO:     45.114.51.250:0 - "POST /login HTTP/1.1" 400 Bad Request
INFO:     45.114.51.250:0 - "POST /login HTTP/1.1" 400 Bad Request
INFO:     45.114.51.250:0 - "POST /login HTTP/1.1" 400 Bad Request
INFO:     45.114.51.250:0 - "OPTIONS /login HTTP/1.1" 200 OK
INFO:     45.114.51.250:0 - "POST /login HTTP/1.1" 400 Bad Request
{'sub': 'd52f5c80-6ab4-489f-b2c4-c6bddd873da0'}
INFO:     45.114.51.250:0 - "POST /login HTTP/1.1" 200 OK
{'sub': 'd52f5c80-6ab4-489f-b2c4-c6bddd873da0'}
INFO:     45.114.51.250:0 - "POST /login HTTP/1.1" 200 OK
{'sub': 'd52f5c80-6ab4-489f-b2c4-c6bddd873da0'}
INFO:     45.114.51.250:0 - "POST /login HTTP/1.1" 200 OK
{'sub': 'd52f5c80-6ab4-489f-b2c4-c6bddd873da0'}
INFO:     45.114.51.250:0 - "POST /login HTTP/1.1" 200 OK
INFO:     45.114.51.250:0 - "POST /login HTTP/1.1" 400 Bad Request
{'sub': 'd52f5c80-6ab4-489f-b2c4-c6bddd873da0'}
INFO:     45.114.51.250:0 - "POST /login HTTP/1.1" 200 OK
{'sub': 'd52f5c80-6ab4-489f-b2c4-c6bddd873da0'}
INFO:     45.114.51.250:0 - "POST /login HTTP/1.1" 200 OK
INFO:     45.114.51.250:0 - "POST /login HTTP/1.1" 400 Bad Request
INFO:     45.114.51.250:0 - "POST /login HTTP/1.1" 400 Bad Request
INFO:     45.114.51.250:0 - "POST /login HTTP/1.1" 400 Bad Request
INFO:     45.114.51.250:0 - "POST /login HTTP/1.1" 400 Bad Request
INFO:     45.114.51.250:0 - "POST /login HTTP/1.1" 400 Bad Request
INFO:     45.114.51.250:0 - "POST /login HTTP/1.1" 400 Bad Request
INFO:     45.114.51.250:0 - "POST /login HTTP/1.1" 400 Bad Request
INFO:     45.114.51.250:0 - "POST /login HTTP/1.1" 400 Bad Request
INFO:     45.114.51.250:0 - "POST /login HTTP/1.1" 400 Bad Request
INFO:     45.114.51.250:0 - "POST /login HTTP/1.1" 400 Bad Request
INFO:     45.114.51.250:0 - "POST /login HTTP/1.1" 400 Bad Request
INFO:     45.114.51.250:0 - "POST /login HTTP/1.1" 400 Bad Request
INFO:     45.114.51.250:0 - "POST /login HTTP/1.1" 400 Bad Request
INFO:     45.114.51.250:0 - "POST /login HTTP/1.1" 400 Bad Request
INFO:     45.114.51.250:0 - "POST /login HTTP/1.1" 400 Bad Request
{'sub': 'd52f5c80-6ab4-489f-b2c4-c6bddd873da0'}
INFO:     45.114.51.250:0 - "POST /login HTTP/1.1" 200 OK
{'sub': 'd52f5c80-6ab4-489f-b2c4-c6bddd873da0'}
INFO:     45.114.51.250:0 - "POST /login HTTP/1.1" 200 OK
{'sub': 'd52f5c80-6ab4-489f-b2c4-c6bddd873da0'}
INFO:     45.114.51.250:0 - "POST /login HTTP/1.1" 200 OK
INFO:     45.114.51.250:0 - "OPTIONS /login HTTP/1.1" 200 OK
{'sub': 'd52f5c80-6ab4-489f-b2c4-c6bddd873da0'}
INFO:     45.114.51.250:0 - "POST /login HTTP/1.1" 200 OK
{'sub': 'd52f5c80-6ab4-489f-b2c4-c6bddd873da0'}
INFO:     45.114.51.250:0 - "POST /login HTTP/1.1" 200 OK
{'sub': 'd52f5c80-6ab4-489f-b2c4-c6bddd873da0'}
INFO:     45.114.51.250:0 - "POST /login HTTP/1.1" 200 OK
{'sub': 'd52f5c80-6ab4-489f-b2c4-c6bddd873da0'}
INFO:     45.114.51.250:0 - "POST /login HTTP/1.1" 200 OK
{'sub': 'd52f5c80-6ab4-489f-b2c4-c6bddd873da0'}
INFO:     45.114.51.250:0 - "POST /login HTTP/1.1" 200 OK
{'sub': 'd52f5c80-6ab4-489f-b2c4-c6bddd873da0'}
INFO:     45.114.51.250:0 - "POST /login HTTP/1.1" 200 OK
{'sub': 'd52f5c80-6ab4-489f-b2c4-c6bddd873da0'}
INFO:     45.114.51.250:0 - "POST /login HTTP/1.1" 200 OK
{'sub': 'd52f5c80-6ab4-489f-b2c4-c6bddd873da0'}
INFO:     45.114.51.250:0 - "POST /login HTTP/1.1" 200 OK
{'sub': 'd52f5c80-6ab4-489f-b2c4-c6bddd873da0'}
INFO:     45.114.51.250:0 - "POST /login HTTP/1.1" 200 OK
{'sub': 'd52f5c80-6ab4-489f-b2c4-c6bddd873da0'}
INFO:     45.114.51.250:0 - "POST /login HTTP/1.1" 200 OK
{'sub': 'd52f5c80-6ab4-489f-b2c4-c6bddd873da0'}
INFO:     45.114.51.250:0 - "POST /login HTTP/1.1" 200 OK
{'sub': 'd52f5c80-6ab4-489f-b2c4-c6bddd873da0'}
INFO:     45.114.51.250:0 - "POST /login HTTP/1.1" 200 OK
{'sub': 'd52f5c80-6ab4-489f-b2c4-c6bddd873da0'}
INFO:     45.114.51.250:0 - "POST /login HTTP/1.1" 200 OK
{'sub': 'd52f5c80-6ab4-489f-b2c4-c6bddd873da0'}
INFO:     45.114.51.250:0 - "POST /login HTTP/1.1" 200 OK
{'sub': 'd52f5c80-6ab4-489f-b2c4-c6bddd873da0'}
INFO:     45.114.51.250:0 - "POST /login HTTP/1.1" 200 OK
{'sub': 'd52f5c80-6ab4-489f-b2c4-c6bddd873da0'}
INFO:     45.114.51.250:0 - "POST /login HTTP/1.1" 200 OK
{'sub': 'd52f5c80-6ab4-489f-b2c4-c6bddd873da0'}
INFO:     45.114.51.250:0 - "POST /login HTTP/1.1" 200 OK
{'sub': 'd52f5c80-6ab4-489f-b2c4-c6bddd873da0'}
INFO:     45.114.51.250:0 - "POST /login HTTP/1.1" 200 OK
{'sub': 'd52f5c80-6ab4-489f-b2c4-c6bddd873da0'}
INFO:     45.114.51.250:0 - "POST /login HTTP/1.1" 200 OK
{'sub': 'd52f5c80-6ab4-489f-b2c4-c6bddd873da0'}
INFO:     45.114.51.250:0 - "POST /login HTTP/1.1" 200 OK
{'sub': 'd52f5c80-6ab4-489f-b2c4-c6bddd873da0'}
INFO:     45.114.51.250:0 - "POST /login HTTP/1.1" 200 OK
{'sub': 'd52f5c80-6ab4-489f-b2c4-c6bddd873da0'}
INFO:     45.114.51.250:0 - "POST /login HTTP/1.1" 200 OK
{'sub': 'd52f5c80-6ab4-489f-b2c4-c6bddd873da0'}
INFO:     45.114.51.250:0 - "POST /login HTTP/1.1" 200 OK
{'sub': 'd52f5c80-6ab4-489f-b2c4-c6bddd873da0'}
INFO:     45.114.51.250:0 - "POST /login HTTP/1.1" 200 OK
{'sub': 'd52f5c80-6ab4-489f-b2c4-c6bddd873da0'}
INFO:     45.114.51.250:0 - "POST /login HTTP/1.1" 200 OK
{'sub': 'd52f5c80-6ab4-489f-b2c4-c6bddd873da0'}
INFO:     45.114.51.250:0 - "POST /login HTTP/1.1" 200 OK
{'sub': 'd52f5c80-6ab4-489f-b2c4-c6bddd873da0'}
INFO:     45.114.51.250:0 - "POST /login HTTP/1.1" 200 OK
INFO:     45.114.51.250:0 - "OPTIONS /login HTTP/1.1" 200 OK
{'sub': 'd52f5c80-6ab4-489f-b2c4-c6bddd873da0'}
INFO:     45.114.51.250:0 - "POST /login HTTP/1.1" 200 OK
{'sub': 'd52f5c80-6ab4-489f-b2c4-c6bddd873da0'}
INFO:     45.114.51.250:0 - "POST /login HTTP/1.1" 200 OK
{'sub': 'd52f5c80-6ab4-489f-b2c4-c6bddd873da0'}
INFO:     45.114.51.250:0 - "POST /login HTTP/1.1" 200 OK
{'sub': 'd52f5c80-6ab4-489f-b2c4-c6bddd873da0'}
INFO:     45.114.51.250:0 - "POST /login HTTP/1.1" 200 OK
{'sub': 'd52f5c80-6ab4-489f-b2c4-c6bddd873da0'}
INFO:     45.114.51.250:0 - "POST /login HTTP/1.1" 200 OK
INFO:     45.114.51.250:0 - "OPTIONS /login HTTP/1.1" 200 OK
{'sub': 'd52f5c80-6ab4-489f-b2c4-c6bddd873da0'}
INFO:     45.114.51.250:0 - "POST /login HTTP/1.1" 200 OK
{'sub': 'd52f5c80-6ab4-489f-b2c4-c6bddd873da0'}
INFO:     45.114.51.250:0 - "POST /login HTTP/1.1" 200 OK
{'sub': 'd52f5c80-6ab4-489f-b2c4-c6bddd873da0'}
INFO:     45.114.51.250:0 - "POST /login HTTP/1.1" 200 OK
{'sub': 'd52f5c80-6ab4-489f-b2c4-c6bddd873da0'}
INFO:     45.114.51.250:0 - "POST /login HTTP/1.1" 200 OK
INFO:     45.148.10.241:56224 - "GET http%3A//example.com/ HTTP/1.1" 404 Not Found
INFO:     171.25.193.25:22599 - "GET / HTTP/1.1" 200 OK
INFO:     185.220.100.254:9376 - "GET /favicon.ico HTTP/1.1" 404 Not Found
WARNING:  Invalid HTTP request received.
Traceback (most recent call last):
  File "/home/partner_portal/virtual_env/lib/python3.8/site-packages/uvicorn/protocols/http/h11_impl.py", line 136, in handle_events
    event = self.conn.next_event()
  File "/home/partner_portal/virtual_env/lib/python3.8/site-packages/h11/_connection.py", line 443, in next_event
    exc._reraise_as_remote_protocol_error()
  File "/home/partner_portal/virtual_env/lib/python3.8/site-packages/h11/_util.py", line 76, in _reraise_as_remote_protocol_error
    raise self
  File "/home/partner_portal/virtual_env/lib/python3.8/site-packages/h11/_connection.py", line 425, in next_event
    event = self._extract_next_receive_event()
  File "/home/partner_portal/virtual_env/lib/python3.8/site-packages/h11/_connection.py", line 367, in _extract_next_receive_event
    event = self._reader(self._receive_buffer)
  File "/home/partner_portal/virtual_env/lib/python3.8/site-packages/h11/_readers.py", line 68, in maybe_read_from_IDLE_client
    raise LocalProtocolError("illegal request line")
h11._util.RemoteProtocolError: illegal request line
INFO:     170.106.115.253:34630 - "GET / HTTP/1.1" 200 OK
INFO:     209.141.54.28:57434 - "GET / HTTP/1.1" 200 OK
INFO:     209.141.54.28:57434 - "GET /favicon.ico HTTP/1.1" 404 Not Found
WARNING:  Invalid HTTP request received.
Traceback (most recent call last):
  File "/home/partner_portal/virtual_env/lib/python3.8/site-packages/uvicorn/protocols/http/h11_impl.py", line 136, in handle_events
    event = self.conn.next_event()
  File "/home/partner_portal/virtual_env/lib/python3.8/site-packages/h11/_connection.py", line 443, in next_event
    exc._reraise_as_remote_protocol_error()
  File "/home/partner_portal/virtual_env/lib/python3.8/site-packages/h11/_util.py", line 76, in _reraise_as_remote_protocol_error
    raise self
  File "/home/partner_portal/virtual_env/lib/python3.8/site-packages/h11/_connection.py", line 425, in next_event
    event = self._extract_next_receive_event()
  File "/home/partner_portal/virtual_env/lib/python3.8/site-packages/h11/_connection.py", line 367, in _extract_next_receive_event
    event = self._reader(self._receive_buffer)
  File "/home/partner_portal/virtual_env/lib/python3.8/site-packages/h11/_readers.py", line 68, in maybe_read_from_IDLE_client
    raise LocalProtocolError("illegal request line")
h11._util.RemoteProtocolError: illegal request line
INFO:     103.39.242.131:0 - "GET / HTTP/1.1" 200 OK
WARNING:  StatReload detected file change in 'main.py'. Reloading...
INFO:     Shutting down
INFO:     Waiting for application shutdown.
INFO:     Application shutdown complete.
INFO:     Finished server process [19665]
INFO:     Started server process [18352]
INFO:     Waiting for application startup.
INFO:     Application startup complete.
WARNING:  StatReload detected file change in 'main.py'. Reloading...
INFO:     Shutting down
INFO:     Waiting for application shutdown.
INFO:     Application shutdown complete.
INFO:     Finished server process [18352]
INFO:     Started server process [18354]
INFO:     Waiting for application startup.
INFO:     Application startup complete.
WARNING:  StatReload detected file change in 'main.py'. Reloading...
INFO:     Shutting down
INFO:     Waiting for application shutdown.
INFO:     Application shutdown complete.
INFO:     Finished server process [18354]
INFO:     Started server process [18706]
INFO:     Waiting for application startup.
INFO:     Application startup complete.
INFO:     103.92.47.139:0 - "OPTIONS /login HTTP/1.1" 200 OK
{'sub': 'd52f5c80-6ab4-489f-b2c4-c6bddd873da0'}
INFO:     103.92.47.139:0 - "POST /login HTTP/1.1" 200 OK
{'sub': 'd52f5c80-6ab4-489f-b2c4-c6bddd873da0'}
INFO:     103.92.47.139:0 - "POST /login HTTP/1.1" 200 OK
WARNING:  Invalid HTTP request received.
Traceback (most recent call last):
  File "/home/partner_portal/virtual_env/lib/python3.8/site-packages/uvicorn/protocols/http/h11_impl.py", line 136, in handle_events
    event = self.conn.next_event()
  File "/home/partner_portal/virtual_env/lib/python3.8/site-packages/h11/_connection.py", line 443, in next_event
    exc._reraise_as_remote_protocol_error()
  File "/home/partner_portal/virtual_env/lib/python3.8/site-packages/h11/_util.py", line 76, in _reraise_as_remote_protocol_error
    raise self
  File "/home/partner_portal/virtual_env/lib/python3.8/site-packages/h11/_connection.py", line 425, in next_event
    event = self._extract_next_receive_event()
  File "/home/partner_portal/virtual_env/lib/python3.8/site-packages/h11/_connection.py", line 367, in _extract_next_receive_event
    event = self._reader(self._receive_buffer)
  File "/home/partner_portal/virtual_env/lib/python3.8/site-packages/h11/_readers.py", line 68, in maybe_read_from_IDLE_client
    raise LocalProtocolError("illegal request line")
h11._util.RemoteProtocolError: illegal request line
INFO:     162.142.125.60:54152 - "GET / HTTP/1.1" 200 OK
INFO:     162.142.125.60:37270 - "GET / HTTP/1.1" 200 OK
WARNING:  Invalid HTTP request received.
Traceback (most recent call last):
  File "/home/partner_portal/virtual_env/lib/python3.8/site-packages/uvicorn/protocols/http/h11_impl.py", line 136, in handle_events
    event = self.conn.next_event()
  File "/home/partner_portal/virtual_env/lib/python3.8/site-packages/h11/_connection.py", line 443, in next_event
    exc._reraise_as_remote_protocol_error()
  File "/home/partner_portal/virtual_env/lib/python3.8/site-packages/h11/_util.py", line 76, in _reraise_as_remote_protocol_error
    raise self
  File "/home/partner_portal/virtual_env/lib/python3.8/site-packages/h11/_connection.py", line 425, in next_event
    event = self._extract_next_receive_event()
  File "/home/partner_portal/virtual_env/lib/python3.8/site-packages/h11/_connection.py", line 367, in _extract_next_receive_event
    event = self._reader(self._receive_buffer)
  File "/home/partner_portal/virtual_env/lib/python3.8/site-packages/h11/_readers.py", line 71, in maybe_read_from_IDLE_client
    raise LocalProtocolError("no request line received")
h11._util.RemoteProtocolError: no request line received
INFO:     162.142.125.128:15026 - "GET / HTTP/1.1" 200 OK
WARNING:  Invalid HTTP request received.
Traceback (most recent call last):
  File "/home/partner_portal/virtual_env/lib/python3.8/site-packages/uvicorn/protocols/http/h11_impl.py", line 136, in handle_events
    event = self.conn.next_event()
  File "/home/partner_portal/virtual_env/lib/python3.8/site-packages/h11/_connection.py", line 443, in next_event
    exc._reraise_as_remote_protocol_error()
  File "/home/partner_portal/virtual_env/lib/python3.8/site-packages/h11/_util.py", line 76, in _reraise_as_remote_protocol_error
    raise self
  File "/home/partner_portal/virtual_env/lib/python3.8/site-packages/h11/_connection.py", line 425, in next_event
    event = self._extract_next_receive_event()
  File "/home/partner_portal/virtual_env/lib/python3.8/site-packages/h11/_connection.py", line 367, in _extract_next_receive_event
    event = self._reader(self._receive_buffer)
  File "/home/partner_portal/virtual_env/lib/python3.8/site-packages/h11/_readers.py", line 68, in maybe_read_from_IDLE_client
    raise LocalProtocolError("illegal request line")
h11._util.RemoteProtocolError: illegal request line
INFO:     23.129.64.138:1655 - "GET / HTTP/1.1" 200 OK
INFO:     185.100.87.174:39123 - "GET /favicon.ico HTTP/1.1" 404 Not Found
INFO:     222.186.19.235:51444 - "GET http%3A//fuwu.sogou.com/404/index.html HTTP/1.1" 404 Not Found
WARNING:  Invalid HTTP request received.
Traceback (most recent call last):
  File "/home/partner_portal/virtual_env/lib/python3.8/site-packages/uvicorn/protocols/http/h11_impl.py", line 136, in handle_events
    event = self.conn.next_event()
  File "/home/partner_portal/virtual_env/lib/python3.8/site-packages/h11/_connection.py", line 443, in next_event
    exc._reraise_as_remote_protocol_error()
  File "/home/partner_portal/virtual_env/lib/python3.8/site-packages/h11/_util.py", line 76, in _reraise_as_remote_protocol_error
    raise self
  File "/home/partner_portal/virtual_env/lib/python3.8/site-packages/h11/_connection.py", line 425, in next_event
    event = self._extract_next_receive_event()
  File "/home/partner_portal/virtual_env/lib/python3.8/site-packages/h11/_connection.py", line 367, in _extract_next_receive_event
    event = self._reader(self._receive_buffer)
  File "/home/partner_portal/virtual_env/lib/python3.8/site-packages/h11/_readers.py", line 68, in maybe_read_from_IDLE_client
    raise LocalProtocolError("illegal request line")
h11._util.RemoteProtocolError: illegal request line
INFO:     Will watch for changes in these directories: ['/home/partner_portal']
ERROR:    [Errno 98] Address already in use
INFO:     Will watch for changes in these directories: ['/home/partner_portal']
ERROR:    [Errno 98] Address already in use
INFO:     167.248.133.115:56508 - "GET / HTTP/1.1" 200 OK
WARNING:  Invalid HTTP request received.
Traceback (most recent call last):
  File "/home/partner_portal/virtual_env/lib/python3.8/site-packages/uvicorn/protocols/http/h11_impl.py", line 136, in handle_events
    event = self.conn.next_event()
  File "/home/partner_portal/virtual_env/lib/python3.8/site-packages/h11/_connection.py", line 443, in next_event
    exc._reraise_as_remote_protocol_error()
  File "/home/partner_portal/virtual_env/lib/python3.8/site-packages/h11/_util.py", line 76, in _reraise_as_remote_protocol_error
    raise self
  File "/home/partner_portal/virtual_env/lib/python3.8/site-packages/h11/_connection.py", line 425, in next_event
    event = self._extract_next_receive_event()
  File "/home/partner_portal/virtual_env/lib/python3.8/site-packages/h11/_connection.py", line 367, in _extract_next_receive_event
    event = self._reader(self._receive_buffer)
  File "/home/partner_portal/virtual_env/lib/python3.8/site-packages/h11/_readers.py", line 68, in maybe_read_from_IDLE_client
    raise LocalProtocolError("illegal request line")
h11._util.RemoteProtocolError: illegal request line
INFO:     185.220.101.49:25330 - "GET / HTTP/1.1" 200 OK
INFO:     171.25.193.20:15289 - "GET /favicon.ico HTTP/1.1" 404 Not Found
INFO:     167.94.138.44:40400 - "GET / HTTP/1.1" 200 OK
WARNING:  Invalid HTTP request received.
Traceback (most recent call last):
  File "/home/partner_portal/virtual_env/lib/python3.8/site-packages/uvicorn/protocols/http/h11_impl.py", line 136, in handle_events
    event = self.conn.next_event()
  File "/home/partner_portal/virtual_env/lib/python3.8/site-packages/h11/_connection.py", line 443, in next_event
    exc._reraise_as_remote_protocol_error()
  File "/home/partner_portal/virtual_env/lib/python3.8/site-packages/h11/_util.py", line 76, in _reraise_as_remote_protocol_error
    raise self
  File "/home/partner_portal/virtual_env/lib/python3.8/site-packages/h11/_connection.py", line 425, in next_event
    event = self._extract_next_receive_event()
  File "/home/partner_portal/virtual_env/lib/python3.8/site-packages/h11/_connection.py", line 367, in _extract_next_receive_event
    event = self._reader(self._receive_buffer)
  File "/home/partner_portal/virtual_env/lib/python3.8/site-packages/h11/_readers.py", line 71, in maybe_read_from_IDLE_client
    raise LocalProtocolError("no request line received")
h11._util.RemoteProtocolError: no request line received
INFO:     162.142.125.128:52824 - "GET / HTTP/1.1" 200 OK
WARNING:  Invalid HTTP request received.
Traceback (most recent call last):
  File "/home/partner_portal/virtual_env/lib/python3.8/site-packages/uvicorn/protocols/http/h11_impl.py", line 136, in handle_events
    event = self.conn.next_event()
  File "/home/partner_portal/virtual_env/lib/python3.8/site-packages/h11/_connection.py", line 443, in next_event
    exc._reraise_as_remote_protocol_error()
  File "/home/partner_portal/virtual_env/lib/python3.8/site-packages/h11/_util.py", line 76, in _reraise_as_remote_protocol_error
    raise self
  File "/home/partner_portal/virtual_env/lib/python3.8/site-packages/h11/_connection.py", line 425, in next_event
    event = self._extract_next_receive_event()
  File "/home/partner_portal/virtual_env/lib/python3.8/site-packages/h11/_connection.py", line 367, in _extract_next_receive_event
    event = self._reader(self._receive_buffer)
  File "/home/partner_portal/virtual_env/lib/python3.8/site-packages/h11/_readers.py", line 71, in maybe_read_from_IDLE_client
    raise LocalProtocolError("no request line received")
h11._util.RemoteProtocolError: no request line received
INFO:     172.104.140.107:34636 - "GET / HTTP/1.0" 200 OK
INFO:     172.104.140.107:34924 - "OPTIONS / HTTP/1.0" 405 Method Not Allowed
WARNING:  Invalid HTTP request received.
Traceback (most recent call last):
  File "/home/partner_portal/virtual_env/lib/python3.8/site-packages/uvicorn/protocols/http/h11_impl.py", line 136, in handle_events
    event = self.conn.next_event()
  File "/home/partner_portal/virtual_env/lib/python3.8/site-packages/h11/_connection.py", line 443, in next_event
    exc._reraise_as_remote_protocol_error()
  File "/home/partner_portal/virtual_env/lib/python3.8/site-packages/h11/_util.py", line 76, in _reraise_as_remote_protocol_error
    raise self
  File "/home/partner_portal/virtual_env/lib/python3.8/site-packages/h11/_connection.py", line 425, in next_event
    event = self._extract_next_receive_event()
  File "/home/partner_portal/virtual_env/lib/python3.8/site-packages/h11/_connection.py", line 367, in _extract_next_receive_event
    event = self._reader(self._receive_buffer)
  File "/home/partner_portal/virtual_env/lib/python3.8/site-packages/h11/_readers.py", line 72, in maybe_read_from_IDLE_client
    matches = validate(
  File "/home/partner_portal/virtual_env/lib/python3.8/site-packages/h11/_util.py", line 88, in validate
    raise LocalProtocolError(msg)
h11._util.RemoteProtocolError: illegal request line: bytearray(b'OPTIONS / RTSP/1.0')
WARNING:  Invalid HTTP request received.
Traceback (most recent call last):
  File "/home/partner_portal/virtual_env/lib/python3.8/site-packages/uvicorn/protocols/http/h11_impl.py", line 136, in handle_events
    event = self.conn.next_event()
  File "/home/partner_portal/virtual_env/lib/python3.8/site-packages/h11/_connection.py", line 443, in next_event
    exc._reraise_as_remote_protocol_error()
  File "/home/partner_portal/virtual_env/lib/python3.8/site-packages/h11/_util.py", line 76, in _reraise_as_remote_protocol_error
    raise self
  File "/home/partner_portal/virtual_env/lib/python3.8/site-packages/h11/_connection.py", line 425, in next_event
    event = self._extract_next_receive_event()
  File "/home/partner_portal/virtual_env/lib/python3.8/site-packages/h11/_connection.py", line 367, in _extract_next_receive_event
    event = self._reader(self._receive_buffer)
  File "/home/partner_portal/virtual_env/lib/python3.8/site-packages/h11/_readers.py", line 68, in maybe_read_from_IDLE_client
    raise LocalProtocolError("illegal request line")
h11._util.RemoteProtocolError: illegal request line
WARNING:  Invalid HTTP request received.
Traceback (most recent call last):
  File "/home/partner_portal/virtual_env/lib/python3.8/site-packages/uvicorn/protocols/http/h11_impl.py", line 136, in handle_events
    event = self.conn.next_event()
  File "/home/partner_portal/virtual_env/lib/python3.8/site-packages/h11/_connection.py", line 443, in next_event
    exc._reraise_as_remote_protocol_error()
  File "/home/partner_portal/virtual_env/lib/python3.8/site-packages/h11/_util.py", line 76, in _reraise_as_remote_protocol_error
    raise self
  File "/home/partner_portal/virtual_env/lib/python3.8/site-packages/h11/_connection.py", line 425, in next_event
    event = self._extract_next_receive_event()
  File "/home/partner_portal/virtual_env/lib/python3.8/site-packages/h11/_connection.py", line 367, in _extract_next_receive_event
    event = self._reader(self._receive_buffer)
  File "/home/partner_portal/virtual_env/lib/python3.8/site-packages/h11/_readers.py", line 68, in maybe_read_from_IDLE_client
    raise LocalProtocolError("illegal request line")
h11._util.RemoteProtocolError: illegal request line
WARNING:  Invalid HTTP request received.
Traceback (most recent call last):
  File "/home/partner_portal/virtual_env/lib/python3.8/site-packages/uvicorn/protocols/http/h11_impl.py", line 136, in handle_events
    event = self.conn.next_event()
  File "/home/partner_portal/virtual_env/lib/python3.8/site-packages/h11/_connection.py", line 443, in next_event
    exc._reraise_as_remote_protocol_error()
  File "/home/partner_portal/virtual_env/lib/python3.8/site-packages/h11/_util.py", line 76, in _reraise_as_remote_protocol_error
    raise self
  File "/home/partner_portal/virtual_env/lib/python3.8/site-packages/h11/_connection.py", line 425, in next_event
    event = self._extract_next_receive_event()
  File "/home/partner_portal/virtual_env/lib/python3.8/site-packages/h11/_connection.py", line 367, in _extract_next_receive_event
    event = self._reader(self._receive_buffer)
  File "/home/partner_portal/virtual_env/lib/python3.8/site-packages/h11/_readers.py", line 68, in maybe_read_from_IDLE_client
    raise LocalProtocolError("illegal request line")
h11._util.RemoteProtocolError: illegal request line
WARNING:  Invalid HTTP request received.
Traceback (most recent call last):
  File "/home/partner_portal/virtual_env/lib/python3.8/site-packages/uvicorn/protocols/http/h11_impl.py", line 136, in handle_events
    event = self.conn.next_event()
  File "/home/partner_portal/virtual_env/lib/python3.8/site-packages/h11/_connection.py", line 443, in next_event
    exc._reraise_as_remote_protocol_error()
  File "/home/partner_portal/virtual_env/lib/python3.8/site-packages/h11/_util.py", line 76, in _reraise_as_remote_protocol_error
    raise self
  File "/home/partner_portal/virtual_env/lib/python3.8/site-packages/h11/_connection.py", line 425, in next_event
    event = self._extract_next_receive_event()
  File "/home/partner_portal/virtual_env/lib/python3.8/site-packages/h11/_connection.py", line 367, in _extract_next_receive_event
    event = self._reader(self._receive_buffer)
  File "/home/partner_portal/virtual_env/lib/python3.8/site-packages/h11/_readers.py", line 68, in maybe_read_from_IDLE_client
    raise LocalProtocolError("illegal request line")
h11._util.RemoteProtocolError: illegal request line
WARNING:  Invalid HTTP request received.
Traceback (most recent call last):
  File "/home/partner_portal/virtual_env/lib/python3.8/site-packages/uvicorn/protocols/http/h11_impl.py", line 136, in handle_events
    event = self.conn.next_event()
  File "/home/partner_portal/virtual_env/lib/python3.8/site-packages/h11/_connection.py", line 443, in next_event
    exc._reraise_as_remote_protocol_error()
  File "/home/partner_portal/virtual_env/lib/python3.8/site-packages/h11/_util.py", line 76, in _reraise_as_remote_protocol_error
    raise self
  File "/home/partner_portal/virtual_env/lib/python3.8/site-packages/h11/_connection.py", line 425, in next_event
    event = self._extract_next_receive_event()
  File "/home/partner_portal/virtual_env/lib/python3.8/site-packages/h11/_connection.py", line 367, in _extract_next_receive_event
    event = self._reader(self._receive_buffer)
  File "/home/partner_portal/virtual_env/lib/python3.8/site-packages/h11/_readers.py", line 68, in maybe_read_from_IDLE_client
    raise LocalProtocolError("illegal request line")
h11._util.RemoteProtocolError: illegal request line
WARNING:  Invalid HTTP request received.
Traceback (most recent call last):
  File "/home/partner_portal/virtual_env/lib/python3.8/site-packages/uvicorn/protocols/http/h11_impl.py", line 136, in handle_events
    event = self.conn.next_event()
  File "/home/partner_portal/virtual_env/lib/python3.8/site-packages/h11/_connection.py", line 443, in next_event
    exc._reraise_as_remote_protocol_error()
  File "/home/partner_portal/virtual_env/lib/python3.8/site-packages/h11/_util.py", line 76, in _reraise_as_remote_protocol_error
    raise self
  File "/home/partner_portal/virtual_env/lib/python3.8/site-packages/h11/_connection.py", line 425, in next_event
    event = self._extract_next_receive_event()
  File "/home/partner_portal/virtual_env/lib/python3.8/site-packages/h11/_connection.py", line 367, in _extract_next_receive_event
    event = self._reader(self._receive_buffer)
  File "/home/partner_portal/virtual_env/lib/python3.8/site-packages/h11/_readers.py", line 72, in maybe_read_from_IDLE_client
    matches = validate(
  File "/home/partner_portal/virtual_env/lib/python3.8/site-packages/h11/_util.py", line 88, in validate
    raise LocalProtocolError(msg)
h11._util.RemoteProtocolError: illegal request line: bytearray(b'OPTIONS sip:nm SIP/2.0')
WARNING:  Invalid HTTP request received.
Traceback (most recent call last):
  File "/home/partner_portal/virtual_env/lib/python3.8/site-packages/uvicorn/protocols/http/h11_impl.py", line 136, in handle_events
    event = self.conn.next_event()
  File "/home/partner_portal/virtual_env/lib/python3.8/site-packages/h11/_connection.py", line 443, in next_event
    exc._reraise_as_remote_protocol_error()
  File "/home/partner_portal/virtual_env/lib/python3.8/site-packages/h11/_util.py", line 76, in _reraise_as_remote_protocol_error
    raise self
  File "/home/partner_portal/virtual_env/lib/python3.8/site-packages/h11/_connection.py", line 425, in next_event
    event = self._extract_next_receive_event()
  File "/home/partner_portal/virtual_env/lib/python3.8/site-packages/h11/_connection.py", line 367, in _extract_next_receive_event
    event = self._reader(self._receive_buffer)
  File "/home/partner_portal/virtual_env/lib/python3.8/site-packages/h11/_readers.py", line 68, in maybe_read_from_IDLE_client
    raise LocalProtocolError("illegal request line")
h11._util.RemoteProtocolError: illegal request line
INFO:     172.104.140.107:42740 - "GET / HTTP/1.1" 200 OK
INFO:     172.104.140.107:45368 - "GET http%3A//www.google.com HTTP/1.0" 404 Not Found
INFO:     172.104.140.107:46234 - "HEAD http%3A//www.google.com HTTP/1.0" 404 Not Found
INFO:     172.104.140.107:46460 - "CONNECT www.google.com%3A80 HTTP/1.0" 404 Not Found
INFO:     195.144.21.56:50666 - "GET / HTTP/1.1" 200 OK
INFO:     195.144.21.56:51444 - "GET /favicon.ico HTTP/1.1" 404 Not Found
WARNING:  Invalid HTTP request received.
Traceback (most recent call last):
  File "/home/partner_portal/virtual_env/lib/python3.8/site-packages/uvicorn/protocols/http/h11_impl.py", line 136, in handle_events
    event = self.conn.next_event()
  File "/home/partner_portal/virtual_env/lib/python3.8/site-packages/h11/_connection.py", line 443, in next_event
    exc._reraise_as_remote_protocol_error()
  File "/home/partner_portal/virtual_env/lib/python3.8/site-packages/h11/_util.py", line 76, in _reraise_as_remote_protocol_error
    raise self
  File "/home/partner_portal/virtual_env/lib/python3.8/site-packages/h11/_connection.py", line 425, in next_event
    event = self._extract_next_receive_event()
  File "/home/partner_portal/virtual_env/lib/python3.8/site-packages/h11/_connection.py", line 367, in _extract_next_receive_event
    event = self._reader(self._receive_buffer)
  File "/home/partner_portal/virtual_env/lib/python3.8/site-packages/h11/_readers.py", line 68, in maybe_read_from_IDLE_client
    raise LocalProtocolError("illegal request line")
h11._util.RemoteProtocolError: illegal request line
INFO:     130.211.54.158:51746 - "GET / HTTP/1.1" 200 OK
INFO:     185.220.101.188:21312 - "GET / HTTP/1.1" 200 OK
INFO:     209.141.58.146:37808 - "GET /favicon.ico HTTP/1.1" 404 Not Found
INFO:     167.248.133.116:41536 - "GET / HTTP/1.1" 200 OK
WARNING:  Invalid HTTP request received.
Traceback (most recent call last):
  File "/home/partner_portal/virtual_env/lib/python3.8/site-packages/uvicorn/protocols/http/h11_impl.py", line 136, in handle_events
    event = self.conn.next_event()
  File "/home/partner_portal/virtual_env/lib/python3.8/site-packages/h11/_connection.py", line 443, in next_event
    exc._reraise_as_remote_protocol_error()
  File "/home/partner_portal/virtual_env/lib/python3.8/site-packages/h11/_util.py", line 76, in _reraise_as_remote_protocol_error
    raise self
  File "/home/partner_portal/virtual_env/lib/python3.8/site-packages/h11/_connection.py", line 425, in next_event
    event = self._extract_next_receive_event()
  File "/home/partner_portal/virtual_env/lib/python3.8/site-packages/h11/_connection.py", line 367, in _extract_next_receive_event
    event = self._reader(self._receive_buffer)
  File "/home/partner_portal/virtual_env/lib/python3.8/site-packages/h11/_readers.py", line 68, in maybe_read_from_IDLE_client
    raise LocalProtocolError("illegal request line")
h11._util.RemoteProtocolError: illegal request line
INFO:     103.39.240.59:46881 - "GET / HTTP/1.1" 200 OK
INFO:     162.142.125.42:56664 - "GET / HTTP/1.1" 200 OK
INFO:     222.186.19.235:49774 - "GET http%3A//fuwu.sogou.com/404/index.html HTTP/1.1" 404 Not Found
WARNING:  Invalid HTTP request received.
Traceback (most recent call last):
  File "/home/partner_portal/virtual_env/lib/python3.8/site-packages/uvicorn/protocols/http/h11_impl.py", line 136, in handle_events
    event = self.conn.next_event()
  File "/home/partner_portal/virtual_env/lib/python3.8/site-packages/h11/_connection.py", line 443, in next_event
    exc._reraise_as_remote_protocol_error()
  File "/home/partner_portal/virtual_env/lib/python3.8/site-packages/h11/_util.py", line 76, in _reraise_as_remote_protocol_error
    raise self
  File "/home/partner_portal/virtual_env/lib/python3.8/site-packages/h11/_connection.py", line 425, in next_event
    event = self._extract_next_receive_event()
  File "/home/partner_portal/virtual_env/lib/python3.8/site-packages/h11/_connection.py", line 367, in _extract_next_receive_event
    event = self._reader(self._receive_buffer)
  File "/home/partner_portal/virtual_env/lib/python3.8/site-packages/h11/_readers.py", line 68, in maybe_read_from_IDLE_client
    raise LocalProtocolError("illegal request line")
h11._util.RemoteProtocolError: illegal request line
INFO:     222.186.19.235:49770 - "GET http%3A//fuwu.sogou.com/404/index.html HTTP/1.1" 404 Not Found
INFO:     185.38.175.132:35797 - "GET / HTTP/1.1" 200 OK
INFO:     185.56.80.65:46288 - "GET /favicon.ico HTTP/1.1" 404 Not Found
WARNING:  Invalid HTTP request received.
Traceback (most recent call last):
  File "/home/partner_portal/virtual_env/lib/python3.8/site-packages/uvicorn/protocols/http/h11_impl.py", line 136, in handle_events
    event = self.conn.next_event()
  File "/home/partner_portal/virtual_env/lib/python3.8/site-packages/h11/_connection.py", line 443, in next_event
    exc._reraise_as_remote_protocol_error()
  File "/home/partner_portal/virtual_env/lib/python3.8/site-packages/h11/_util.py", line 76, in _reraise_as_remote_protocol_error
    raise self
  File "/home/partner_portal/virtual_env/lib/python3.8/site-packages/h11/_connection.py", line 425, in next_event
    event = self._extract_next_receive_event()
  File "/home/partner_portal/virtual_env/lib/python3.8/site-packages/h11/_connection.py", line 367, in _extract_next_receive_event
    event = self._reader(self._receive_buffer)
  File "/home/partner_portal/virtual_env/lib/python3.8/site-packages/h11/_readers.py", line 68, in maybe_read_from_IDLE_client
    raise LocalProtocolError("illegal request line")
h11._util.RemoteProtocolError: illegal request line
INFO:     193.37.255.114:42080 - "GET / HTTP/1.1" 200 OK
INFO:     193.37.255.114:42518 - "GET /favicon.ico HTTP/1.1" 404 Not Found
WARNING:  Invalid HTTP request received.
Traceback (most recent call last):
  File "/home/partner_portal/virtual_env/lib/python3.8/site-packages/uvicorn/protocols/http/h11_impl.py", line 136, in handle_events
    event = self.conn.next_event()
  File "/home/partner_portal/virtual_env/lib/python3.8/site-packages/h11/_connection.py", line 443, in next_event
    exc._reraise_as_remote_protocol_error()
  File "/home/partner_portal/virtual_env/lib/python3.8/site-packages/h11/_util.py", line 76, in _reraise_as_remote_protocol_error
    raise self
  File "/home/partner_portal/virtual_env/lib/python3.8/site-packages/h11/_connection.py", line 425, in next_event
    event = self._extract_next_receive_event()
  File "/home/partner_portal/virtual_env/lib/python3.8/site-packages/h11/_connection.py", line 367, in _extract_next_receive_event
    event = self._reader(self._receive_buffer)
  File "/home/partner_portal/virtual_env/lib/python3.8/site-packages/h11/_readers.py", line 68, in maybe_read_from_IDLE_client
    raise LocalProtocolError("illegal request line")
h11._util.RemoteProtocolError: illegal request line
INFO:     130.211.54.158:57660 - "GET / HTTP/1.1" 200 OK
INFO:     162.142.125.44:44284 - "GET / HTTP/1.1" 200 OK
WARNING:  Invalid HTTP request received.
Traceback (most recent call last):
  File "/home/partner_portal/virtual_env/lib/python3.8/site-packages/uvicorn/protocols/http/h11_impl.py", line 136, in handle_events
    event = self.conn.next_event()
  File "/home/partner_portal/virtual_env/lib/python3.8/site-packages/h11/_connection.py", line 443, in next_event
    exc._reraise_as_remote_protocol_error()
  File "/home/partner_portal/virtual_env/lib/python3.8/site-packages/h11/_util.py", line 76, in _reraise_as_remote_protocol_error
    raise self
  File "/home/partner_portal/virtual_env/lib/python3.8/site-packages/h11/_connection.py", line 425, in next_event
    event = self._extract_next_receive_event()
  File "/home/partner_portal/virtual_env/lib/python3.8/site-packages/h11/_connection.py", line 367, in _extract_next_receive_event
    event = self._reader(self._receive_buffer)
  File "/home/partner_portal/virtual_env/lib/python3.8/site-packages/h11/_readers.py", line 68, in maybe_read_from_IDLE_client
    raise LocalProtocolError("illegal request line")
h11._util.RemoteProtocolError: illegal request line
INFO:     167.248.133.58:54354 - "GET / HTTP/1.1" 200 OK
INFO:     167.248.133.58:53888 - "GET / HTTP/1.1" 200 OK
WARNING:  Invalid HTTP request received.
Traceback (most recent call last):
  File "/home/partner_portal/virtual_env/lib/python3.8/site-packages/uvicorn/protocols/http/h11_impl.py", line 136, in handle_events
    event = self.conn.next_event()
  File "/home/partner_portal/virtual_env/lib/python3.8/site-packages/h11/_connection.py", line 443, in next_event
    exc._reraise_as_remote_protocol_error()
  File "/home/partner_portal/virtual_env/lib/python3.8/site-packages/h11/_util.py", line 76, in _reraise_as_remote_protocol_error
    raise self
  File "/home/partner_portal/virtual_env/lib/python3.8/site-packages/h11/_connection.py", line 425, in next_event
    event = self._extract_next_receive_event()
  File "/home/partner_portal/virtual_env/lib/python3.8/site-packages/h11/_connection.py", line 367, in _extract_next_receive_event
    event = self._reader(self._receive_buffer)
  File "/home/partner_portal/virtual_env/lib/python3.8/site-packages/h11/_readers.py", line 68, in maybe_read_from_IDLE_client
    raise LocalProtocolError("illegal request line")
h11._util.RemoteProtocolError: illegal request line
WARNING:  Invalid HTTP request received.
Traceback (most recent call last):
  File "/home/partner_portal/virtual_env/lib/python3.8/site-packages/uvicorn/protocols/http/h11_impl.py", line 136, in handle_events
    event = self.conn.next_event()
  File "/home/partner_portal/virtual_env/lib/python3.8/site-packages/h11/_connection.py", line 443, in next_event
    exc._reraise_as_remote_protocol_error()
  File "/home/partner_portal/virtual_env/lib/python3.8/site-packages/h11/_util.py", line 76, in _reraise_as_remote_protocol_error
    raise self
  File "/home/partner_portal/virtual_env/lib/python3.8/site-packages/h11/_connection.py", line 425, in next_event
    event = self._extract_next_receive_event()
  File "/home/partner_portal/virtual_env/lib/python3.8/site-packages/h11/_connection.py", line 367, in _extract_next_receive_event
    event = self._reader(self._receive_buffer)
  File "/home/partner_portal/virtual_env/lib/python3.8/site-packages/h11/_readers.py", line 68, in maybe_read_from_IDLE_client
    raise LocalProtocolError("illegal request line")
h11._util.RemoteProtocolError: illegal request line
WARNING:  Invalid HTTP request received.
Traceback (most recent call last):
  File "/home/partner_portal/virtual_env/lib/python3.8/site-packages/uvicorn/protocols/http/h11_impl.py", line 136, in handle_events
    event = self.conn.next_event()
  File "/home/partner_portal/virtual_env/lib/python3.8/site-packages/h11/_connection.py", line 443, in next_event
    exc._reraise_as_remote_protocol_error()
  File "/home/partner_portal/virtual_env/lib/python3.8/site-packages/h11/_util.py", line 76, in _reraise_as_remote_protocol_error
    raise self
  File "/home/partner_portal/virtual_env/lib/python3.8/site-packages/h11/_connection.py", line 425, in next_event
    event = self._extract_next_receive_event()
  File "/home/partner_portal/virtual_env/lib/python3.8/site-packages/h11/_connection.py", line 367, in _extract_next_receive_event
    event = self._reader(self._receive_buffer)
  File "/home/partner_portal/virtual_env/lib/python3.8/site-packages/h11/_readers.py", line 68, in maybe_read_from_IDLE_client
    raise LocalProtocolError("illegal request line")
h11._util.RemoteProtocolError: illegal request line
INFO:     185.220.100.251:25294 - "GET / HTTP/1.1" 200 OK
INFO:     185.220.100.250:27728 - "GET /favicon.ico HTTP/1.1" 404 Not Found
WARNING:  Invalid HTTP request received.
Traceback (most recent call last):
  File "/home/partner_portal/virtual_env/lib/python3.8/site-packages/uvicorn/protocols/http/h11_impl.py", line 136, in handle_events
    event = self.conn.next_event()
  File "/home/partner_portal/virtual_env/lib/python3.8/site-packages/h11/_connection.py", line 443, in next_event
    exc._reraise_as_remote_protocol_error()
  File "/home/partner_portal/virtual_env/lib/python3.8/site-packages/h11/_util.py", line 76, in _reraise_as_remote_protocol_error
    raise self
  File "/home/partner_portal/virtual_env/lib/python3.8/site-packages/h11/_connection.py", line 425, in next_event
    event = self._extract_next_receive_event()
  File "/home/partner_portal/virtual_env/lib/python3.8/site-packages/h11/_connection.py", line 367, in _extract_next_receive_event
    event = self._reader(self._receive_buffer)
  File "/home/partner_portal/virtual_env/lib/python3.8/site-packages/h11/_readers.py", line 71, in maybe_read_from_IDLE_client
    raise LocalProtocolError("no request line received")
h11._util.RemoteProtocolError: no request line received
INFO:     172.104.159.48:33770 - "GET / HTTP/1.0" 200 OK
INFO:     172.104.159.48:34308 - "OPTIONS / HTTP/1.0" 405 Method Not Allowed
WARNING:  Invalid HTTP request received.
Traceback (most recent call last):
  File "/home/partner_portal/virtual_env/lib/python3.8/site-packages/uvicorn/protocols/http/h11_impl.py", line 136, in handle_events
    event = self.conn.next_event()
  File "/home/partner_portal/virtual_env/lib/python3.8/site-packages/h11/_connection.py", line 443, in next_event
    exc._reraise_as_remote_protocol_error()
  File "/home/partner_portal/virtual_env/lib/python3.8/site-packages/h11/_util.py", line 76, in _reraise_as_remote_protocol_error
    raise self
  File "/home/partner_portal/virtual_env/lib/python3.8/site-packages/h11/_connection.py", line 425, in next_event
    event = self._extract_next_receive_event()
  File "/home/partner_portal/virtual_env/lib/python3.8/site-packages/h11/_connection.py", line 367, in _extract_next_receive_event
    event = self._reader(self._receive_buffer)
  File "/home/partner_portal/virtual_env/lib/python3.8/site-packages/h11/_readers.py", line 72, in maybe_read_from_IDLE_client
    matches = validate(
  File "/home/partner_portal/virtual_env/lib/python3.8/site-packages/h11/_util.py", line 88, in validate
    raise LocalProtocolError(msg)
h11._util.RemoteProtocolError: illegal request line: bytearray(b'OPTIONS / RTSP/1.0')
WARNING:  Invalid HTTP request received.
Traceback (most recent call last):
  File "/home/partner_portal/virtual_env/lib/python3.8/site-packages/uvicorn/protocols/http/h11_impl.py", line 136, in handle_events
    event = self.conn.next_event()
  File "/home/partner_portal/virtual_env/lib/python3.8/site-packages/h11/_connection.py", line 443, in next_event
    exc._reraise_as_remote_protocol_error()
  File "/home/partner_portal/virtual_env/lib/python3.8/site-packages/h11/_util.py", line 76, in _reraise_as_remote_protocol_error
    raise self
  File "/home/partner_portal/virtual_env/lib/python3.8/site-packages/h11/_connection.py", line 425, in next_event
    event = self._extract_next_receive_event()
  File "/home/partner_portal/virtual_env/lib/python3.8/site-packages/h11/_connection.py", line 367, in _extract_next_receive_event
    event = self._reader(self._receive_buffer)
  File "/home/partner_portal/virtual_env/lib/python3.8/site-packages/h11/_readers.py", line 68, in maybe_read_from_IDLE_client
    raise LocalProtocolError("illegal request line")
h11._util.RemoteProtocolError: illegal request line
WARNING:  Invalid HTTP request received.
Traceback (most recent call last):
  File "/home/partner_portal/virtual_env/lib/python3.8/site-packages/uvicorn/protocols/http/h11_impl.py", line 136, in handle_events
    event = self.conn.next_event()
  File "/home/partner_portal/virtual_env/lib/python3.8/site-packages/h11/_connection.py", line 443, in next_event
    exc._reraise_as_remote_protocol_error()
  File "/home/partner_portal/virtual_env/lib/python3.8/site-packages/h11/_util.py", line 76, in _reraise_as_remote_protocol_error
    raise self
  File "/home/partner_portal/virtual_env/lib/python3.8/site-packages/h11/_connection.py", line 425, in next_event
    event = self._extract_next_receive_event()
  File "/home/partner_portal/virtual_env/lib/python3.8/site-packages/h11/_connection.py", line 367, in _extract_next_receive_event
    event = self._reader(self._receive_buffer)
  File "/home/partner_portal/virtual_env/lib/python3.8/site-packages/h11/_readers.py", line 68, in maybe_read_from_IDLE_client
    raise LocalProtocolError("illegal request line")
h11._util.RemoteProtocolError: illegal request line
WARNING:  Invalid HTTP request received.
Traceback (most recent call last):
  File "/home/partner_portal/virtual_env/lib/python3.8/site-packages/uvicorn/protocols/http/h11_impl.py", line 136, in handle_events
    event = self.conn.next_event()
  File "/home/partner_portal/virtual_env/lib/python3.8/site-packages/h11/_connection.py", line 443, in next_event
    exc._reraise_as_remote_protocol_error()
  File "/home/partner_portal/virtual_env/lib/python3.8/site-packages/h11/_util.py", line 76, in _reraise_as_remote_protocol_error
    raise self
  File "/home/partner_portal/virtual_env/lib/python3.8/site-packages/h11/_connection.py", line 425, in next_event
    event = self._extract_next_receive_event()
  File "/home/partner_portal/virtual_env/lib/python3.8/site-packages/h11/_connection.py", line 367, in _extract_next_receive_event
    event = self._reader(self._receive_buffer)
  File "/home/partner_portal/virtual_env/lib/python3.8/site-packages/h11/_readers.py", line 68, in maybe_read_from_IDLE_client
    raise LocalProtocolError("illegal request line")
h11._util.RemoteProtocolError: illegal request line
WARNING:  Invalid HTTP request received.
Traceback (most recent call last):
  File "/home/partner_portal/virtual_env/lib/python3.8/site-packages/uvicorn/protocols/http/h11_impl.py", line 136, in handle_events
    event = self.conn.next_event()
  File "/home/partner_portal/virtual_env/lib/python3.8/site-packages/h11/_connection.py", line 443, in next_event
    exc._reraise_as_remote_protocol_error()
  File "/home/partner_portal/virtual_env/lib/python3.8/site-packages/h11/_util.py", line 76, in _reraise_as_remote_protocol_error
    raise self
  File "/home/partner_portal/virtual_env/lib/python3.8/site-packages/h11/_connection.py", line 425, in next_event
    event = self._extract_next_receive_event()
  File "/home/partner_portal/virtual_env/lib/python3.8/site-packages/h11/_connection.py", line 367, in _extract_next_receive_event
    event = self._reader(self._receive_buffer)
  File "/home/partner_portal/virtual_env/lib/python3.8/site-packages/h11/_readers.py", line 68, in maybe_read_from_IDLE_client
    raise LocalProtocolError("illegal request line")
h11._util.RemoteProtocolError: illegal request line
WARNING:  Invalid HTTP request received.
Traceback (most recent call last):
  File "/home/partner_portal/virtual_env/lib/python3.8/site-packages/uvicorn/protocols/http/h11_impl.py", line 136, in handle_events
    event = self.conn.next_event()
  File "/home/partner_portal/virtual_env/lib/python3.8/site-packages/h11/_connection.py", line 443, in next_event
    exc._reraise_as_remote_protocol_error()
  File "/home/partner_portal/virtual_env/lib/python3.8/site-packages/h11/_util.py", line 76, in _reraise_as_remote_protocol_error
    raise self
  File "/home/partner_portal/virtual_env/lib/python3.8/site-packages/h11/_connection.py", line 425, in next_event
    event = self._extract_next_receive_event()
  File "/home/partner_portal/virtual_env/lib/python3.8/site-packages/h11/_connection.py", line 367, in _extract_next_receive_event
    event = self._reader(self._receive_buffer)
  File "/home/partner_portal/virtual_env/lib/python3.8/site-packages/h11/_readers.py", line 68, in maybe_read_from_IDLE_client
    raise LocalProtocolError("illegal request line")
h11._util.RemoteProtocolError: illegal request line
WARNING:  Invalid HTTP request received.
Traceback (most recent call last):
  File "/home/partner_portal/virtual_env/lib/python3.8/site-packages/uvicorn/protocols/http/h11_impl.py", line 136, in handle_events
    event = self.conn.next_event()
  File "/home/partner_portal/virtual_env/lib/python3.8/site-packages/h11/_connection.py", line 443, in next_event
    exc._reraise_as_remote_protocol_error()
  File "/home/partner_portal/virtual_env/lib/python3.8/site-packages/h11/_util.py", line 76, in _reraise_as_remote_protocol_error
    raise self
  File "/home/partner_portal/virtual_env/lib/python3.8/site-packages/h11/_connection.py", line 425, in next_event
    event = self._extract_next_receive_event()
  File "/home/partner_portal/virtual_env/lib/python3.8/site-packages/h11/_connection.py", line 367, in _extract_next_receive_event
    event = self._reader(self._receive_buffer)
  File "/home/partner_portal/virtual_env/lib/python3.8/site-packages/h11/_readers.py", line 72, in maybe_read_from_IDLE_client
    matches = validate(
  File "/home/partner_portal/virtual_env/lib/python3.8/site-packages/h11/_util.py", line 88, in validate
    raise LocalProtocolError(msg)
h11._util.RemoteProtocolError: illegal request line: bytearray(b'OPTIONS sip:nm SIP/2.0')
WARNING:  Invalid HTTP request received.
Traceback (most recent call last):
  File "/home/partner_portal/virtual_env/lib/python3.8/site-packages/uvicorn/protocols/http/h11_impl.py", line 136, in handle_events
    event = self.conn.next_event()
  File "/home/partner_portal/virtual_env/lib/python3.8/site-packages/h11/_connection.py", line 443, in next_event
    exc._reraise_as_remote_protocol_error()
  File "/home/partner_portal/virtual_env/lib/python3.8/site-packages/h11/_util.py", line 76, in _reraise_as_remote_protocol_error
    raise self
  File "/home/partner_portal/virtual_env/lib/python3.8/site-packages/h11/_connection.py", line 425, in next_event
    event = self._extract_next_receive_event()
  File "/home/partner_portal/virtual_env/lib/python3.8/site-packages/h11/_connection.py", line 367, in _extract_next_receive_event
    event = self._reader(self._receive_buffer)
  File "/home/partner_portal/virtual_env/lib/python3.8/site-packages/h11/_readers.py", line 68, in maybe_read_from_IDLE_client
    raise LocalProtocolError("illegal request line")
h11._util.RemoteProtocolError: illegal request line
INFO:     172.104.159.48:42896 - "GET / HTTP/1.1" 200 OK
INFO:     172.104.159.48:49986 - "GET http%3A//www.google.com HTTP/1.0" 404 Not Found
INFO:     172.104.159.48:50712 - "HEAD http%3A//www.google.com HTTP/1.0" 404 Not Found
INFO:     172.104.159.48:51214 - "CONNECT www.google.com%3A80 HTTP/1.0" 404 Not Found
WARNING:  Invalid HTTP request received.
Traceback (most recent call last):
  File "/home/partner_portal/virtual_env/lib/python3.8/site-packages/uvicorn/protocols/http/h11_impl.py", line 136, in handle_events
    event = self.conn.next_event()
  File "/home/partner_portal/virtual_env/lib/python3.8/site-packages/h11/_connection.py", line 443, in next_event
    exc._reraise_as_remote_protocol_error()
  File "/home/partner_portal/virtual_env/lib/python3.8/site-packages/h11/_util.py", line 76, in _reraise_as_remote_protocol_error
    raise self
  File "/home/partner_portal/virtual_env/lib/python3.8/site-packages/h11/_connection.py", line 425, in next_event
    event = self._extract_next_receive_event()
  File "/home/partner_portal/virtual_env/lib/python3.8/site-packages/h11/_connection.py", line 367, in _extract_next_receive_event
    event = self._reader(self._receive_buffer)
  File "/home/partner_portal/virtual_env/lib/python3.8/site-packages/h11/_readers.py", line 68, in maybe_read_from_IDLE_client
    raise LocalProtocolError("illegal request line")
h11._util.RemoteProtocolError: illegal request line
INFO:     43.131.91.178:26858 - "GET / HTTP/1.1" 200 OK
INFO:     209.141.36.112:52398 - "GET / HTTP/1.1" 200 OK
INFO:     209.141.36.112:52398 - "GET /favicon.ico HTTP/1.1" 404 Not Found
INFO:     167.248.133.113:51630 - "GET / HTTP/1.1" 200 OK
WARNING:  Invalid HTTP request received.
Traceback (most recent call last):
  File "/home/partner_portal/virtual_env/lib/python3.8/site-packages/uvicorn/protocols/http/h11_impl.py", line 136, in handle_events
    event = self.conn.next_event()
  File "/home/partner_portal/virtual_env/lib/python3.8/site-packages/h11/_connection.py", line 443, in next_event
    exc._reraise_as_remote_protocol_error()
  File "/home/partner_portal/virtual_env/lib/python3.8/site-packages/h11/_util.py", line 76, in _reraise_as_remote_protocol_error
    raise self
  File "/home/partner_portal/virtual_env/lib/python3.8/site-packages/h11/_connection.py", line 425, in next_event
    event = self._extract_next_receive_event()
  File "/home/partner_portal/virtual_env/lib/python3.8/site-packages/h11/_connection.py", line 367, in _extract_next_receive_event
    event = self._reader(self._receive_buffer)
  File "/home/partner_portal/virtual_env/lib/python3.8/site-packages/h11/_readers.py", line 68, in maybe_read_from_IDLE_client
    raise LocalProtocolError("illegal request line")
h11._util.RemoteProtocolError: illegal request line
WARNING:  Invalid HTTP request received.
Traceback (most recent call last):
  File "/home/partner_portal/virtual_env/lib/python3.8/site-packages/uvicorn/protocols/http/h11_impl.py", line 136, in handle_events
    event = self.conn.next_event()
  File "/home/partner_portal/virtual_env/lib/python3.8/site-packages/h11/_connection.py", line 443, in next_event
    exc._reraise_as_remote_protocol_error()
  File "/home/partner_portal/virtual_env/lib/python3.8/site-packages/h11/_util.py", line 76, in _reraise_as_remote_protocol_error
    raise self
  File "/home/partner_portal/virtual_env/lib/python3.8/site-packages/h11/_connection.py", line 425, in next_event
    event = self._extract_next_receive_event()
  File "/home/partner_portal/virtual_env/lib/python3.8/site-packages/h11/_connection.py", line 367, in _extract_next_receive_event
    event = self._reader(self._receive_buffer)
  File "/home/partner_portal/virtual_env/lib/python3.8/site-packages/h11/_readers.py", line 75, in maybe_read_from_IDLE_client
    return Request(
  File "/home/partner_portal/virtual_env/lib/python3.8/site-packages/h11/_events.py", line 71, in __init__
    self._validate()
  File "/home/partner_portal/virtual_env/lib/python3.8/site-packages/h11/_events.py", line 140, in _validate
    raise LocalProtocolError("Missing mandatory Host: header")
h11._util.RemoteProtocolError: Missing mandatory Host: header
WARNING:  Invalid HTTP request received.
Traceback (most recent call last):
  File "/home/partner_portal/virtual_env/lib/python3.8/site-packages/uvicorn/protocols/http/h11_impl.py", line 136, in handle_events
    event = self.conn.next_event()
  File "/home/partner_portal/virtual_env/lib/python3.8/site-packages/h11/_connection.py", line 443, in next_event
    exc._reraise_as_remote_protocol_error()
  File "/home/partner_portal/virtual_env/lib/python3.8/site-packages/h11/_util.py", line 76, in _reraise_as_remote_protocol_error
    raise self
  File "/home/partner_portal/virtual_env/lib/python3.8/site-packages/h11/_connection.py", line 425, in next_event
    event = self._extract_next_receive_event()
  File "/home/partner_portal/virtual_env/lib/python3.8/site-packages/h11/_connection.py", line 367, in _extract_next_receive_event
    event = self._reader(self._receive_buffer)
  File "/home/partner_portal/virtual_env/lib/python3.8/site-packages/h11/_readers.py", line 68, in maybe_read_from_IDLE_client
    raise LocalProtocolError("illegal request line")
h11._util.RemoteProtocolError: illegal request line
WARNING:  Invalid HTTP request received.
Traceback (most recent call last):
  File "/home/partner_portal/virtual_env/lib/python3.8/site-packages/uvicorn/protocols/http/h11_impl.py", line 136, in handle_events
    event = self.conn.next_event()
  File "/home/partner_portal/virtual_env/lib/python3.8/site-packages/h11/_connection.py", line 443, in next_event
    exc._reraise_as_remote_protocol_error()
  File "/home/partner_portal/virtual_env/lib/python3.8/site-packages/h11/_util.py", line 76, in _reraise_as_remote_protocol_error
    raise self
  File "/home/partner_portal/virtual_env/lib/python3.8/site-packages/h11/_connection.py", line 425, in next_event
    event = self._extract_next_receive_event()
  File "/home/partner_portal/virtual_env/lib/python3.8/site-packages/h11/_connection.py", line 367, in _extract_next_receive_event
    event = self._reader(self._receive_buffer)
  File "/home/partner_portal/virtual_env/lib/python3.8/site-packages/h11/_readers.py", line 68, in maybe_read_from_IDLE_client
    raise LocalProtocolError("illegal request line")
h11._util.RemoteProtocolError: illegal request line
INFO:     222.186.19.235:55908 - "GET http%3A//fuwu.sogou.com/404/index.html HTTP/1.1" 404 Not Found
INFO:     222.186.19.235:55946 - "GET http%3A//fuwu.sogou.com/404/index.html HTTP/1.1" 404 Not Found
WARNING:  Invalid HTTP request received.
Traceback (most recent call last):
  File "/home/partner_portal/virtual_env/lib/python3.8/site-packages/uvicorn/protocols/http/h11_impl.py", line 136, in handle_events
    event = self.conn.next_event()
  File "/home/partner_portal/virtual_env/lib/python3.8/site-packages/h11/_connection.py", line 443, in next_event
    exc._reraise_as_remote_protocol_error()
  File "/home/partner_portal/virtual_env/lib/python3.8/site-packages/h11/_util.py", line 76, in _reraise_as_remote_protocol_error
    raise self
  File "/home/partner_portal/virtual_env/lib/python3.8/site-packages/h11/_connection.py", line 425, in next_event
    event = self._extract_next_receive_event()
  File "/home/partner_portal/virtual_env/lib/python3.8/site-packages/h11/_connection.py", line 367, in _extract_next_receive_event
    event = self._reader(self._receive_buffer)
  File "/home/partner_portal/virtual_env/lib/python3.8/site-packages/h11/_readers.py", line 68, in maybe_read_from_IDLE_client
    raise LocalProtocolError("illegal request line")
h11._util.RemoteProtocolError: illegal request line
INFO:     205.185.117.149:32892 - "GET / HTTP/1.1" 200 OK
INFO:     185.220.101.174:10394 - "GET /favicon.ico HTTP/1.1" 404 Not Found
INFO:     167.94.138.57:53698 - "GET / HTTP/1.1" 200 OK
INFO:     162.142.125.195:50488 - "GET / HTTP/1.1" 200 OK
INFO:     45.12.134.108:56930 - "GET / HTTP/1.1" 200 OK
INFO:     45.129.56.200:49432 - "GET /favicon.ico HTTP/1.1" 404 Not Found
INFO:     167.94.138.44:41300 - "GET / HTTP/1.1" 200 OK
WARNING:  Invalid HTTP request received.
Traceback (most recent call last):
  File "/home/partner_portal/virtual_env/lib/python3.8/site-packages/uvicorn/protocols/http/h11_impl.py", line 136, in handle_events
    event = self.conn.next_event()
  File "/home/partner_portal/virtual_env/lib/python3.8/site-packages/h11/_connection.py", line 443, in next_event
    exc._reraise_as_remote_protocol_error()
  File "/home/partner_portal/virtual_env/lib/python3.8/site-packages/h11/_util.py", line 76, in _reraise_as_remote_protocol_error
    raise self
  File "/home/partner_portal/virtual_env/lib/python3.8/site-packages/h11/_connection.py", line 425, in next_event
    event = self._extract_next_receive_event()
  File "/home/partner_portal/virtual_env/lib/python3.8/site-packages/h11/_connection.py", line 367, in _extract_next_receive_event
    event = self._reader(self._receive_buffer)
  File "/home/partner_portal/virtual_env/lib/python3.8/site-packages/h11/_readers.py", line 68, in maybe_read_from_IDLE_client
    raise LocalProtocolError("illegal request line")
h11._util.RemoteProtocolError: illegal request line
INFO:     167.94.138.43:42032 - "GET / HTTP/1.1" 200 OK
INFO:     167.94.138.43:40660 - "GET / HTTP/1.1" 200 OK
INFO:     185.220.101.37:18172 - "GET / HTTP/1.1" 200 OK
INFO:     185.220.101.141:16932 - "GET /favicon.ico HTTP/1.1" 404 Not Found
INFO:     162.142.125.41:58158 - "GET / HTTP/1.1" 200 OK
WARNING:  Invalid HTTP request received.
Traceback (most recent call last):
  File "/home/partner_portal/virtual_env/lib/python3.8/site-packages/uvicorn/protocols/http/h11_impl.py", line 136, in handle_events
    event = self.conn.next_event()
  File "/home/partner_portal/virtual_env/lib/python3.8/site-packages/h11/_connection.py", line 443, in next_event
    exc._reraise_as_remote_protocol_error()
  File "/home/partner_portal/virtual_env/lib/python3.8/site-packages/h11/_util.py", line 76, in _reraise_as_remote_protocol_error
    raise self
  File "/home/partner_portal/virtual_env/lib/python3.8/site-packages/h11/_connection.py", line 425, in next_event
    event = self._extract_next_receive_event()
  File "/home/partner_portal/virtual_env/lib/python3.8/site-packages/h11/_connection.py", line 367, in _extract_next_receive_event
    event = self._reader(self._receive_buffer)
  File "/home/partner_portal/virtual_env/lib/python3.8/site-packages/h11/_readers.py", line 68, in maybe_read_from_IDLE_client
    raise LocalProtocolError("illegal request line")
h11._util.RemoteProtocolError: illegal request line
INFO:     222.186.19.235:34372 - "GET http%3A//fuwu.sogou.com/404/index.html HTTP/1.1" 404 Not Found
WARNING:  Invalid HTTP request received.
Traceback (most recent call last):
  File "/home/partner_portal/virtual_env/lib/python3.8/site-packages/uvicorn/protocols/http/h11_impl.py", line 136, in handle_events
    event = self.conn.next_event()
  File "/home/partner_portal/virtual_env/lib/python3.8/site-packages/h11/_connection.py", line 443, in next_event
    exc._reraise_as_remote_protocol_error()
  File "/home/partner_portal/virtual_env/lib/python3.8/site-packages/h11/_util.py", line 76, in _reraise_as_remote_protocol_error
    raise self
  File "/home/partner_portal/virtual_env/lib/python3.8/site-packages/h11/_connection.py", line 425, in next_event
    event = self._extract_next_receive_event()
  File "/home/partner_portal/virtual_env/lib/python3.8/site-packages/h11/_connection.py", line 367, in _extract_next_receive_event
    event = self._reader(self._receive_buffer)
  File "/home/partner_portal/virtual_env/lib/python3.8/site-packages/h11/_readers.py", line 68, in maybe_read_from_IDLE_client
    raise LocalProtocolError("illegal request line")
h11._util.RemoteProtocolError: illegal request line
INFO:     222.186.19.235:34424 - "GET http%3A//fuwu.sogou.com/404/index.html HTTP/1.1" 404 Not Found
INFO:     45.154.255.147:36468 - "GET / HTTP/1.1" 200 OK
INFO:     45.154.255.147:53964 - "GET /favicon.ico HTTP/1.1" 404 Not Found
INFO:     183.136.225.42:2744 - "GET / HTTP/1.1" 200 OK
INFO:     183.136.225.42:14751 - "GET /favicon.ico HTTP/1.1" 404 Not Found
WARNING:  Invalid HTTP request received.
Traceback (most recent call last):
  File "/home/partner_portal/virtual_env/lib/python3.8/site-packages/uvicorn/protocols/http/h11_impl.py", line 136, in handle_events
    event = self.conn.next_event()
  File "/home/partner_portal/virtual_env/lib/python3.8/site-packages/h11/_connection.py", line 443, in next_event
    exc._reraise_as_remote_protocol_error()
  File "/home/partner_portal/virtual_env/lib/python3.8/site-packages/h11/_util.py", line 76, in _reraise_as_remote_protocol_error
    raise self
  File "/home/partner_portal/virtual_env/lib/python3.8/site-packages/h11/_connection.py", line 425, in next_event
    event = self._extract_next_receive_event()
  File "/home/partner_portal/virtual_env/lib/python3.8/site-packages/h11/_connection.py", line 367, in _extract_next_receive_event
    event = self._reader(self._receive_buffer)
  File "/home/partner_portal/virtual_env/lib/python3.8/site-packages/h11/_readers.py", line 68, in maybe_read_from_IDLE_client
    raise LocalProtocolError("illegal request line")
h11._util.RemoteProtocolError: illegal request line
INFO:     162.142.125.43:33382 - "GET / HTTP/1.1" 200 OK
INFO:     162.142.125.42:48330 - "GET / HTTP/1.1" 200 OK
WARNING:  Invalid HTTP request received.
Traceback (most recent call last):
  File "/home/partner_portal/virtual_env/lib/python3.8/site-packages/uvicorn/protocols/http/h11_impl.py", line 136, in handle_events
    event = self.conn.next_event()
  File "/home/partner_portal/virtual_env/lib/python3.8/site-packages/h11/_connection.py", line 443, in next_event
    exc._reraise_as_remote_protocol_error()
  File "/home/partner_portal/virtual_env/lib/python3.8/site-packages/h11/_util.py", line 76, in _reraise_as_remote_protocol_error
    raise self
  File "/home/partner_portal/virtual_env/lib/python3.8/site-packages/h11/_connection.py", line 425, in next_event
    event = self._extract_next_receive_event()
  File "/home/partner_portal/virtual_env/lib/python3.8/site-packages/h11/_connection.py", line 367, in _extract_next_receive_event
    event = self._reader(self._receive_buffer)
  File "/home/partner_portal/virtual_env/lib/python3.8/site-packages/h11/_readers.py", line 68, in maybe_read_from_IDLE_client
    raise LocalProtocolError("illegal request line")
h11._util.RemoteProtocolError: illegal request line
INFO:     45.12.134.108:52736 - "GET / HTTP/1.1" 200 OK
INFO:     185.100.87.174:37265 - "GET /favicon.ico HTTP/1.1" 404 Not Found
INFO:     167.248.133.115:52410 - "GET / HTTP/1.1" 200 OK
INFO:     103.39.240.122:0 - "GET /login HTTP/1.1" 405 Method Not Allowed
INFO:     103.39.240.122:0 - "GET /login HTTP/1.1" 405 Method Not Allowed
INFO:     103.39.240.122:0 - "GET /login HTTP/1.1" 405 Method Not Allowed
INFO:     103.39.240.122:0 - "GET / HTTP/1.1" 200 OK
INFO:     103.39.240.122:0 - "GET / HTTP/1.1" 200 OK
INFO:     103.39.240.122:0 - "GET / HTTP/1.1" 200 OK
INFO:     103.39.240.122:0 - "GET / HTTP/1.1" 200 OK
INFO:     103.39.240.122:0 - "GET / HTTP/1.1" 200 OK
INFO:     103.39.240.122:0 - "GET / HTTP/1.1" 200 OK
INFO:     103.39.240.122:0 - "OPTIONS /login HTTP/1.1" 200 OK
INFO:     103.39.240.122:0 - "POST /login HTTP/1.1" 500 Internal Server Error
ERROR:    Exception in ASGI application
Traceback (most recent call last):
  File "/home/partner_portal/virtual_env/lib/python3.8/site-packages/sqlalchemy/engine/base.py", line 1702, in _execute_context
    context = constructor(
  File "/home/partner_portal/virtual_env/lib/python3.8/site-packages/sqlalchemy/engine/default.py", line 1000, in _init_compiled
    self.cursor = self.create_cursor()
  File "/home/partner_portal/virtual_env/lib/python3.8/site-packages/sqlalchemy/engine/default.py", line 1348, in create_cursor
    return self.create_default_cursor()
  File "/home/partner_portal/virtual_env/lib/python3.8/site-packages/sqlalchemy/engine/default.py", line 1351, in create_default_cursor
    return self._dbapi_connection.cursor()
  File "/home/partner_portal/virtual_env/lib/python3.8/site-packages/sqlalchemy/pool/base.py", line 1083, in cursor
    return self.dbapi_connection.cursor(*args, **kwargs)
  File "/home/partner_portal/virtual_env/lib/python3.8/site-packages/mysql/connector/connection_cext.py", line 571, in cursor
    raise errors.OperationalError("MySQL Connection not available.")
mysql.connector.errors.OperationalError: MySQL Connection not available.

The above exception was the direct cause of the following exception:

Traceback (most recent call last):
  File "/home/partner_portal/virtual_env/lib/python3.8/site-packages/uvicorn/protocols/http/h11_impl.py", line 373, in run_asgi
    result = await app(self.scope, self.receive, self.send)
  File "/home/partner_portal/virtual_env/lib/python3.8/site-packages/uvicorn/middleware/proxy_headers.py", line 75, in __call__
    return await self.app(scope, receive, send)
  File "/home/partner_portal/virtual_env/lib/python3.8/site-packages/fastapi/applications.py", line 208, in __call__
    await super().__call__(scope, receive, send)
  File "/home/partner_portal/virtual_env/lib/python3.8/site-packages/starlette/applications.py", line 112, in __call__
    await self.middleware_stack(scope, receive, send)
  File "/home/partner_portal/virtual_env/lib/python3.8/site-packages/starlette/middleware/errors.py", line 181, in __call__
    raise exc
  File "/home/partner_portal/virtual_env/lib/python3.8/site-packages/starlette/middleware/errors.py", line 159, in __call__
    await self.app(scope, receive, _send)
  File "/home/partner_portal/virtual_env/lib/python3.8/site-packages/starlette/middleware/cors.py", line 92, in __call__
    await self.simple_response(scope, receive, send, request_headers=headers)
  File "/home/partner_portal/virtual_env/lib/python3.8/site-packages/starlette/middleware/cors.py", line 147, in simple_response
    await self.app(scope, receive, send)
  File "/home/partner_portal/virtual_env/lib/python3.8/site-packages/starlette/exceptions.py", line 82, in __call__
    raise exc
  File "/home/partner_portal/virtual_env/lib/python3.8/site-packages/starlette/exceptions.py", line 71, in __call__
    await self.app(scope, receive, sender)
  File "/home/partner_portal/virtual_env/lib/python3.8/site-packages/starlette/routing.py", line 656, in __call__
    await route.handle(scope, receive, send)
  File "/home/partner_portal/virtual_env/lib/python3.8/site-packages/starlette/routing.py", line 259, in handle
    await self.app(scope, receive, send)
  File "/home/partner_portal/virtual_env/lib/python3.8/site-packages/starlette/routing.py", line 61, in app
    response = await func(request)
  File "/home/partner_portal/virtual_env/lib/python3.8/site-packages/fastapi/routing.py", line 226, in app
    raw_response = await run_endpoint_function(
  File "/home/partner_portal/virtual_env/lib/python3.8/site-packages/fastapi/routing.py", line 161, in run_endpoint_function
    return await run_in_threadpool(dependant.call, **values)
  File "/home/partner_portal/virtual_env/lib/python3.8/site-packages/starlette/concurrency.py", line 39, in run_in_threadpool
    return await anyio.to_thread.run_sync(func, *args)
  File "/home/partner_portal/virtual_env/lib/python3.8/site-packages/anyio/to_thread.py", line 28, in run_sync
    return await get_asynclib().run_sync_in_worker_thread(func, *args, cancellable=cancellable,
  File "/home/partner_portal/virtual_env/lib/python3.8/site-packages/anyio/_backends/_asyncio.py", line 818, in run_sync_in_worker_thread
    return await future
  File "/home/partner_portal/virtual_env/lib/python3.8/site-packages/anyio/_backends/_asyncio.py", line 754, in run
    result = context.run(func, *args)
  File "/home/partner_portal/./main.py", line 74, in authenticate_user
    db_user = crud.get_user_by_username(db, email=user.email)
  File "/home/partner_portal/./app/crud.py", line 13, in get_user_by_username
    return db.query(models.UserInfo).filter(models.UserInfo.email == email).first()
  File "/home/partner_portal/virtual_env/lib/python3.8/site-packages/sqlalchemy/orm/query.py", line 2810, in first
    return self.limit(1)._iter().first()
  File "/home/partner_portal/virtual_env/lib/python3.8/site-packages/sqlalchemy/orm/query.py", line 2894, in _iter
    result = self.session.execute(
  File "/home/partner_portal/virtual_env/lib/python3.8/site-packages/sqlalchemy/orm/session.py", line 1689, in execute
    result = conn._execute_20(statement, params or {}, execution_options)
  File "/home/partner_portal/virtual_env/lib/python3.8/site-packages/sqlalchemy/engine/base.py", line 1614, in _execute_20
    return meth(self, args_10style, kwargs_10style, execution_options)
  File "/home/partner_portal/virtual_env/lib/python3.8/site-packages/sqlalchemy/sql/elements.py", line 325, in _execute_on_connection
    return connection._execute_clauseelement(
  File "/home/partner_portal/virtual_env/lib/python3.8/site-packages/sqlalchemy/engine/base.py", line 1481, in _execute_clauseelement
    ret = self._execute_context(
  File "/home/partner_portal/virtual_env/lib/python3.8/site-packages/sqlalchemy/engine/base.py", line 1708, in _execute_context
    self._handle_dbapi_exception(
  File "/home/partner_portal/virtual_env/lib/python3.8/site-packages/sqlalchemy/engine/base.py", line 2026, in _handle_dbapi_exception
    util.raise_(
  File "/home/partner_portal/virtual_env/lib/python3.8/site-packages/sqlalchemy/util/compat.py", line 207, in raise_
    raise exception
  File "/home/partner_portal/virtual_env/lib/python3.8/site-packages/sqlalchemy/engine/base.py", line 1702, in _execute_context
    context = constructor(
  File "/home/partner_portal/virtual_env/lib/python3.8/site-packages/sqlalchemy/engine/default.py", line 1000, in _init_compiled
    self.cursor = self.create_cursor()
  File "/home/partner_portal/virtual_env/lib/python3.8/site-packages/sqlalchemy/engine/default.py", line 1348, in create_cursor
    return self.create_default_cursor()
  File "/home/partner_portal/virtual_env/lib/python3.8/site-packages/sqlalchemy/engine/default.py", line 1351, in create_default_cursor
    return self._dbapi_connection.cursor()
  File "/home/partner_portal/virtual_env/lib/python3.8/site-packages/sqlalchemy/pool/base.py", line 1083, in cursor
    return self.dbapi_connection.cursor(*args, **kwargs)
  File "/home/partner_portal/virtual_env/lib/python3.8/site-packages/mysql/connector/connection_cext.py", line 571, in cursor
    raise errors.OperationalError("MySQL Connection not available.")
sqlalchemy.exc.OperationalError: (mysql.connector.errors.OperationalError) MySQL Connection not available.
[SQL: SELECT partners.id AS partners_id, partners.email AS partners_email, partners.name AS partners_name, partners.organization AS partners_organization, partners.password AS partners_password, partners.created_on AS partners_created_on, partners.email_varification_code AS partners_email_varification_code, partners.public_id AS partners_public_id, partners.is_active AS partners_is_active 
FROM partners 
WHERE partners.email = %(email_1)s 
 LIMIT %(param_1)s]
[parameters: [{}]]
(Background on this error at: https://sqlalche.me/e/14/e3q8)
INFO:     3.84.117.116:0 - "GET / HTTP/1.1" 200 OK
INFO:     3.84.117.116:0 - "GET / HTTP/1.1" 200 OK
INFO:     3.84.117.116:0 - "GET / HTTP/1.1" 200 OK
INFO:     3.84.117.116:0 - "GET / HTTP/1.1" 200 OK
INFO:     3.84.117.116:0 - "GET / HTTP/1.1" 200 OK
INFO:     3.84.117.116:0 - "GET / HTTP/1.1" 200 OK
INFO:     45.146.165.37:0 - "GET /vendor/phpunit/phpunit/src/Util/PHP/eval-stdin.php HTTP/1.1" 404 Not Found
INFO:     88.80.184.191:0 - "GET / HTTP/1.1" 200 OK
INFO:     52.152.137.44:0 - "GET /.env HTTP/1.1" 404 Not Found
INFO:     52.152.137.44:0 - "POST / HTTP/1.1" 405 Method Not Allowed
INFO:     45.146.165.37:0 - "GET /index.php?s=/Index/\think\app/invokefunction&function=call_user_func_array&vars[0]=md5&vars[1][]=HelloThinkPHP21 HTTP/1.1" 404 Not Found
INFO:     20.124.220.238:0 - "GET /.env HTTP/1.1" 404 Not Found
INFO:     20.124.220.238:0 - "POST / HTTP/1.1" 405 Method Not Allowed
INFO:     3.250.228.215:0 - "GET / HTTP/1.1" 200 OK
INFO:     3.250.228.215:0 - "GET /favicon.ico HTTP/1.1" 404 Not Found
INFO:     45.146.165.37:0 - "GET /?XDEBUG_SESSION_START=phpstorm HTTP/1.1" 200 OK
INFO:     162.142.125.194:0 - "GET / HTTP/1.1" 200 OK
INFO:     162.142.125.194:0 - "GET / HTTP/1.1" 200 OK
INFO:     40.121.23.141:0 - "GET /.env HTTP/1.1" 404 Not Found
INFO:     40.121.23.141:0 - "POST / HTTP/1.1" 405 Method Not Allowed
INFO:     45.146.165.37:0 - "POST /mifs/.%3B/services/LogService HTTP/1.1" 404 Not Found
INFO:     89.104.111.15:0 - "GET / HTTP/1.1" 200 OK
INFO:     89.104.111.15:0 - "GET /favicon.ico HTTP/1.1" 404 Not Found
INFO:     176.53.222.79:0 - "GET / HTTP/1.1" 200 OK
INFO:     176.53.222.79:0 - "GET /favicon.ico HTTP/1.1" 404 Not Found
INFO:     89.104.111.15:0 - "GET /favicon.ico HTTP/1.1" 404 Not Found
INFO:     45.146.165.37:0 - "GET /console/ HTTP/1.1" 404 Not Found
INFO:     109.237.103.9:0 - "GET /.env HTTP/1.1" 404 Not Found
INFO:     45.146.165.37:0 - "POST /Autodiscover/Autodiscover.xml HTTP/1.1" 404 Not Found
INFO:     109.237.103.118:0 - "GET /.env HTTP/1.1" 404 Not Found
INFO:     45.146.165.37:0 - "GET /_ignition/execute-solution HTTP/1.1" 404 Not Found
INFO:     109.237.103.123:0 - "GET /.env HTTP/1.1" 404 Not Found
INFO:     45.146.165.37:0 - "GET / HTTP/1.1" 200 OK
INFO:     178.32.197.93:0 - "GET / HTTP/1.1" 200 OK
INFO:     178.62.222.151:0 - "GET /system_api.php HTTP/1.1" 404 Not Found
INFO:     178.62.222.151:0 - "GET /c/version.js HTTP/1.1" 404 Not Found
INFO:     178.62.222.151:0 - "GET /streaming/clients_live.php HTTP/1.1" 404 Not Found
INFO:     178.62.222.151:0 - "GET /stalker_portal/c/version.js HTTP/1.1" 404 Not Found
INFO:     178.62.222.151:0 - "GET /stream/live.php HTTP/1.1" 404 Not Found
INFO:     178.62.222.151:0 - "GET /flu/403.html HTTP/1.1" 404 Not Found
INFO:     178.62.222.151:0 - "GET / HTTP/1.1" 200 OK
INFO:     138.246.253.24:0 - "GET /robots.txt HTTP/1.1" 404 Not Found
INFO:     62.210.5.253:0 - "GET /favicon.ico HTTP/1.1" 404 Not Found
INFO:     51.254.49.105:0 - "GET / HTTP/1.1" 200 OK
INFO:     47.241.66.187:0 - "GET /dns-query?dns=lggBAAABAAAAAAAAA3d3dwZnb29nbGUDY29tAAABAAE HTTP/1.1" 404 Not Found
INFO:     47.241.66.187:0 - "GET /dns-query?dns=5jIBAAABAAAAAAAAA3d3dwZnb29nbGUDY29tAAABAAE HTTP/1.1" 404 Not Found
INFO:     130.211.54.158:0 - "GET / HTTP/1.1" 200 OK
WARNING:  Invalid HTTP request received.
Traceback (most recent call last):
  File "/home/partner_portal/virtual_env/lib/python3.8/site-packages/uvicorn/protocols/http/h11_impl.py", line 136, in handle_events
    event = self.conn.next_event()
  File "/home/partner_portal/virtual_env/lib/python3.8/site-packages/h11/_connection.py", line 443, in next_event
    exc._reraise_as_remote_protocol_error()
  File "/home/partner_portal/virtual_env/lib/python3.8/site-packages/h11/_util.py", line 76, in _reraise_as_remote_protocol_error
    raise self
  File "/home/partner_portal/virtual_env/lib/python3.8/site-packages/h11/_connection.py", line 425, in next_event
    event = self._extract_next_receive_event()
  File "/home/partner_portal/virtual_env/lib/python3.8/site-packages/h11/_connection.py", line 367, in _extract_next_receive_event
    event = self._reader(self._receive_buffer)
  File "/home/partner_portal/virtual_env/lib/python3.8/site-packages/h11/_readers.py", line 68, in maybe_read_from_IDLE_client
    raise LocalProtocolError("illegal request line")
h11._util.RemoteProtocolError: illegal request line
INFO:     65.49.20.66:0 - "GET / HTTP/1.1" 200 OK
INFO:     106.75.229.12:0 - "GET / HTTP/1.1" 200 OK
WARNING:  Invalid HTTP request received.
Traceback (most recent call last):
  File "/home/partner_portal/virtual_env/lib/python3.8/site-packages/uvicorn/protocols/http/h11_impl.py", line 136, in handle_events
    event = self.conn.next_event()
  File "/home/partner_portal/virtual_env/lib/python3.8/site-packages/h11/_connection.py", line 443, in next_event
    exc._reraise_as_remote_protocol_error()
  File "/home/partner_portal/virtual_env/lib/python3.8/site-packages/h11/_util.py", line 76, in _reraise_as_remote_protocol_error
    raise self
  File "/home/partner_portal/virtual_env/lib/python3.8/site-packages/h11/_connection.py", line 425, in next_event
    event = self._extract_next_receive_event()
  File "/home/partner_portal/virtual_env/lib/python3.8/site-packages/h11/_connection.py", line 367, in _extract_next_receive_event
    event = self._reader(self._receive_buffer)
  File "/home/partner_portal/virtual_env/lib/python3.8/site-packages/h11/_readers.py", line 68, in maybe_read_from_IDLE_client
    raise LocalProtocolError("illegal request line")
h11._util.RemoteProtocolError: illegal request line
INFO:     185.220.100.241:1774 - "GET / HTTP/1.1" 200 OK
INFO:     185.220.101.51:22272 - "GET /favicon.ico HTTP/1.1" 404 Not Found
INFO:     192.241.218.83:0 - "GET /actuator/health HTTP/1.1" 404 Not Found
INFO:     172.70.1.75:0 - "GET / HTTP/1.1" 200 OK
INFO:     172.70.1.75:0 - "GET / HTTP/1.1" 200 OK
INFO:     172.70.1.75:0 - "GET / HTTP/1.1" 200 OK
INFO:     109.237.103.38:0 - "GET /.env HTTP/1.1" 404 Not Found
INFO:     192.241.210.240:0 - "GET / HTTP/1.1" 200 OK
WARNING:  Invalid HTTP request received.
Traceback (most recent call last):
  File "/home/partner_portal/virtual_env/lib/python3.8/site-packages/uvicorn/protocols/http/h11_impl.py", line 136, in handle_events
    event = self.conn.next_event()
  File "/home/partner_portal/virtual_env/lib/python3.8/site-packages/h11/_connection.py", line 443, in next_event
    exc._reraise_as_remote_protocol_error()
  File "/home/partner_portal/virtual_env/lib/python3.8/site-packages/h11/_util.py", line 76, in _reraise_as_remote_protocol_error
    raise self
  File "/home/partner_portal/virtual_env/lib/python3.8/site-packages/h11/_connection.py", line 425, in next_event
    event = self._extract_next_receive_event()
  File "/home/partner_portal/virtual_env/lib/python3.8/site-packages/h11/_connection.py", line 367, in _extract_next_receive_event
    event = self._reader(self._receive_buffer)
  File "/home/partner_portal/virtual_env/lib/python3.8/site-packages/h11/_readers.py", line 68, in maybe_read_from_IDLE_client
    raise LocalProtocolError("illegal request line")
h11._util.RemoteProtocolError: illegal request line
INFO:     91.236.239.224:0 - "POST / HTTP/1.1" 405 Method Not Allowed
INFO:     192.241.218.41:0 - "GET /ecp/Current/exporttool/microsoft.exchange.ediscovery.exporttool.application HTTP/1.1" 404 Not Found
INFO:     192.241.216.202:0 - "GET /owa/auth/x.js HTTP/1.1" 404 Not Found
INFO:     192.241.217.44:0 - "GET /owa/auth/logon.aspx HTTP/1.1" 404 Not Found
INFO:     216.19.217.166:0 - "GET / HTTP/1.1" 200 OK
INFO:     167.94.138.113:0 - "GET / HTTP/1.1" 200 OK
INFO:     167.94.138.113:0 - "GET / HTTP/1.1" 200 OK
INFO:     213.32.122.82:0 - "GET / HTTP/1.1" 200 OK
INFO:     3.145.135.127:0 - "GET / HTTP/1.1" 200 OK
INFO:     45.146.165.37:0 - "POST /vendor/phpunit/phpunit/src/Util/PHP/eval-stdin.php HTTP/1.1" 404 Not Found
INFO:     192.241.217.17:0 - "GET /ecp/Current/exporttool/microsoft.exchange.ediscovery.exporttool.application HTTP/1.1" 404 Not Found
INFO:     172.93.194.119:0 - "GET /autodiscover/autodiscover.json?@1337.com/owa/?&Email=autodiscover/autodiscover.json%3F@1337.com HTTP/1.1" 404 Not Found
INFO:     192.241.205.198:0 - "GET /owa/auth/logon.aspx?url=https%3a%2f%2f1%2fecp%2f HTTP/1.1" 404 Not Found
INFO:     3.145.135.127:0 - "GET /mobile/ HTTP/1.1" 404 Not Found
INFO:     45.146.165.37:0 - "GET /index.php?s=/Index/\think\app/invokefunction&function=call_user_func_array&vars[0]=md5&vars[1][]=HelloThinkPHP21 HTTP/1.1" 404 Not Found
INFO:     102.129.145.16:0 - "GET /aaa9 HTTP/1.1" 404 Not Found
INFO:     156.146.50.162:0 - "OPTIONS / HTTP/1.1" 405 Method Not Allowed
INFO:     45.146.165.37:0 - "GET /?XDEBUG_SESSION_START=phpstorm HTTP/1.1" 200 OK
INFO:     139.162.145.250:0 - "GET /bag2 HTTP/1.1" 404 Not Found
INFO:     66.240.236.109:0 - "GET / HTTP/1.1" 200 OK
INFO:     45.146.165.37:0 - "POST /Autodiscover/Autodiscover.xml HTTP/1.1" 404 Not Found
INFO:     45.146.165.37:0 - "GET /_ignition/execute-solution HTTP/1.1" 404 Not Found
INFO:     45.146.165.37:0 - "GET / HTTP/1.1" 200 OK
INFO:     222.186.19.235:60588 - "GET http%3A//fuwu.sogou.com/404/index.html HTTP/1.1" 404 Not Found
INFO:     222.186.19.235:60572 - "GET http%3A//fuwu.sogou.com/404/index.html HTTP/1.1" 404 Not Found
WARNING:  Invalid HTTP request received.
Traceback (most recent call last):
  File "/home/partner_portal/virtual_env/lib/python3.8/site-packages/uvicorn/protocols/http/h11_impl.py", line 136, in handle_events
    event = self.conn.next_event()
  File "/home/partner_portal/virtual_env/lib/python3.8/site-packages/h11/_connection.py", line 443, in next_event
    exc._reraise_as_remote_protocol_error()
  File "/home/partner_portal/virtual_env/lib/python3.8/site-packages/h11/_util.py", line 76, in _reraise_as_remote_protocol_error
    raise self
  File "/home/partner_portal/virtual_env/lib/python3.8/site-packages/h11/_connection.py", line 425, in next_event
    event = self._extract_next_receive_event()
  File "/home/partner_portal/virtual_env/lib/python3.8/site-packages/h11/_connection.py", line 367, in _extract_next_receive_event
    event = self._reader(self._receive_buffer)
  File "/home/partner_portal/virtual_env/lib/python3.8/site-packages/h11/_readers.py", line 68, in maybe_read_from_IDLE_client
    raise LocalProtocolError("illegal request line")
h11._util.RemoteProtocolError: illegal request line
INFO:     176.113.42.198:0 - "GET / HTTP/1.1" 200 OK
INFO:     176.113.42.198:0 - "GET /favicon.ico HTTP/1.1" 404 Not Found
INFO:     89.104.100.135:0 - "GET / HTTP/1.1" 200 OK
INFO:     89.104.100.135:0 - "GET /favicon.ico HTTP/1.1" 404 Not Found
INFO:     176.113.42.198:0 - "GET /favicon.ico HTTP/1.1" 404 Not Found
INFO:     45.146.165.37:0 - "GET / HTTP/1.1" 200 OK
INFO:     103.28.70.140:0 - "GET /.env HTTP/1.1" 404 Not Found
INFO:     103.28.70.140:0 - "POST / HTTP/1.1" 405 Method Not Allowed
INFO:     35.195.93.98:0 - "GET / HTTP/1.1" 200 OK
INFO:     109.248.6.50:0 - "GET /favicon.ico HTTP/1.1" 404 Not Found
INFO:     64.62.197.182:0 - "GET / HTTP/1.1" 200 OK
INFO:     3.88.185.113:0 - "GET /.env HTTP/1.1" 404 Not Found
INFO:     3.88.185.113:0 - "POST / HTTP/1.1" 405 Method Not Allowed
INFO:     91.236.239.224:0 - "POST / HTTP/1.1" 405 Method Not Allowed
INFO:     172.69.31.144:0 - "GET / HTTP/1.1" 200 OK
INFO:     172.69.31.144:0 - "GET / HTTP/1.1" 200 OK
INFO:     172.69.31.144:0 - "GET / HTTP/1.1" 200 OK
INFO:     109.237.103.9:0 - "GET /.env HTTP/1.1" 404 Not Found
INFO:     192.241.216.133:0 - "GET /actuator/health HTTP/1.1" 404 Not Found
INFO:     45.146.165.37:0 - "POST /vendor/phpunit/phpunit/src/Util/PHP/eval-stdin.php HTTP/1.1" 404 Not Found
INFO:     178.128.194.144:0 - "GET / HTTP/1.1" 200 OK
INFO:     45.146.165.37:0 - "GET /index.php?s=/Index/\think\app/invokefunction&function=call_user_func_array&vars[0]=md5&vars[1][]=HelloThinkPHP21 HTTP/1.1" 404 Not Found
INFO:     192.241.208.135:0 - "GET / HTTP/1.1" 200 OK
INFO:     45.146.165.37:0 - "GET /?XDEBUG_SESSION_START=phpstorm HTTP/1.1" 200 OK
INFO:     104.152.52.73:0 - "GET / HTTP/1.1" 200 OK
INFO:     104.152.52.73:0 - "OPTIONS / HTTP/1.1" 405 Method Not Allowed
INFO:     45.146.165.37:0 - "POST /mifs/.%3B/services/LogService HTTP/1.1" 404 Not Found
INFO:     192.241.204.142:0 - "GET /ecp/Current/exporttool/microsoft.exchange.ediscovery.exporttool.application HTTP/1.1" 404 Not Found
INFO:     192.241.205.93:0 - "GET /owa/auth/logon.aspx?url=https%3a%2f%2f1%2fecp%2f HTTP/1.1" 404 Not Found
INFO:     162.142.125.44:43894 - "GET / HTTP/1.1" 200 OK
INFO:     45.146.165.37:0 - "GET /console/ HTTP/1.1" 404 Not Found
INFO:     13.59.110.100:0 - "GET /.env HTTP/1.1" 404 Not Found
INFO:     13.59.110.100:0 - "POST / HTTP/1.1" 405 Method Not Allowed
INFO:     40.121.51.198:0 - "GET /.env HTTP/1.1" 404 Not Found
INFO:     40.121.51.198:0 - "POST / HTTP/1.1" 405 Method Not Allowed
INFO:     45.146.165.37:0 - "POST /Autodiscover/Autodiscover.xml HTTP/1.1" 404 Not Found
INFO:     40.121.51.198:0 - "GET /.env HTTP/1.1" 404 Not Found
INFO:     40.121.51.198:0 - "POST / HTTP/1.1" 405 Method Not Allowed
INFO:     45.146.165.37:0 - "GET /_ignition/execute-solution HTTP/1.1" 404 Not Found
INFO:     109.237.103.38:0 - "GET /.env HTTP/1.1" 404 Not Found
INFO:     45.146.165.37:0 - "GET / HTTP/1.1" 200 OK
INFO:     185.136.167.60:0 - "GET /.env HTTP/1.1" 404 Not Found
INFO:     185.136.167.60:0 - "POST / HTTP/1.1" 405 Method Not Allowed
INFO:     104.206.128.78:0 - "GET / HTTP/1.1" 200 OK
INFO:     45.146.165.37:0 - "GET / HTTP/1.1" 200 OK
INFO:     109.237.103.123:0 - "GET /.env HTTP/1.1" 404 Not Found
INFO:     180.149.125.167:0 - "GET / HTTP/1.1" 200 OK
INFO:     185.136.167.60:0 - "GET /.env HTTP/1.1" 404 Not Found
INFO:     185.136.167.60:0 - "POST / HTTP/1.1" 405 Method Not Allowed
INFO:     61.164.47.194:0 - "GET / HTTP/1.1" 200 OK
INFO:     34.214.127.141:0 - "GET /.env HTTP/1.1" 404 Not Found
INFO:     34.214.127.141:0 - "POST / HTTP/1.1" 405 Method Not Allowed
INFO:     194.48.199.78:0 - "GET /cgi-bin/welcome HTTP/1.1" 404 Not Found
INFO:     128.199.181.53:0 - "GET /?config HTTP/1.1" 200 OK
INFO:     128.199.181.53:0 - "GET /phpinfo.php?ctime=system&atime=id HTTP/1.1" 404 Not Found
INFO:     130.211.54.158:0 - "GET / HTTP/1.1" 200 OK
INFO:     167.94.138.116:0 - "GET / HTTP/1.1" 200 OK
INFO:     167.94.138.116:0 - "GET / HTTP/1.1" 200 OK
INFO:     185.136.167.60:0 - "GET /.env HTTP/1.1" 404 Not Found
INFO:     185.136.167.60:0 - "POST / HTTP/1.1" 405 Method Not Allowed
INFO:     154.89.5.73:0 - "GET / HTTP/1.1" 200 OK
INFO:     139.59.77.211:0 - "GET / HTTP/1.1" 200 OK
INFO:     45.146.165.37:0 - "POST /vendor/phpunit/phpunit/src/Util/PHP/eval-stdin.php HTTP/1.1" 404 Not Found
INFO:     64.225.75.232:0 - "GET / HTTP/1.1" 200 OK
INFO:     45.146.165.37:0 - "GET /vendor/phpunit/phpunit/src/Util/PHP/eval-stdin.php HTTP/1.1" 404 Not Found
INFO:     45.146.165.37:0 - "GET /index.php?s=/Index/\think\app/invokefunction&function=call_user_func_array&vars[0]=md5&vars[1][]=HelloThinkPHP21 HTTP/1.1" 404 Not Found
INFO:     193.239.232.102:0 - "GET / HTTP/1.1" 200 OK
INFO:     198.98.49.184:0 - "GET /favicon.ico HTTP/1.1" 404 Not Found
INFO:     172.70.1.203:0 - "GET / HTTP/1.1" 200 OK
INFO:     172.70.1.203:0 - "GET / HTTP/1.1" 200 OK
INFO:     172.70.1.203:0 - "GET / HTTP/1.1" 200 OK
INFO:     64.62.197.212:0 - "GET / HTTP/1.1" 200 OK
INFO:     52.90.148.47:0 - "GET / HTTP/1.1" 200 OK
INFO:     52.90.148.47:0 - "GET / HTTP/1.1" 200 OK
INFO:     52.90.148.47:0 - "GET / HTTP/1.1" 200 OK
INFO:     52.90.148.47:0 - "GET / HTTP/1.1" 200 OK
INFO:     52.90.148.47:0 - "GET / HTTP/1.1" 200 OK
INFO:     52.90.148.47:0 - "GET / HTTP/1.1" 200 OK
INFO:     52.90.148.47:0 - "GET / HTTP/1.1" 200 OK
INFO:     52.90.148.47:0 - "GET / HTTP/1.1" 200 OK
INFO:     52.90.148.47:0 - "GET / HTTP/1.1" 200 OK
INFO:     52.90.148.47:0 - "GET / HTTP/1.1" 200 OK
INFO:     52.90.148.47:0 - "GET / HTTP/1.1" 200 OK
INFO:     52.90.148.47:0 - "GET / HTTP/1.1" 200 OK
INFO:     52.90.148.47:0 - "GET / HTTP/1.1" 200 OK
INFO:     52.90.148.47:0 - "GET / HTTP/1.1" 200 OK
INFO:     52.90.148.47:0 - "GET / HTTP/1.1" 200 OK
INFO:     52.90.148.47:0 - "GET / HTTP/1.1" 200 OK
INFO:     52.90.148.47:0 - "GET / HTTP/1.1" 200 OK
INFO:     52.90.148.47:0 - "GET / HTTP/1.1" 200 OK
INFO:     52.90.148.47:0 - "GET / HTTP/1.1" 200 OK
INFO:     52.90.148.47:0 - "GET / HTTP/1.1" 200 OK
INFO:     52.90.148.47:0 - "GET / HTTP/1.1" 200 OK
INFO:     52.90.148.47:0 - "GET / HTTP/1.1" 200 OK
INFO:     52.90.148.47:0 - "GET / HTTP/1.1" 200 OK
INFO:     52.90.148.47:0 - "GET / HTTP/1.1" 200 OK
INFO:     52.90.148.47:0 - "GET / HTTP/1.1" 200 OK
INFO:     52.90.148.47:0 - "GET / HTTP/1.1" 200 OK
INFO:     52.90.148.47:0 - "GET / HTTP/1.1" 200 OK
INFO:     52.90.148.47:0 - "GET / HTTP/1.1" 200 OK
INFO:     52.90.148.47:0 - "GET / HTTP/1.1" 200 OK
INFO:     52.90.148.47:0 - "GET / HTTP/1.1" 200 OK
INFO:     52.90.148.47:0 - "GET / HTTP/1.1" 200 OK
INFO:     52.90.148.47:0 - "GET / HTTP/1.1" 200 OK
INFO:     185.100.87.54:0 - "GET / HTTP/1.1" 200 OK
INFO:     198.20.69.98:0 - "GET / HTTP/1.1" 200 OK
INFO:     198.20.69.98:0 - "GET /robots.txt HTTP/1.1" 404 Not Found
INFO:     198.20.69.98:0 - "GET /sitemap.xml HTTP/1.1" 404 Not Found
INFO:     198.20.69.98:0 - "GET /.well-known/security.txt HTTP/1.1" 404 Not Found
INFO:     198.20.69.98:0 - "GET /favicon.ico HTTP/1.1" 404 Not Found
INFO:     45.146.165.37:0 - "POST /mifs/.%3B/services/LogService HTTP/1.1" 404 Not Found
INFO:     212.243.9.107:0 - "GET /remote/fgt_lang?lang=/../../../..//////////dev/cmdb/sslvpn_websession HTTP/1.1" 404 Not Found
INFO:     178.73.215.171:0 - "GET / HTTP/1.1" 200 OK
INFO:     45.146.165.37:0 - "GET /console/ HTTP/1.1" 404 Not Found
INFO:     192.241.217.81:0 - "GET /actuator/health HTTP/1.1" 404 Not Found
INFO:     45.146.165.37:0 - "POST /Autodiscover/Autodiscover.xml HTTP/1.1" 404 Not Found
INFO:     199.244.49.67:0 - "GET /.env HTTP/1.1" 404 Not Found
INFO:     199.244.49.67:0 - "POST / HTTP/1.1" 405 Method Not Allowed
WARNING:  Invalid HTTP request received.
Traceback (most recent call last):
  File "/home/partner_portal/virtual_env/lib/python3.8/site-packages/uvicorn/protocols/http/h11_impl.py", line 136, in handle_events
    event = self.conn.next_event()
  File "/home/partner_portal/virtual_env/lib/python3.8/site-packages/h11/_connection.py", line 443, in next_event
    exc._reraise_as_remote_protocol_error()
  File "/home/partner_portal/virtual_env/lib/python3.8/site-packages/h11/_util.py", line 76, in _reraise_as_remote_protocol_error
    raise self
  File "/home/partner_portal/virtual_env/lib/python3.8/site-packages/h11/_connection.py", line 425, in next_event
    event = self._extract_next_receive_event()
  File "/home/partner_portal/virtual_env/lib/python3.8/site-packages/h11/_connection.py", line 367, in _extract_next_receive_event
    event = self._reader(self._receive_buffer)
  File "/home/partner_portal/virtual_env/lib/python3.8/site-packages/h11/_readers.py", line 68, in maybe_read_from_IDLE_client
    raise LocalProtocolError("illegal request line")
h11._util.RemoteProtocolError: illegal request line
INFO:     170.106.115.55:57394 - "GET / HTTP/1.1" 200 OK
INFO:     205.185.117.203:36330 - "GET / HTTP/1.1" 200 OK
INFO:     205.185.117.203:36330 - "GET /favicon.ico HTTP/1.1" 404 Not Found
INFO:     45.146.165.37:0 - "GET / HTTP/1.1" 200 OK
INFO:     192.241.205.77:0 - "GET /ecp/Current/exporttool/microsoft.exchange.ediscovery.exporttool.application HTTP/1.1" 404 Not Found
INFO:     109.248.6.98:0 - "GET / HTTP/1.1" 200 OK
INFO:     192.241.214.239:0 - "GET /owa/auth/logon.aspx?url=https%3a%2f%2f1%2fecp%2f HTTP/1.1" 404 Not Found
INFO:     192.241.208.41:0 - "GET / HTTP/1.1" 200 OK
INFO:     47.89.190.157:0 - "GET / HTTP/1.1" 200 OK
INFO:     47.89.190.157:0 - "OPTIONS / HTTP/1.1" 405 Method Not Allowed
INFO:     47.89.190.157:0 - "GET /nice%20ports%2C/Trinity.txt.bak HTTP/1.1" 404 Not Found
INFO:     47.89.190.157:0 - "GET / HTTP/1.1" 200 OK
INFO:     47.89.190.157:0 - "GET /text4041642258209 HTTP/1.1" 404 Not Found
INFO:     47.89.190.157:0 - "GET /evox/about HTTP/1.1" 404 Not Found
INFO:     47.89.190.157:0 - "GET / HTTP/1.1" 200 OK
INFO:     47.89.190.157:0 - "POST /sdk HTTP/1.1" 404 Not Found
INFO:     47.89.190.157:0 - "GET /HNAP1 HTTP/1.1" 404 Not Found
INFO:     47.89.190.157:0 - "GET / HTTP/1.1" 200 OK
INFO:     47.89.190.157:0 - "GET /favicon.ico HTTP/1.1" 404 Not Found
INFO:     47.89.190.157:0 - "GET /robots.txt HTTP/1.1" 404 Not Found
INFO:     50.31.21.11:0 - "GET / HTTP/1.1" 200 OK
INFO:     50.31.21.11:0 - "OPTIONS / HTTP/1.1" 405 Method Not Allowed
INFO:     50.31.21.11:0 - "GET /nice%20ports%2C/Trinity.txt.bak HTTP/1.1" 404 Not Found
INFO:     50.31.21.11:0 - "POST /sdk HTTP/1.1" 404 Not Found
INFO:     50.31.21.11:0 - "GET / HTTP/1.1" 200 OK
INFO:     50.31.21.11:0 - "GET /nmaplowercheck1642264238 HTTP/1.1" 404 Not Found
INFO:     50.31.21.11:0 - "HEAD / HTTP/1.1" 405 Method Not Allowed
INFO:     50.31.21.11:0 - "GET / HTTP/1.1" 200 OK
INFO:     50.31.21.11:0 - "GET /evox/about HTTP/1.1" 404 Not Found
INFO:     50.31.21.11:0 - "GET /HNAP1 HTTP/1.1" 404 Not Found
INFO:     50.31.21.11:0 - "GET / HTTP/1.1" 200 OK
INFO:     185.136.167.60:0 - "GET /.env HTTP/1.1" 404 Not Found
INFO:     185.136.167.60:0 - "POST / HTTP/1.1" 405 Method Not Allowed
INFO:     45.154.255.147:47498 - "GET / HTTP/1.1" 200 OK
INFO:     45.154.255.147:50624 - "GET /favicon.ico HTTP/1.1" 404 Not Found
INFO:     194.48.199.78:0 - "GET /cgi-bin/welcome HTTP/1.1" 404 Not Found
INFO:     167.248.133.60:0 - "GET / HTTP/1.1" 200 OK
INFO:     167.248.133.60:0 - "GET / HTTP/1.1" 200 OK
INFO:     109.237.103.38:0 - "GET /.env HTTP/1.1" 404 Not Found
INFO:     45.146.165.37:0 - "POST /vendor/phpunit/phpunit/src/Util/PHP/eval-stdin.php HTTP/1.1" 404 Not Found
INFO:     88.9.119.217:0 - "GET / HTTP/1.1" 200 OK
INFO:     109.237.103.9:0 - "GET /.env HTTP/1.1" 404 Not Found
INFO:     109.237.103.123:0 - "GET /.env HTTP/1.1" 404 Not Found
INFO:     35.233.62.116:0 - "GET / HTTP/1.1" 200 OK
INFO:     45.146.165.37:0 - "GET /vendor/phpunit/phpunit/src/Util/PHP/eval-stdin.php HTTP/1.1" 404 Not Found
INFO:     45.146.165.37:0 - "GET /?XDEBUG_SESSION_START=phpstorm HTTP/1.1" 200 OK
INFO:     45.146.165.37:0 - "POST /mifs/.%3B/services/LogService HTTP/1.1" 404 Not Found
INFO:     45.146.165.37:0 - "GET /console/ HTTP/1.1" 404 Not Found
INFO:     45.146.165.37:0 - "POST /Autodiscover/Autodiscover.xml HTTP/1.1" 404 Not Found
INFO:     172.70.8.203:0 - "GET / HTTP/1.1" 200 OK
INFO:     172.70.8.203:0 - "GET / HTTP/1.1" 200 OK
INFO:     172.70.8.203:0 - "GET / HTTP/1.1" 200 OK
INFO:     45.146.165.37:0 - "GET /_ignition/execute-solution HTTP/1.1" 404 Not Found
INFO:     36.72.216.119:0 - "GET /wp-json/wp/v2/users HTTP/1.1" 404 Not Found
INFO:     36.72.216.119:0 - "GET /?rest_route=/wp/v2/users HTTP/1.1" 200 OK
INFO:     36.72.216.119:0 - "GET /?author=1 HTTP/1.1" 200 OK
INFO:     45.146.165.37:0 - "GET / HTTP/1.1" 200 OK
INFO:     45.146.165.37:0 - "GET / HTTP/1.1" 200 OK
INFO:     185.100.87.136:0 - "POST /ajax HTTP/1.1" 404 Not Found
INFO:     20.55.53.144:0 - "GET /UK6hwlfPm8DT4gybV0zX7itJ9ot HTTP/1.1" 404 Not Found
INFO:     154.89.5.74:45048 - "GET / HTTP/1.0" 200 OK
INFO:     192.241.206.156:0 - "GET /ecp/Current/exporttool/microsoft.exchange.ediscovery.exporttool.application HTTP/1.1" 404 Not Found
INFO:     164.92.224.19:0 - "GET / HTTP/1.1" 200 OK
INFO:     192.241.205.198:0 - "GET /owa/auth/logon.aspx?url=https%3a%2f%2f1%2fecp%2f HTTP/1.1" 404 Not Found
INFO:     34.74.180.74:0 - "GET / HTTP/1.1" 200 OK
INFO:     184.105.139.67:0 - "GET / HTTP/1.1" 200 OK
INFO:     109.237.103.118:0 - "GET /.env HTTP/1.1" 404 Not Found
INFO:     185.147.34.149:0 - "GET /.env HTTP/1.1" 404 Not Found
INFO:     185.147.34.149:0 - "POST / HTTP/1.1" 405 Method Not Allowed
INFO:     3.14.255.15:0 - "GET /.git/HEAD HTTP/1.1" 404 Not Found
INFO:     45.146.165.37:0 - "POST /vendor/phpunit/phpunit/src/Util/PHP/eval-stdin.php HTTP/1.1" 404 Not Found
INFO:     192.241.216.166:0 - "GET /actuator/health HTTP/1.1" 404 Not Found
INFO:     106.75.123.132:58966 - "GET / HTTP/1.1" 200 OK
INFO:     103.156.91.51:0 - "GET /.env HTTP/1.1" 404 Not Found
INFO:     103.156.91.51:0 - "POST / HTTP/1.1" 405 Method Not Allowed
INFO:     103.156.91.51:0 - "GET /.env HTTP/1.1" 404 Not Found
INFO:     103.156.91.51:0 - "POST / HTTP/1.1" 405 Method Not Allowed
INFO:     45.146.165.37:0 - "GET /vendor/phpunit/phpunit/src/Util/PHP/eval-stdin.php HTTP/1.1" 404 Not Found
INFO:     103.102.153.153:0 - "GET / HTTP/1.1" 200 OK
INFO:     103.102.153.153:0 - "GET /favicon.ico HTTP/1.1" 404 Not Found
INFO:     103.102.153.153:0 - "GET /robots.txt HTTP/1.1" 404 Not Found
INFO:     103.102.153.153:0 - "GET /sitemap.xml HTTP/1.1" 404 Not Found
INFO:     20.55.53.144:0 - "GET / HTTP/1.1" 200 OK
INFO:     45.146.165.37:0 - "GET /index.php?s=/Index/\think\app/invokefunction&function=call_user_func_array&vars[0]=md5&vars[1][]=HelloThinkPHP21 HTTP/1.1" 404 Not Found
INFO:     45.146.165.37:0 - "GET /?XDEBUG_SESSION_START=phpstorm HTTP/1.1" 200 OK
INFO:     45.146.165.37:0 - "POST /mifs/.%3B/services/LogService HTTP/1.1" 404 Not Found
INFO:     35.195.93.98:0 - "GET / HTTP/1.1" 200 OK
INFO:     45.146.165.37:0 - "GET /console/ HTTP/1.1" 404 Not Found
INFO:     197.184.182.17:0 - "GET /.env HTTP/1.1" 404 Not Found
INFO:     197.184.182.17:0 - "POST / HTTP/1.1" 405 Method Not Allowed
INFO:     45.146.165.37:0 - "GET /_ignition/execute-solution HTTP/1.1" 404 Not Found
INFO:     192.241.204.36:0 - "GET / HTTP/1.1" 200 OK
INFO:     45.146.165.37:0 - "GET / HTTP/1.1" 200 OK
INFO:     45.146.165.37:0 - "GET / HTTP/1.1" 200 OK
INFO:     172.70.1.203:0 - "GET / HTTP/1.1" 200 OK
INFO:     172.70.1.203:0 - "GET / HTTP/1.1" 200 OK
INFO:     172.70.1.203:0 - "GET / HTTP/1.1" 200 OK
INFO:     193.118.53.194:0 - "GET /remote/login HTTP/1.1" 404 Not Found
INFO:     109.237.103.9:0 - "GET /.env HTTP/1.1" 404 Not Found
INFO:     45.146.165.37:0 - "GET / HTTP/1.1" 200 OK
INFO:     183.136.225.42:4610 - "GET / HTTP/1.1" 200 OK
INFO:     183.136.225.42:45235 - "GET / HTTP/1.1" 200 OK
INFO:     183.136.225.42:13200 - "GET /favicon.ico HTTP/1.1" 404 Not Found
INFO:     173.249.48.46:0 - "GET /.env HTTP/1.1" 404 Not Found
INFO:     173.249.48.46:0 - "POST / HTTP/1.1" 405 Method Not Allowed
INFO:     172.93.220.136:0 - "GET /.env HTTP/1.1" 404 Not Found
INFO:     172.93.220.136:0 - "POST / HTTP/1.1" 405 Method Not Allowed
INFO:     59.36.168.250:0 - "GET /.env HTTP/1.1" 404 Not Found
INFO:     59.36.168.250:0 - "POST / HTTP/1.1" 405 Method Not Allowed
INFO:     167.248.133.41:34094 - "GET / HTTP/1.1" 200 OK
INFO:     192.241.208.103:0 - "GET /ecp/Current/exporttool/microsoft.exchange.ediscovery.exporttool.application HTTP/1.1" 404 Not Found
INFO:     192.241.217.80:0 - "GET /owa/auth/logon.aspx?url=https%3a%2f%2f1%2fecp%2f HTTP/1.1" 404 Not Found
INFO:     102.129.145.16:0 - "GET /aaa9 HTTP/1.1" 404 Not Found
INFO:     183.136.226.3:0 - "GET / HTTP/1.1" 200 OK
INFO:     183.136.226.3:0 - "GET /favicon.ico HTTP/1.1" 404 Not Found
INFO:     23.236.147.154:0 - "GET / HTTP/1.1" 200 OK
INFO:     45.134.144.108:0 - "GET /remote/fgt_lang?lang=/../../../..//////////dev/ HTTP/1.1" 404 Not Found
INFO:     45.146.165.37:0 - "POST /vendor/phpunit/phpunit/src/Util/PHP/eval-stdin.php HTTP/1.1" 404 Not Found
INFO:     45.146.165.37:0 - "GET /vendor/phpunit/phpunit/src/Util/PHP/eval-stdin.php HTTP/1.1" 404 Not Found
INFO:     194.48.199.78:0 - "GET / HTTP/1.1" 200 OK
INFO:     45.146.165.37:0 - "GET /index.php?s=/Index/\think\app/invokefunction&function=call_user_func_array&vars[0]=md5&vars[1][]=HelloThinkPHP21 HTTP/1.1" 404 Not Found
INFO:     45.146.165.37:0 - "GET /?XDEBUG_SESSION_START=phpstorm HTTP/1.1" 200 OK
INFO:     51.158.103.247:0 - "GET / HTTP/1.1" 200 OK
INFO:     139.162.145.250:0 - "GET /bag2 HTTP/1.1" 404 Not Found
INFO:     185.173.35.37:0 - "GET / HTTP/1.1" 200 OK
INFO:     45.146.165.37:0 - "POST /mifs/.%3B/services/LogService HTTP/1.1" 404 Not Found
INFO:     194.49.68.118:0 - "GET /.env HTTP/1.1" 404 Not Found
INFO:     194.49.68.118:0 - "POST / HTTP/1.1" 405 Method Not Allowed
INFO:     109.237.103.123:0 - "GET /.env HTTP/1.1" 404 Not Found
INFO:     45.146.165.37:0 - "GET /console/ HTTP/1.1" 404 Not Found
INFO:     172.105.252.81:0 - "POST /sdk HTTP/1.1" 404 Not Found
WARNING:  Invalid HTTP request received.
Traceback (most recent call last):
  File "/home/partner_portal/virtual_env/lib/python3.8/site-packages/uvicorn/protocols/http/h11_impl.py", line 136, in handle_events
    event = self.conn.next_event()
  File "/home/partner_portal/virtual_env/lib/python3.8/site-packages/h11/_connection.py", line 443, in next_event
    exc._reraise_as_remote_protocol_error()
  File "/home/partner_portal/virtual_env/lib/python3.8/site-packages/h11/_util.py", line 76, in _reraise_as_remote_protocol_error
    raise self
  File "/home/partner_portal/virtual_env/lib/python3.8/site-packages/h11/_connection.py", line 425, in next_event
    event = self._extract_next_receive_event()
  File "/home/partner_portal/virtual_env/lib/python3.8/site-packages/h11/_connection.py", line 367, in _extract_next_receive_event
    event = self._reader(self._receive_buffer)
  File "/home/partner_portal/virtual_env/lib/python3.8/site-packages/h11/_readers.py", line 68, in maybe_read_from_IDLE_client
    raise LocalProtocolError("illegal request line")
h11._util.RemoteProtocolError: illegal request line
INFO:     178.128.194.144:0 - "GET /.git/config HTTP/1.1" 404 Not Found
INFO:     45.146.165.37:0 - "POST /Autodiscover/Autodiscover.xml HTTP/1.1" 404 Not Found
INFO:     162.142.125.44:0 - "GET / HTTP/1.1" 200 OK
INFO:     162.142.125.44:0 - "GET / HTTP/1.1" 200 OK
INFO:     109.237.103.38:0 - "GET /.env HTTP/1.1" 404 Not Found
INFO:     162.142.125.193:0 - "GET / HTTP/1.1" 200 OK
INFO:     45.146.165.37:0 - "GET /_ignition/execute-solution HTTP/1.1" 404 Not Found
INFO:     45.146.165.37:0 - "GET / HTTP/1.1" 200 OK
INFO:     34.140.248.32:0 - "GET / HTTP/1.1" 200 OK
INFO:     167.248.133.60:0 - "GET / HTTP/1.1" 200 OK
INFO:     167.248.133.60:0 - "GET / HTTP/1.1" 200 OK
INFO:     180.149.125.167:0 - "GET / HTTP/1.1" 200 OK
INFO:     91.236.239.224:0 - "POST / HTTP/1.1" 405 Method Not Allowed
INFO:     45.146.165.37:0 - "GET / HTTP/1.1" 200 OK
INFO:     192.241.217.80:0 - "GET /actuator/health HTTP/1.1" 404 Not Found
INFO:     45.146.165.37:0 - "GET / HTTP/1.1" 200 OK
INFO:     103.141.137.205:0 - "GET /.env HTTP/1.1" 404 Not Found
INFO:     103.141.137.205:0 - "POST / HTTP/1.1" 405 Method Not Allowed
INFO:     185.83.214.69:0 - "GET / HTTP/1.1" 200 OK
INFO:     45.154.255.147:0 - "GET /favicon.ico HTTP/1.1" 404 Not Found
INFO:     172.69.31.207:0 - "GET / HTTP/1.1" 200 OK
INFO:     172.69.31.207:0 - "GET / HTTP/1.1" 200 OK
INFO:     172.69.31.207:0 - "GET / HTTP/1.1" 200 OK
INFO:     192.241.206.89:0 - "GET / HTTP/1.1" 200 OK
INFO:     71.6.232.7:0 - "GET / HTTP/1.1" 200 OK
INFO:     40.114.126.32:0 - "GET /.git/config HTTP/1.1" 404 Not Found
INFO:     34.96.130.24:0 - "GET / HTTP/1.1" 200 OK
INFO:     54.198.93.154:0 - "GET /.env HTTP/1.1" 404 Not Found
INFO:     54.198.93.154:0 - "POST / HTTP/1.1" 405 Method Not Allowed
INFO:     65.49.20.68:0 - "GET / HTTP/1.1" 200 OK
INFO:     18.236.107.61:0 - "GET /.env HTTP/1.1" 404 Not Found
INFO:     18.236.107.61:0 - "POST / HTTP/1.1" 405 Method Not Allowed
INFO:     192.241.205.218:0 - "GET /ecp/Current/exporttool/microsoft.exchange.ediscovery.exporttool.application HTTP/1.1" 404 Not Found
INFO:     192.241.216.214:0 - "GET /owa/auth/logon.aspx?url=https%3a%2f%2f1%2fecp%2f HTTP/1.1" 404 Not Found
INFO:     40.114.126.32:0 - "GET /.git/config HTTP/1.1" 404 Not Found
INFO:     45.146.165.37:0 - "GET /vendor/phpunit/phpunit/src/Util/PHP/eval-stdin.php HTTP/1.1" 404 Not Found
INFO:     45.146.165.37:0 - "GET /index.php?s=/Index/\think\app/invokefunction&function=call_user_func_array&vars[0]=md5&vars[1][]=HelloThinkPHP21 HTTP/1.1" 404 Not Found
INFO:     35.172.228.187:0 - "GET /.env HTTP/1.1" 404 Not Found
INFO:     35.172.228.187:0 - "POST / HTTP/1.1" 405 Method Not Allowed
INFO:     45.146.165.37:0 - "POST /mifs/.%3B/services/LogService HTTP/1.1" 404 Not Found
INFO:     45.146.165.37:0 - "GET /console/ HTTP/1.1" 404 Not Found
INFO:     109.237.103.9:0 - "GET /.env HTTP/1.1" 404 Not Found
INFO:     45.146.165.37:0 - "POST /Autodiscover/Autodiscover.xml HTTP/1.1" 404 Not Found
WARNING:  Invalid HTTP request received.
Traceback (most recent call last):
  File "/home/partner_portal/virtual_env/lib/python3.8/site-packages/uvicorn/protocols/http/h11_impl.py", line 136, in handle_events
    event = self.conn.next_event()
  File "/home/partner_portal/virtual_env/lib/python3.8/site-packages/h11/_connection.py", line 443, in next_event
    exc._reraise_as_remote_protocol_error()
  File "/home/partner_portal/virtual_env/lib/python3.8/site-packages/h11/_util.py", line 76, in _reraise_as_remote_protocol_error
    raise self
  File "/home/partner_portal/virtual_env/lib/python3.8/site-packages/h11/_connection.py", line 425, in next_event
    event = self._extract_next_receive_event()
  File "/home/partner_portal/virtual_env/lib/python3.8/site-packages/h11/_connection.py", line 367, in _extract_next_receive_event
    event = self._reader(self._receive_buffer)
  File "/home/partner_portal/virtual_env/lib/python3.8/site-packages/h11/_readers.py", line 71, in maybe_read_from_IDLE_client
    raise LocalProtocolError("no request line received")
h11._util.RemoteProtocolError: no request line received
INFO:     178.79.148.229:53052 - "GET / HTTP/1.0" 200 OK
INFO:     178.79.148.229:53966 - "OPTIONS / HTTP/1.0" 405 Method Not Allowed
WARNING:  Invalid HTTP request received.
Traceback (most recent call last):
  File "/home/partner_portal/virtual_env/lib/python3.8/site-packages/uvicorn/protocols/http/h11_impl.py", line 136, in handle_events
    event = self.conn.next_event()
  File "/home/partner_portal/virtual_env/lib/python3.8/site-packages/h11/_connection.py", line 443, in next_event
    exc._reraise_as_remote_protocol_error()
  File "/home/partner_portal/virtual_env/lib/python3.8/site-packages/h11/_util.py", line 76, in _reraise_as_remote_protocol_error
    raise self
  File "/home/partner_portal/virtual_env/lib/python3.8/site-packages/h11/_connection.py", line 425, in next_event
    event = self._extract_next_receive_event()
  File "/home/partner_portal/virtual_env/lib/python3.8/site-packages/h11/_connection.py", line 367, in _extract_next_receive_event
    event = self._reader(self._receive_buffer)
  File "/home/partner_portal/virtual_env/lib/python3.8/site-packages/h11/_readers.py", line 72, in maybe_read_from_IDLE_client
    matches = validate(
  File "/home/partner_portal/virtual_env/lib/python3.8/site-packages/h11/_util.py", line 88, in validate
    raise LocalProtocolError(msg)
h11._util.RemoteProtocolError: illegal request line: bytearray(b'OPTIONS / RTSP/1.0')
INFO:     178.79.148.229:0 - "GET / HTTP/1.1" 200 OK
WARNING:  Invalid HTTP request received.
Traceback (most recent call last):
  File "/home/partner_portal/virtual_env/lib/python3.8/site-packages/uvicorn/protocols/http/h11_impl.py", line 136, in handle_events
    event = self.conn.next_event()
  File "/home/partner_portal/virtual_env/lib/python3.8/site-packages/h11/_connection.py", line 443, in next_event
    exc._reraise_as_remote_protocol_error()
  File "/home/partner_portal/virtual_env/lib/python3.8/site-packages/h11/_util.py", line 76, in _reraise_as_remote_protocol_error
    raise self
  File "/home/partner_portal/virtual_env/lib/python3.8/site-packages/h11/_connection.py", line 425, in next_event
    event = self._extract_next_receive_event()
  File "/home/partner_portal/virtual_env/lib/python3.8/site-packages/h11/_connection.py", line 367, in _extract_next_receive_event
    event = self._reader(self._receive_buffer)
  File "/home/partner_portal/virtual_env/lib/python3.8/site-packages/h11/_readers.py", line 68, in maybe_read_from_IDLE_client
    raise LocalProtocolError("illegal request line")
h11._util.RemoteProtocolError: illegal request line
INFO:     178.79.148.229:0 - "OPTIONS / HTTP/1.1" 405 Method Not Allowed
INFO:     178.79.148.229:0 - "GET /nice%20ports%2C/Trinity.txt.bak HTTP/1.1" 404 Not Found
WARNING:  Invalid HTTP request received.
Traceback (most recent call last):
  File "/home/partner_portal/virtual_env/lib/python3.8/site-packages/uvicorn/protocols/http/h11_impl.py", line 136, in handle_events
    event = self.conn.next_event()
  File "/home/partner_portal/virtual_env/lib/python3.8/site-packages/h11/_connection.py", line 443, in next_event
    exc._reraise_as_remote_protocol_error()
  File "/home/partner_portal/virtual_env/lib/python3.8/site-packages/h11/_util.py", line 76, in _reraise_as_remote_protocol_error
    raise self
  File "/home/partner_portal/virtual_env/lib/python3.8/site-packages/h11/_connection.py", line 425, in next_event
    event = self._extract_next_receive_event()
  File "/home/partner_portal/virtual_env/lib/python3.8/site-packages/h11/_connection.py", line 367, in _extract_next_receive_event
    event = self._reader(self._receive_buffer)
  File "/home/partner_portal/virtual_env/lib/python3.8/site-packages/h11/_readers.py", line 68, in maybe_read_from_IDLE_client
    raise LocalProtocolError("illegal request line")
h11._util.RemoteProtocolError: illegal request line
WARNING:  Invalid HTTP request received.
Traceback (most recent call last):
  File "/home/partner_portal/virtual_env/lib/python3.8/site-packages/uvicorn/protocols/http/h11_impl.py", line 136, in handle_events
    event = self.conn.next_event()
  File "/home/partner_portal/virtual_env/lib/python3.8/site-packages/h11/_connection.py", line 443, in next_event
    exc._reraise_as_remote_protocol_error()
  File "/home/partner_portal/virtual_env/lib/python3.8/site-packages/h11/_util.py", line 76, in _reraise_as_remote_protocol_error
    raise self
  File "/home/partner_portal/virtual_env/lib/python3.8/site-packages/h11/_connection.py", line 425, in next_event
    event = self._extract_next_receive_event()
  File "/home/partner_portal/virtual_env/lib/python3.8/site-packages/h11/_connection.py", line 367, in _extract_next_receive_event
    event = self._reader(self._receive_buffer)
  File "/home/partner_portal/virtual_env/lib/python3.8/site-packages/h11/_readers.py", line 68, in maybe_read_from_IDLE_client
    raise LocalProtocolError("illegal request line")
h11._util.RemoteProtocolError: illegal request line
WARNING:  Invalid HTTP request received.
Traceback (most recent call last):
  File "/home/partner_portal/virtual_env/lib/python3.8/site-packages/uvicorn/protocols/http/h11_impl.py", line 136, in handle_events
    event = self.conn.next_event()
  File "/home/partner_portal/virtual_env/lib/python3.8/site-packages/h11/_connection.py", line 443, in next_event
    exc._reraise_as_remote_protocol_error()
  File "/home/partner_portal/virtual_env/lib/python3.8/site-packages/h11/_util.py", line 76, in _reraise_as_remote_protocol_error
    raise self
  File "/home/partner_portal/virtual_env/lib/python3.8/site-packages/h11/_connection.py", line 425, in next_event
    event = self._extract_next_receive_event()
  File "/home/partner_portal/virtual_env/lib/python3.8/site-packages/h11/_connection.py", line 367, in _extract_next_receive_event
    event = self._reader(self._receive_buffer)
  File "/home/partner_portal/virtual_env/lib/python3.8/site-packages/h11/_readers.py", line 68, in maybe_read_from_IDLE_client
    raise LocalProtocolError("illegal request line")
h11._util.RemoteProtocolError: illegal request line
WARNING:  Invalid HTTP request received.
Traceback (most recent call last):
  File "/home/partner_portal/virtual_env/lib/python3.8/site-packages/uvicorn/protocols/http/h11_impl.py", line 136, in handle_events
    event = self.conn.next_event()
  File "/home/partner_portal/virtual_env/lib/python3.8/site-packages/h11/_connection.py", line 443, in next_event
    exc._reraise_as_remote_protocol_error()
  File "/home/partner_portal/virtual_env/lib/python3.8/site-packages/h11/_util.py", line 76, in _reraise_as_remote_protocol_error
    raise self
  File "/home/partner_portal/virtual_env/lib/python3.8/site-packages/h11/_connection.py", line 425, in next_event
    event = self._extract_next_receive_event()
  File "/home/partner_portal/virtual_env/lib/python3.8/site-packages/h11/_connection.py", line 367, in _extract_next_receive_event
    event = self._reader(self._receive_buffer)
  File "/home/partner_portal/virtual_env/lib/python3.8/site-packages/h11/_readers.py", line 68, in maybe_read_from_IDLE_client
    raise LocalProtocolError("illegal request line")
h11._util.RemoteProtocolError: illegal request line
WARNING:  Invalid HTTP request received.
Traceback (most recent call last):
  File "/home/partner_portal/virtual_env/lib/python3.8/site-packages/uvicorn/protocols/http/h11_impl.py", line 136, in handle_events
    event = self.conn.next_event()
  File "/home/partner_portal/virtual_env/lib/python3.8/site-packages/h11/_connection.py", line 443, in next_event
    exc._reraise_as_remote_protocol_error()
  File "/home/partner_portal/virtual_env/lib/python3.8/site-packages/h11/_util.py", line 76, in _reraise_as_remote_protocol_error
    raise self
  File "/home/partner_portal/virtual_env/lib/python3.8/site-packages/h11/_connection.py", line 425, in next_event
    event = self._extract_next_receive_event()
  File "/home/partner_portal/virtual_env/lib/python3.8/site-packages/h11/_connection.py", line 367, in _extract_next_receive_event
    event = self._reader(self._receive_buffer)
  File "/home/partner_portal/virtual_env/lib/python3.8/site-packages/h11/_readers.py", line 72, in maybe_read_from_IDLE_client
    matches = validate(
  File "/home/partner_portal/virtual_env/lib/python3.8/site-packages/h11/_util.py", line 88, in validate
    raise LocalProtocolError(msg)
h11._util.RemoteProtocolError: illegal request line: bytearray(b'OPTIONS sip:nm SIP/2.0')
INFO:     178.79.148.229:0 - "GET / HTTP/1.1" 200 OK
WARNING:  Invalid HTTP request received.
Traceback (most recent call last):
  File "/home/partner_portal/virtual_env/lib/python3.8/site-packages/uvicorn/protocols/http/h11_impl.py", line 136, in handle_events
    event = self.conn.next_event()
  File "/home/partner_portal/virtual_env/lib/python3.8/site-packages/h11/_connection.py", line 443, in next_event
    exc._reraise_as_remote_protocol_error()
  File "/home/partner_portal/virtual_env/lib/python3.8/site-packages/h11/_util.py", line 76, in _reraise_as_remote_protocol_error
    raise self
  File "/home/partner_portal/virtual_env/lib/python3.8/site-packages/h11/_connection.py", line 425, in next_event
    event = self._extract_next_receive_event()
  File "/home/partner_portal/virtual_env/lib/python3.8/site-packages/h11/_connection.py", line 367, in _extract_next_receive_event
    event = self._reader(self._receive_buffer)
  File "/home/partner_portal/virtual_env/lib/python3.8/site-packages/h11/_readers.py", line 68, in maybe_read_from_IDLE_client
    raise LocalProtocolError("illegal request line")
h11._util.RemoteProtocolError: illegal request line
INFO:     178.79.148.229:0 - "GET /nmaplowercheck1642528693 HTTP/1.1" 404 Not Found
WARNING:  Invalid HTTP request received.
Traceback (most recent call last):
  File "/home/partner_portal/virtual_env/lib/python3.8/site-packages/uvicorn/protocols/http/h11_impl.py", line 136, in handle_events
    event = self.conn.next_event()
  File "/home/partner_portal/virtual_env/lib/python3.8/site-packages/h11/_connection.py", line 443, in next_event
    exc._reraise_as_remote_protocol_error()
  File "/home/partner_portal/virtual_env/lib/python3.8/site-packages/h11/_util.py", line 76, in _reraise_as_remote_protocol_error
    raise self
  File "/home/partner_portal/virtual_env/lib/python3.8/site-packages/h11/_connection.py", line 425, in next_event
    event = self._extract_next_receive_event()
  File "/home/partner_portal/virtual_env/lib/python3.8/site-packages/h11/_connection.py", line 367, in _extract_next_receive_event
    event = self._reader(self._receive_buffer)
  File "/home/partner_portal/virtual_env/lib/python3.8/site-packages/h11/_readers.py", line 68, in maybe_read_from_IDLE_client
    raise LocalProtocolError("illegal request line")
h11._util.RemoteProtocolError: illegal request line
INFO:     178.79.148.229:0 - "GET /default.pl HTTP/1.1" 404 Not Found
INFO:     178.79.148.229:0 - "GET /Portal0000.htm HTTP/1.1" 404 Not Found
INFO:     178.79.148.229:0 - "GET /HNAP1 HTTP/1.1" 404 Not Found
INFO:     178.79.148.229:0 - "GET /Portal/Portal.mwsl HTTP/1.1" 404 Not Found
INFO:     178.79.148.229:0 - "GET /kLCb HTTP/1.1" 404 Not Found
INFO:     178.79.148.229:0 - "GET / HTTP/1.1" 200 OK
INFO:     178.79.148.229:0 - "GET /CSS/Miniweb.css HTTP/1.1" 404 Not Found
INFO:     178.79.148.229:56272 - "GET / HTTP/1.1" 200 OK
INFO:     178.79.148.229:0 - "GET /__Additional HTTP/1.1" 404 Not Found
INFO:     178.79.148.229:0 - "GET /indice.jhtml HTTP/1.1" 404 Not Found
WARNING:  Invalid HTTP request received.
Traceback (most recent call last):
  File "/home/partner_portal/virtual_env/lib/python3.8/site-packages/uvicorn/protocols/http/h11_impl.py", line 136, in handle_events
    event = self.conn.next_event()
  File "/home/partner_portal/virtual_env/lib/python3.8/site-packages/h11/_connection.py", line 443, in next_event
    exc._reraise_as_remote_protocol_error()
  File "/home/partner_portal/virtual_env/lib/python3.8/site-packages/h11/_util.py", line 76, in _reraise_as_remote_protocol_error
    raise self
  File "/home/partner_portal/virtual_env/lib/python3.8/site-packages/h11/_connection.py", line 425, in next_event
    event = self._extract_next_receive_event()
  File "/home/partner_portal/virtual_env/lib/python3.8/site-packages/h11/_connection.py", line 367, in _extract_next_receive_event
    event = self._reader(self._receive_buffer)
  File "/home/partner_portal/virtual_env/lib/python3.8/site-packages/h11/_readers.py", line 68, in maybe_read_from_IDLE_client
    raise LocalProtocolError("illegal request line")
h11._util.RemoteProtocolError: illegal request line
INFO:     178.79.148.229:0 - "GET /docs/cplugError.html/ HTTP/1.1" 404 Not Found
INFO:     178.79.148.229:0 - "GET / HTTP/1.1" 200 OK
INFO:     178.79.148.229:0 - "POST /scripts/WPnBr.dll HTTP/1.1" 404 Not Found
INFO:     178.79.148.229:0 - "GET /index.cgi HTTP/1.1" 404 Not Found
INFO:     178.79.148.229:0 - "POST /sdk HTTP/1.1" 404 Not Found
INFO:     178.79.148.229:0 - "GET / HTTP/1.1" 200 OK
INFO:     178.79.148.229:33632 - "GET http%3A//www.google.com HTTP/1.0" 404 Not Found
INFO:     178.79.148.229:0 - "GET /.git/HEAD HTTP/1.1" 404 Not Found
INFO:     178.79.148.229:0 - "GET /?=PHPE9568F36-D428-11d2-A769-00AA001ACF42 HTTP/1.1" 200 OK
INFO:     178.79.148.229:34324 - "HEAD http%3A//www.google.com HTTP/1.0" 404 Not Found
INFO:     178.79.148.229:0 - "GET /start.html HTTP/1.1" 404 Not Found
INFO:     178.79.148.229:0 - "GET /favicon.ico HTTP/1.1" 404 Not Found
INFO:     178.79.148.229:0 - "HEAD / HTTP/1.1" 405 Method Not Allowed
INFO:     178.79.148.229:35064 - "CONNECT www.google.com%3A80 HTTP/1.0" 404 Not Found
INFO:     178.79.148.229:0 - "GET /?=PHPB8B5F2A0-3C92-11d3-A3A9-4C7B08C10000 HTTP/1.1" 200 OK
INFO:     178.79.148.229:0 - "GET / HTTP/1.1" 200 OK
INFO:     178.79.148.229:0 - "GET / HTTP/1.1" 200 OK
INFO:     45.146.165.37:0 - "GET / HTTP/1.1" 200 OK
INFO:     194.48.199.78:0 - "GET / HTTP/1.1" 200 OK
INFO:     128.199.2.117:0 - "GET / HTTP/1.1" 200 OK
INFO:     128.199.2.117:0 - "GET /.git/config HTTP/1.1" 404 Not Found
INFO:     192.241.219.95:0 - "GET /owa/auth/x.js HTTP/1.1" 404 Not Found
INFO:     192.241.217.148:0 - "GET /ecp/Current/exporttool/microsoft.exchange.ediscovery.exporttool.application HTTP/1.1" 404 Not Found
INFO:     192.241.219.141:0 - "GET /owa/auth/logon.aspx HTTP/1.1" 404 Not Found
INFO:     109.248.6.17:0 - "GET /favicon.ico HTTP/1.1" 404 Not Found
INFO:     45.146.165.37:0 - "GET / HTTP/1.1" 200 OK
WARNING:  Invalid HTTP request received.
Traceback (most recent call last):
  File "/home/partner_portal/virtual_env/lib/python3.8/site-packages/uvicorn/protocols/http/h11_impl.py", line 136, in handle_events
    event = self.conn.next_event()
  File "/home/partner_portal/virtual_env/lib/python3.8/site-packages/h11/_connection.py", line 443, in next_event
    exc._reraise_as_remote_protocol_error()
  File "/home/partner_portal/virtual_env/lib/python3.8/site-packages/h11/_util.py", line 76, in _reraise_as_remote_protocol_error
    raise self
  File "/home/partner_portal/virtual_env/lib/python3.8/site-packages/h11/_connection.py", line 425, in next_event
    event = self._extract_next_receive_event()
  File "/home/partner_portal/virtual_env/lib/python3.8/site-packages/h11/_connection.py", line 367, in _extract_next_receive_event
    event = self._reader(self._receive_buffer)
  File "/home/partner_portal/virtual_env/lib/python3.8/site-packages/h11/_readers.py", line 68, in maybe_read_from_IDLE_client
    raise LocalProtocolError("illegal request line")
h11._util.RemoteProtocolError: illegal request line
WARNING:  Invalid HTTP request received.
Traceback (most recent call last):
  File "/home/partner_portal/virtual_env/lib/python3.8/site-packages/uvicorn/protocols/http/h11_impl.py", line 136, in handle_events
    event = self.conn.next_event()
  File "/home/partner_portal/virtual_env/lib/python3.8/site-packages/h11/_connection.py", line 443, in next_event
    exc._reraise_as_remote_protocol_error()
  File "/home/partner_portal/virtual_env/lib/python3.8/site-packages/h11/_util.py", line 76, in _reraise_as_remote_protocol_error
    raise self
  File "/home/partner_portal/virtual_env/lib/python3.8/site-packages/h11/_connection.py", line 425, in next_event
    event = self._extract_next_receive_event()
  File "/home/partner_portal/virtual_env/lib/python3.8/site-packages/h11/_connection.py", line 367, in _extract_next_receive_event
    event = self._reader(self._receive_buffer)
  File "/home/partner_portal/virtual_env/lib/python3.8/site-packages/h11/_readers.py", line 68, in maybe_read_from_IDLE_client
    raise LocalProtocolError("illegal request line")
h11._util.RemoteProtocolError: illegal request line
INFO:     45.129.56.200:42592 - "GET / HTTP/1.1" 200 OK
INFO:     185.220.101.59:22466 - "GET /favicon.ico HTTP/1.1" 404 Not Found
INFO:     34.140.248.32:0 - "GET / HTTP/1.1" 200 OK
INFO:     192.241.217.52:0 - "GET /ReportServer HTTP/1.1" 404 Not Found
INFO:     192.241.217.46:0 - "GET /login HTTP/1.1" 405 Method Not Allowed
INFO:     185.136.167.61:0 - "GET /.env HTTP/1.1" 404 Not Found
INFO:     185.136.167.61:0 - "POST / HTTP/1.1" 405 Method Not Allowed
INFO:     167.94.138.116:49324 - "GET / HTTP/1.1" 200 OK
INFO:     54.174.206.144:0 - "GET /.git/HEAD HTTP/1.1" 404 Not Found
INFO:     91.236.239.224:0 - "POST / HTTP/1.1" 405 Method Not Allowed
INFO:     109.237.103.123:0 - "GET /.env HTTP/1.1" 404 Not Found
INFO:     192.241.219.72:0 - "GET /actuator/health HTTP/1.1" 404 Not Found
INFO:     64.225.75.232:0 - "GET / HTTP/1.1" 200 OK
INFO:     185.162.235.245:61002 - "GET http%3A//dyn.epicgifs.net/test6956.php HTTP/1.1" 404 Not Found
INFO:     172.70.8.22:0 - "GET / HTTP/1.1" 200 OK
INFO:     172.70.8.22:0 - "GET / HTTP/1.1" 200 OK
INFO:     172.70.8.22:0 - "GET / HTTP/1.1" 200 OK
WARNING:  Invalid HTTP request received.
Traceback (most recent call last):
  File "/home/partner_portal/virtual_env/lib/python3.8/site-packages/uvicorn/protocols/http/h11_impl.py", line 136, in handle_events
    event = self.conn.next_event()
  File "/home/partner_portal/virtual_env/lib/python3.8/site-packages/h11/_connection.py", line 443, in next_event
    exc._reraise_as_remote_protocol_error()
  File "/home/partner_portal/virtual_env/lib/python3.8/site-packages/h11/_util.py", line 76, in _reraise_as_remote_protocol_error
    raise self
  File "/home/partner_portal/virtual_env/lib/python3.8/site-packages/h11/_connection.py", line 425, in next_event
    event = self._extract_next_receive_event()
  File "/home/partner_portal/virtual_env/lib/python3.8/site-packages/h11/_connection.py", line 367, in _extract_next_receive_event
    event = self._reader(self._receive_buffer)
  File "/home/partner_portal/virtual_env/lib/python3.8/site-packages/h11/_readers.py", line 71, in maybe_read_from_IDLE_client
    raise LocalProtocolError("no request line received")
h11._util.RemoteProtocolError: no request line received
INFO:     45.33.65.249:44764 - "GET / HTTP/1.0" 200 OK
INFO:     45.33.65.249:45158 - "OPTIONS / HTTP/1.0" 405 Method Not Allowed
WARNING:  Invalid HTTP request received.
Traceback (most recent call last):
  File "/home/partner_portal/virtual_env/lib/python3.8/site-packages/uvicorn/protocols/http/h11_impl.py", line 136, in handle_events
    event = self.conn.next_event()
  File "/home/partner_portal/virtual_env/lib/python3.8/site-packages/h11/_connection.py", line 443, in next_event
    exc._reraise_as_remote_protocol_error()
  File "/home/partner_portal/virtual_env/lib/python3.8/site-packages/h11/_util.py", line 76, in _reraise_as_remote_protocol_error
    raise self
  File "/home/partner_portal/virtual_env/lib/python3.8/site-packages/h11/_connection.py", line 425, in next_event
    event = self._extract_next_receive_event()
  File "/home/partner_portal/virtual_env/lib/python3.8/site-packages/h11/_connection.py", line 367, in _extract_next_receive_event
    event = self._reader(self._receive_buffer)
  File "/home/partner_portal/virtual_env/lib/python3.8/site-packages/h11/_readers.py", line 72, in maybe_read_from_IDLE_client
    matches = validate(
  File "/home/partner_portal/virtual_env/lib/python3.8/site-packages/h11/_util.py", line 88, in validate
    raise LocalProtocolError(msg)
h11._util.RemoteProtocolError: illegal request line: bytearray(b'OPTIONS / RTSP/1.0')
INFO:     45.33.65.249:0 - "GET / HTTP/1.1" 200 OK
WARNING:  Invalid HTTP request received.
Traceback (most recent call last):
  File "/home/partner_portal/virtual_env/lib/python3.8/site-packages/uvicorn/protocols/http/h11_impl.py", line 136, in handle_events
    event = self.conn.next_event()
  File "/home/partner_portal/virtual_env/lib/python3.8/site-packages/h11/_connection.py", line 443, in next_event
    exc._reraise_as_remote_protocol_error()
  File "/home/partner_portal/virtual_env/lib/python3.8/site-packages/h11/_util.py", line 76, in _reraise_as_remote_protocol_error
    raise self
  File "/home/partner_portal/virtual_env/lib/python3.8/site-packages/h11/_connection.py", line 425, in next_event
    event = self._extract_next_receive_event()
  File "/home/partner_portal/virtual_env/lib/python3.8/site-packages/h11/_connection.py", line 367, in _extract_next_receive_event
    event = self._reader(self._receive_buffer)
  File "/home/partner_portal/virtual_env/lib/python3.8/site-packages/h11/_readers.py", line 68, in maybe_read_from_IDLE_client
    raise LocalProtocolError("illegal request line")
h11._util.RemoteProtocolError: illegal request line
INFO:     45.33.65.249:0 - "OPTIONS / HTTP/1.1" 405 Method Not Allowed
INFO:     45.33.65.249:0 - "GET /nice%20ports%2C/Trinity.txt.bak HTTP/1.1" 404 Not Found
WARNING:  Invalid HTTP request received.
Traceback (most recent call last):
  File "/home/partner_portal/virtual_env/lib/python3.8/site-packages/uvicorn/protocols/http/h11_impl.py", line 136, in handle_events
    event = self.conn.next_event()
  File "/home/partner_portal/virtual_env/lib/python3.8/site-packages/h11/_connection.py", line 443, in next_event
    exc._reraise_as_remote_protocol_error()
  File "/home/partner_portal/virtual_env/lib/python3.8/site-packages/h11/_util.py", line 76, in _reraise_as_remote_protocol_error
    raise self
  File "/home/partner_portal/virtual_env/lib/python3.8/site-packages/h11/_connection.py", line 425, in next_event
    event = self._extract_next_receive_event()
  File "/home/partner_portal/virtual_env/lib/python3.8/site-packages/h11/_connection.py", line 367, in _extract_next_receive_event
    event = self._reader(self._receive_buffer)
  File "/home/partner_portal/virtual_env/lib/python3.8/site-packages/h11/_readers.py", line 68, in maybe_read_from_IDLE_client
    raise LocalProtocolError("illegal request line")
h11._util.RemoteProtocolError: illegal request line
WARNING:  Invalid HTTP request received.
Traceback (most recent call last):
  File "/home/partner_portal/virtual_env/lib/python3.8/site-packages/uvicorn/protocols/http/h11_impl.py", line 136, in handle_events
    event = self.conn.next_event()
  File "/home/partner_portal/virtual_env/lib/python3.8/site-packages/h11/_connection.py", line 443, in next_event
    exc._reraise_as_remote_protocol_error()
  File "/home/partner_portal/virtual_env/lib/python3.8/site-packages/h11/_util.py", line 76, in _reraise_as_remote_protocol_error
    raise self
  File "/home/partner_portal/virtual_env/lib/python3.8/site-packages/h11/_connection.py", line 425, in next_event
    event = self._extract_next_receive_event()
  File "/home/partner_portal/virtual_env/lib/python3.8/site-packages/h11/_connection.py", line 367, in _extract_next_receive_event
    event = self._reader(self._receive_buffer)
  File "/home/partner_portal/virtual_env/lib/python3.8/site-packages/h11/_readers.py", line 68, in maybe_read_from_IDLE_client
    raise LocalProtocolError("illegal request line")
h11._util.RemoteProtocolError: illegal request line
WARNING:  Invalid HTTP request received.
Traceback (most recent call last):
  File "/home/partner_portal/virtual_env/lib/python3.8/site-packages/uvicorn/protocols/http/h11_impl.py", line 136, in handle_events
    event = self.conn.next_event()
  File "/home/partner_portal/virtual_env/lib/python3.8/site-packages/h11/_connection.py", line 443, in next_event
    exc._reraise_as_remote_protocol_error()
  File "/home/partner_portal/virtual_env/lib/python3.8/site-packages/h11/_util.py", line 76, in _reraise_as_remote_protocol_error
    raise self
  File "/home/partner_portal/virtual_env/lib/python3.8/site-packages/h11/_connection.py", line 425, in next_event
    event = self._extract_next_receive_event()
  File "/home/partner_portal/virtual_env/lib/python3.8/site-packages/h11/_connection.py", line 367, in _extract_next_receive_event
    event = self._reader(self._receive_buffer)
  File "/home/partner_portal/virtual_env/lib/python3.8/site-packages/h11/_readers.py", line 68, in maybe_read_from_IDLE_client
    raise LocalProtocolError("illegal request line")
h11._util.RemoteProtocolError: illegal request line
WARNING:  Invalid HTTP request received.
Traceback (most recent call last):
  File "/home/partner_portal/virtual_env/lib/python3.8/site-packages/uvicorn/protocols/http/h11_impl.py", line 136, in handle_events
    event = self.conn.next_event()
  File "/home/partner_portal/virtual_env/lib/python3.8/site-packages/h11/_connection.py", line 443, in next_event
    exc._reraise_as_remote_protocol_error()
  File "/home/partner_portal/virtual_env/lib/python3.8/site-packages/h11/_util.py", line 76, in _reraise_as_remote_protocol_error
    raise self
  File "/home/partner_portal/virtual_env/lib/python3.8/site-packages/h11/_connection.py", line 425, in next_event
    event = self._extract_next_receive_event()
  File "/home/partner_portal/virtual_env/lib/python3.8/site-packages/h11/_connection.py", line 367, in _extract_next_receive_event
    event = self._reader(self._receive_buffer)
  File "/home/partner_portal/virtual_env/lib/python3.8/site-packages/h11/_readers.py", line 68, in maybe_read_from_IDLE_client
    raise LocalProtocolError("illegal request line")
h11._util.RemoteProtocolError: illegal request line
WARNING:  Invalid HTTP request received.
Traceback (most recent call last):
  File "/home/partner_portal/virtual_env/lib/python3.8/site-packages/uvicorn/protocols/http/h11_impl.py", line 136, in handle_events
    event = self.conn.next_event()
  File "/home/partner_portal/virtual_env/lib/python3.8/site-packages/h11/_connection.py", line 443, in next_event
    exc._reraise_as_remote_protocol_error()
  File "/home/partner_portal/virtual_env/lib/python3.8/site-packages/h11/_util.py", line 76, in _reraise_as_remote_protocol_error
    raise self
  File "/home/partner_portal/virtual_env/lib/python3.8/site-packages/h11/_connection.py", line 425, in next_event
    event = self._extract_next_receive_event()
  File "/home/partner_portal/virtual_env/lib/python3.8/site-packages/h11/_connection.py", line 367, in _extract_next_receive_event
    event = self._reader(self._receive_buffer)
  File "/home/partner_portal/virtual_env/lib/python3.8/site-packages/h11/_readers.py", line 72, in maybe_read_from_IDLE_client
    matches = validate(
  File "/home/partner_portal/virtual_env/lib/python3.8/site-packages/h11/_util.py", line 88, in validate
    raise LocalProtocolError(msg)
h11._util.RemoteProtocolError: illegal request line: bytearray(b'OPTIONS sip:nm SIP/2.0')
INFO:     45.33.65.249:0 - "GET / HTTP/1.1" 200 OK
INFO:     45.33.65.249:0 - "GET /Portal0000.htm HTTP/1.1" 404 Not Found
INFO:     45.33.65.249:0 - "GET /nmaplowercheck1642572323 HTTP/1.1" 404 Not Found
INFO:     45.33.65.249:0 - "GET /?=PHPE9568F36-D428-11d2-A769-00AA001ACF42 HTTP/1.1" 200 OK
INFO:     45.33.65.249:0 - "GET /HNAP1 HTTP/1.1" 404 Not Found
INFO:     45.33.65.249:0 - "GET /?=PHPB8B5F2A0-3C92-11d3-A3A9-4C7B08C10000 HTTP/1.1" 200 OK
INFO:     45.33.65.249:0 - "GET /__Additional HTTP/1.1" 404 Not Found
INFO:     45.33.65.249:0 - "GET / HTTP/1.1" 200 OK
INFO:     45.33.65.249:0 - "GET / HTTP/1.1" 200 OK
INFO:     45.33.65.249:0 - "GET /Portal/Portal.mwsl HTTP/1.1" 404 Not Found
WARNING:  Invalid HTTP request received.
Traceback (most recent call last):
  File "/home/partner_portal/virtual_env/lib/python3.8/site-packages/uvicorn/protocols/http/h11_impl.py", line 136, in handle_events
    event = self.conn.next_event()
  File "/home/partner_portal/virtual_env/lib/python3.8/site-packages/h11/_connection.py", line 443, in next_event
    exc._reraise_as_remote_protocol_error()
  File "/home/partner_portal/virtual_env/lib/python3.8/site-packages/h11/_util.py", line 76, in _reraise_as_remote_protocol_error
    raise self
  File "/home/partner_portal/virtual_env/lib/python3.8/site-packages/h11/_connection.py", line 425, in next_event
    event = self._extract_next_receive_event()
  File "/home/partner_portal/virtual_env/lib/python3.8/site-packages/h11/_connection.py", line 367, in _extract_next_receive_event
    event = self._reader(self._receive_buffer)
  File "/home/partner_portal/virtual_env/lib/python3.8/site-packages/h11/_readers.py", line 68, in maybe_read_from_IDLE_client
    raise LocalProtocolError("illegal request line")
h11._util.RemoteProtocolError: illegal request line
INFO:     45.33.65.249:0 - "POST /scripts/WPnBr.dll HTTP/1.1" 404 Not Found
WARNING:  Invalid HTTP request received.
Traceback (most recent call last):
  File "/home/partner_portal/virtual_env/lib/python3.8/site-packages/uvicorn/protocols/http/h11_impl.py", line 136, in handle_events
    event = self.conn.next_event()
  File "/home/partner_portal/virtual_env/lib/python3.8/site-packages/h11/_connection.py", line 443, in next_event
    exc._reraise_as_remote_protocol_error()
  File "/home/partner_portal/virtual_env/lib/python3.8/site-packages/h11/_util.py", line 76, in _reraise_as_remote_protocol_error
    raise self
  File "/home/partner_portal/virtual_env/lib/python3.8/site-packages/h11/_connection.py", line 425, in next_event
    event = self._extract_next_receive_event()
  File "/home/partner_portal/virtual_env/lib/python3.8/site-packages/h11/_connection.py", line 367, in _extract_next_receive_event
    event = self._reader(self._receive_buffer)
  File "/home/partner_portal/virtual_env/lib/python3.8/site-packages/h11/_readers.py", line 68, in maybe_read_from_IDLE_client
    raise LocalProtocolError("illegal request line")
h11._util.RemoteProtocolError: illegal request line
INFO:     45.33.65.249:0 - "GET /localstart.pl HTTP/1.1" 404 Not Found
INFO:     45.33.65.249:0 - "HEAD / HTTP/1.1" 405 Method Not Allowed
WARNING:  Invalid HTTP request received.
Traceback (most recent call last):
  File "/home/partner_portal/virtual_env/lib/python3.8/site-packages/uvicorn/protocols/http/h11_impl.py", line 136, in handle_events
    event = self.conn.next_event()
  File "/home/partner_portal/virtual_env/lib/python3.8/site-packages/h11/_connection.py", line 443, in next_event
    exc._reraise_as_remote_protocol_error()
  File "/home/partner_portal/virtual_env/lib/python3.8/site-packages/h11/_util.py", line 76, in _reraise_as_remote_protocol_error
    raise self
  File "/home/partner_portal/virtual_env/lib/python3.8/site-packages/h11/_connection.py", line 425, in next_event
    event = self._extract_next_receive_event()
  File "/home/partner_portal/virtual_env/lib/python3.8/site-packages/h11/_connection.py", line 367, in _extract_next_receive_event
    event = self._reader(self._receive_buffer)
  File "/home/partner_portal/virtual_env/lib/python3.8/site-packages/h11/_readers.py", line 68, in maybe_read_from_IDLE_client
    raise LocalProtocolError("illegal request line")
h11._util.RemoteProtocolError: illegal request line
INFO:     45.33.65.249:0 - "GET /docs/cplugError.html/ HTTP/1.1" 404 Not Found
INFO:     45.33.65.249:46166 - "GET http%3A//www.google.com HTTP/1.0" 404 Not Found
INFO:     45.33.65.249:0 - "GET /default.jhtml HTTP/1.1" 404 Not Found
INFO:     45.33.65.249:46684 - "HEAD http%3A//www.google.com HTTP/1.0" 404 Not Found
INFO:     45.33.65.249:0 - "GET / HTTP/1.1" 200 OK
INFO:     45.33.65.249:42818 - "GET / HTTP/1.1" 200 OK
INFO:     45.33.65.249:0 - "GET / HTTP/1.1" 200 OK
INFO:     45.33.65.249:0 - "GET /CSS/Miniweb.css HTTP/1.1" 404 Not Found
INFO:     45.33.65.249:47346 - "CONNECT www.google.com%3A80 HTTP/1.0" 404 Not Found
INFO:     45.33.65.249:0 - "GET /.git/HEAD HTTP/1.1" 404 Not Found
INFO:     45.33.65.249:0 - "GET /default.shtml HTTP/1.1" 404 Not Found
INFO:     45.33.65.249:0 - "POST /sdk HTTP/1.1" 404 Not Found
INFO:     45.33.65.249:0 - "GET /favicon.ico HTTP/1.1" 404 Not Found
INFO:     45.33.65.249:0 - "GET /hEfI HTTP/1.1" 404 Not Found
INFO:     45.33.65.249:0 - "GET /localstart.cgi HTTP/1.1" 404 Not Found
INFO:     45.33.65.249:0 - "GET /index.cgi HTTP/1.1" 404 Not Found
INFO:     45.33.65.249:0 - "GET / HTTP/1.1" 200 OK
INFO:     45.33.65.249:0 - "GET / HTTP/1.1" 200 OK
INFO:     192.241.208.68:0 - "GET / HTTP/1.1" 200 OK
INFO:     45.83.67.38:0 - "GET / HTTP/1.1" 200 OK
INFO:     45.83.67.191:0 - "GET /favicon.ico HTTP/1.1" 404 Not Found
INFO:     109.237.103.38:0 - "GET /.env HTTP/1.1" 404 Not Found
INFO:     45.146.165.37:0 - "POST /vendor/phpunit/phpunit/src/Util/PHP/eval-stdin.php HTTP/1.1" 404 Not Found
INFO:     45.146.165.37:0 - "GET /index.php?s=/Index/\think\app/invokefunction&function=call_user_func_array&vars[0]=md5&vars[1][]=HelloThinkPHP21 HTTP/1.1" 404 Not Found
INFO:     45.146.165.37:0 - "GET /?XDEBUG_SESSION_START=phpstorm HTTP/1.1" 200 OK
INFO:     45.146.165.37:0 - "POST /mifs/.%3B/services/LogService HTTP/1.1" 404 Not Found
INFO:     91.90.123.91:0 - "GET / HTTP/1.1" 200 OK
INFO:     192.241.219.179:0 - "GET /ecp/Current/exporttool/microsoft.exchange.ediscovery.exporttool.application HTTP/1.1" 404 Not Found
INFO:     192.241.217.36:0 - "GET /owa/auth/logon.aspx?url=https%3a%2f%2f1%2fecp%2f HTTP/1.1" 404 Not Found
INFO:     45.146.165.37:0 - "GET /console/ HTTP/1.1" 404 Not Found
INFO:     102.129.145.16:0 - "GET /aaa9 HTTP/1.1" 404 Not Found
INFO:     185.136.167.62:0 - "GET /.env HTTP/1.1" 404 Not Found
INFO:     185.136.167.62:0 - "POST / HTTP/1.1" 405 Method Not Allowed
INFO:     45.146.165.37:0 - "POST /Autodiscover/Autodiscover.xml HTTP/1.1" 404 Not Found
INFO:     45.146.165.37:0 - "GET /_ignition/execute-solution HTTP/1.1" 404 Not Found
INFO:     162.142.125.196:0 - "GET / HTTP/1.1" 200 OK
INFO:     162.142.125.196:0 - "GET / HTTP/1.1" 200 OK
INFO:     45.146.165.37:0 - "GET / HTTP/1.1" 200 OK
INFO:     139.162.214.213:0 - "GET / HTTP/1.1" 200 OK
INFO:     45.146.165.37:0 - "GET / HTTP/1.1" 200 OK
INFO:     47.90.177.97:0 - "GET / HTTP/1.1" 200 OK
INFO:     47.90.177.97:0 - "OPTIONS / HTTP/1.1" 405 Method Not Allowed
INFO:     47.90.177.97:0 - "GET /nice%20ports%2C/Trinity.txt.bak HTTP/1.1" 404 Not Found
INFO:     47.90.177.97:0 - "GET /text4041642628214 HTTP/1.1" 404 Not Found
INFO:     47.90.177.97:0 - "GET / HTTP/1.1" 200 OK
INFO:     47.90.177.97:0 - "GET /HNAP1 HTTP/1.1" 404 Not Found
INFO:     47.90.177.97:0 - "GET / HTTP/1.1" 200 OK
INFO:     47.90.177.97:0 - "POST /sdk HTTP/1.1" 404 Not Found
INFO:     47.90.177.97:0 - "GET /evox/about HTTP/1.1" 404 Not Found
INFO:     47.90.177.97:0 - "GET / HTTP/1.1" 200 OK
INFO:     47.90.177.97:0 - "GET /favicon.ico HTTP/1.1" 404 Not Found
INFO:     47.90.177.97:0 - "GET /robots.txt HTTP/1.1" 404 Not Found
INFO:     165.154.21.120:0 - "GET / HTTP/1.1" 200 OK
INFO:     35.233.62.116:0 - "GET / HTTP/1.1" 200 OK
INFO:     185.136.167.62:0 - "GET /.env HTTP/1.1" 404 Not Found
INFO:     185.136.167.62:0 - "POST / HTTP/1.1" 405 Method Not Allowed
INFO:     185.136.167.60:0 - "GET /.env HTTP/1.1" 404 Not Found
INFO:     185.136.167.60:0 - "POST / HTTP/1.1" 405 Method Not Allowed
INFO:     222.186.19.235:37996 - "GET http%3A//fuwu.sogou.com/404/index.html HTTP/1.1" 404 Not Found
INFO:     222.186.19.235:37990 - "GET http%3A//fuwu.sogou.com/404/index.html HTTP/1.1" 404 Not Found
WARNING:  Invalid HTTP request received.
Traceback (most recent call last):
  File "/home/partner_portal/virtual_env/lib/python3.8/site-packages/uvicorn/protocols/http/h11_impl.py", line 136, in handle_events
    event = self.conn.next_event()
  File "/home/partner_portal/virtual_env/lib/python3.8/site-packages/h11/_connection.py", line 443, in next_event
    exc._reraise_as_remote_protocol_error()
  File "/home/partner_portal/virtual_env/lib/python3.8/site-packages/h11/_util.py", line 76, in _reraise_as_remote_protocol_error
    raise self
  File "/home/partner_portal/virtual_env/lib/python3.8/site-packages/h11/_connection.py", line 425, in next_event
    event = self._extract_next_receive_event()
  File "/home/partner_portal/virtual_env/lib/python3.8/site-packages/h11/_connection.py", line 367, in _extract_next_receive_event
    event = self._reader(self._receive_buffer)
  File "/home/partner_portal/virtual_env/lib/python3.8/site-packages/h11/_readers.py", line 68, in maybe_read_from_IDLE_client
    raise LocalProtocolError("illegal request line")
h11._util.RemoteProtocolError: illegal request line
INFO:     138.246.253.24:0 - "GET /robots.txt HTTP/1.1" 404 Not Found
INFO:     185.136.167.60:0 - "GET /.env HTTP/1.1" 404 Not Found
INFO:     194.48.199.78:0 - "GET / HTTP/1.1" 200 OK
INFO:     45.146.165.168:0 - "POST /RestAPI/LogonCustomization HTTP/1.1" 404 Not Found
INFO:     167.99.190.92:0 - "GET /system_api.php HTTP/1.1" 404 Not Found
INFO:     167.99.190.92:0 - "GET /c/version.js HTTP/1.1" 404 Not Found
INFO:     167.99.190.92:0 - "GET /streaming/clients_live.php HTTP/1.1" 404 Not Found
INFO:     167.99.190.92:0 - "GET /stalker_portal/c/version.js HTTP/1.1" 404 Not Found
INFO:     167.99.190.92:0 - "GET /stream/live.php HTTP/1.1" 404 Not Found
INFO:     167.99.190.92:0 - "GET /flu/403.html HTTP/1.1" 404 Not Found
INFO:     167.99.190.92:0 - "GET / HTTP/1.1" 200 OK
INFO:     172.70.1.76:0 - "GET / HTTP/1.1" 200 OK
INFO:     172.70.1.76:0 - "GET / HTTP/1.1" 200 OK
INFO:     172.70.1.76:0 - "GET / HTTP/1.1" 200 OK
INFO:     184.105.139.70:0 - "GET / HTTP/1.1" 200 OK
INFO:     66.240.236.109:0 - "GET / HTTP/1.1" 200 OK
INFO:     45.146.165.37:0 - "GET /index.php?s=/Index/\think\app/invokefunction&function=call_user_func_array&vars[0]=md5&vars[1][]=HelloThinkPHP21 HTTP/1.1" 404 Not Found
INFO:     192.241.217.239:0 - "GET /actuator/health HTTP/1.1" 404 Not Found
INFO:     45.146.165.37:0 - "GET /?XDEBUG_SESSION_START=phpstorm HTTP/1.1" 200 OK
INFO:     89.248.173.131:0 - "GET /remote/login?lang=en HTTP/1.1" 404 Not Found
INFO:     204.15.74.102:0 - "GET / HTTP/1.1" 200 OK
INFO:     45.146.165.37:0 - "POST /mifs/.%3B/services/LogService HTTP/1.1" 404 Not Found
WARNING:  Invalid HTTP request received.
Traceback (most recent call last):
  File "/home/partner_portal/virtual_env/lib/python3.8/site-packages/uvicorn/protocols/http/h11_impl.py", line 136, in handle_events
    event = self.conn.next_event()
  File "/home/partner_portal/virtual_env/lib/python3.8/site-packages/h11/_connection.py", line 443, in next_event
    exc._reraise_as_remote_protocol_error()
  File "/home/partner_portal/virtual_env/lib/python3.8/site-packages/h11/_util.py", line 76, in _reraise_as_remote_protocol_error
    raise self
  File "/home/partner_portal/virtual_env/lib/python3.8/site-packages/h11/_connection.py", line 425, in next_event
    event = self._extract_next_receive_event()
  File "/home/partner_portal/virtual_env/lib/python3.8/site-packages/h11/_connection.py", line 367, in _extract_next_receive_event
    event = self._reader(self._receive_buffer)
  File "/home/partner_portal/virtual_env/lib/python3.8/site-packages/h11/_readers.py", line 68, in maybe_read_from_IDLE_client
    raise LocalProtocolError("illegal request line")
h11._util.RemoteProtocolError: illegal request line
INFO:     45.146.165.37:0 - "GET /console/ HTTP/1.1" 404 Not Found
INFO:     45.146.165.37:0 - "POST /Autodiscover/Autodiscover.xml HTTP/1.1" 404 Not Found
INFO:     167.94.138.42:0 - "GET / HTTP/1.1" 200 OK
INFO:     167.94.138.42:0 - "GET / HTTP/1.1" 200 OK
INFO:     185.136.167.61:0 - "GET /.env HTTP/1.1" 404 Not Found
INFO:     185.136.167.61:0 - "POST / HTTP/1.1" 405 Method Not Allowed
INFO:     109.237.103.9:0 - "GET /.env HTTP/1.1" 404 Not Found
INFO:     192.241.219.159:0 - "GET / HTTP/1.1" 200 OK
INFO:     45.143.144.187:0 - "GET /.env HTTP/1.1" 404 Not Found
INFO:     45.143.144.187:0 - "POST / HTTP/1.1" 405 Method Not Allowed
INFO:     45.146.165.37:0 - "GET / HTTP/1.1" 200 OK
INFO:     45.146.165.37:0 - "GET / HTTP/1.1" 200 OK
INFO:     192.241.220.23:0 - "GET /ecp/Current/exporttool/microsoft.exchange.ediscovery.exporttool.application HTTP/1.1" 404 Not Found
INFO:     20.55.53.144:0 - "GET /ExV6hcWAJGgrlFq1MdZykK7zItJ HTTP/1.1" 404 Not Found
INFO:     192.241.206.181:0 - "GET /owa/auth/logon.aspx?url=https%3a%2f%2f1%2fecp%2f HTTP/1.1" 404 Not Found
INFO:     185.142.236.43:0 - "GET / HTTP/1.1" 200 OK
INFO:     174.7.32.199:0 - "GET /aaa9 HTTP/1.1" 404 Not Found
INFO:     45.146.165.37:0 - "GET / HTTP/1.1" 200 OK
INFO:     109.237.103.118:0 - "GET /.env HTTP/1.1" 404 Not Found
INFO:     131.153.240.10:0 - "GET / HTTP/1.1" 200 OK
INFO:     185.142.236.34:33606 - "GET / HTTP/1.1" 200 OK
INFO:     185.142.236.34:35292 - "GET /favicon.ico HTTP/1.1" 404 Not Found
WARNING:  Invalid HTTP request received.
Traceback (most recent call last):
  File "/home/partner_portal/virtual_env/lib/python3.8/site-packages/uvicorn/protocols/http/h11_impl.py", line 136, in handle_events
    event = self.conn.next_event()
  File "/home/partner_portal/virtual_env/lib/python3.8/site-packages/h11/_connection.py", line 443, in next_event
    exc._reraise_as_remote_protocol_error()
  File "/home/partner_portal/virtual_env/lib/python3.8/site-packages/h11/_util.py", line 76, in _reraise_as_remote_protocol_error
    raise self
  File "/home/partner_portal/virtual_env/lib/python3.8/site-packages/h11/_connection.py", line 425, in next_event
    event = self._extract_next_receive_event()
  File "/home/partner_portal/virtual_env/lib/python3.8/site-packages/h11/_connection.py", line 367, in _extract_next_receive_event
    event = self._reader(self._receive_buffer)
  File "/home/partner_portal/virtual_env/lib/python3.8/site-packages/h11/_readers.py", line 68, in maybe_read_from_IDLE_client
    raise LocalProtocolError("illegal request line")
h11._util.RemoteProtocolError: illegal request line
INFO:     34.140.248.32:41908 - "GET / HTTP/1.1" 200 OK
WARNING:  Invalid HTTP request received.
Traceback (most recent call last):
  File "/home/partner_portal/virtual_env/lib/python3.8/site-packages/uvicorn/protocols/http/h11_impl.py", line 136, in handle_events
    event = self.conn.next_event()
  File "/home/partner_portal/virtual_env/lib/python3.8/site-packages/h11/_connection.py", line 443, in next_event
    exc._reraise_as_remote_protocol_error()
  File "/home/partner_portal/virtual_env/lib/python3.8/site-packages/h11/_util.py", line 76, in _reraise_as_remote_protocol_error
    raise self
  File "/home/partner_portal/virtual_env/lib/python3.8/site-packages/h11/_connection.py", line 425, in next_event
    event = self._extract_next_receive_event()
  File "/home/partner_portal/virtual_env/lib/python3.8/site-packages/h11/_connection.py", line 367, in _extract_next_receive_event
    event = self._reader(self._receive_buffer)
  File "/home/partner_portal/virtual_env/lib/python3.8/site-packages/h11/_readers.py", line 68, in maybe_read_from_IDLE_client
    raise LocalProtocolError("illegal request line")
h11._util.RemoteProtocolError: illegal request line
INFO:     167.248.133.115:56174 - "GET / HTTP/1.1" 200 OK
INFO:     167.248.133.115:48102 - "GET / HTTP/1.1" 200 OK
INFO:     148.72.176.52:0 - "GET /remote/fgt_lang?lang=/../../../..//////////dev/cmdb/sslvpn_websession HTTP/1.1" 404 Not Found
INFO:     193.160.21.36:0 - "GET /.env HTTP/1.1" 404 Not Found
INFO:     193.160.21.36:0 - "POST / HTTP/1.1" 405 Method Not Allowed
INFO:     141.98.83.139:0 - "GET /owa/auth.owa HTTP/1.1" 404 Not Found
INFO:     109.248.6.74:0 - "GET /favicon.ico HTTP/1.1" 404 Not Found
INFO:     45.87.62.185:0 - "GET /.env HTTP/1.1" 404 Not Found
INFO:     45.87.62.185:0 - "POST / HTTP/1.1" 405 Method Not Allowed
INFO:     20.55.53.144:0 - "GET / HTTP/1.1" 200 OK
INFO:     130.211.54.158:0 - "GET / HTTP/1.1" 200 OK
INFO:     109.237.103.123:0 - "GET /.env HTTP/1.1" 404 Not Found
INFO:     45.146.165.37:0 - "POST /vendor/phpunit/phpunit/src/Util/PHP/eval-stdin.php HTTP/1.1" 404 Not Found
WARNING:  Invalid HTTP request received.
Traceback (most recent call last):
  File "/home/partner_portal/virtual_env/lib/python3.8/site-packages/uvicorn/protocols/http/h11_impl.py", line 136, in handle_events
    event = self.conn.next_event()
  File "/home/partner_portal/virtual_env/lib/python3.8/site-packages/h11/_connection.py", line 443, in next_event
    exc._reraise_as_remote_protocol_error()
  File "/home/partner_portal/virtual_env/lib/python3.8/site-packages/h11/_util.py", line 76, in _reraise_as_remote_protocol_error
    raise self
  File "/home/partner_portal/virtual_env/lib/python3.8/site-packages/h11/_connection.py", line 425, in next_event
    event = self._extract_next_receive_event()
  File "/home/partner_portal/virtual_env/lib/python3.8/site-packages/h11/_connection.py", line 367, in _extract_next_receive_event
    event = self._reader(self._receive_buffer)
  File "/home/partner_portal/virtual_env/lib/python3.8/site-packages/h11/_readers.py", line 71, in maybe_read_from_IDLE_client
    raise LocalProtocolError("no request line received")
h11._util.RemoteProtocolError: no request line received
INFO:     45.33.65.249:40410 - "GET / HTTP/1.0" 200 OK
INFO:     45.33.65.249:40808 - "OPTIONS / HTTP/1.0" 405 Method Not Allowed
WARNING:  Invalid HTTP request received.
Traceback (most recent call last):
  File "/home/partner_portal/virtual_env/lib/python3.8/site-packages/uvicorn/protocols/http/h11_impl.py", line 136, in handle_events
    event = self.conn.next_event()
  File "/home/partner_portal/virtual_env/lib/python3.8/site-packages/h11/_connection.py", line 443, in next_event
    exc._reraise_as_remote_protocol_error()
  File "/home/partner_portal/virtual_env/lib/python3.8/site-packages/h11/_util.py", line 76, in _reraise_as_remote_protocol_error
    raise self
  File "/home/partner_portal/virtual_env/lib/python3.8/site-packages/h11/_connection.py", line 425, in next_event
    event = self._extract_next_receive_event()
  File "/home/partner_portal/virtual_env/lib/python3.8/site-packages/h11/_connection.py", line 367, in _extract_next_receive_event
    event = self._reader(self._receive_buffer)
  File "/home/partner_portal/virtual_env/lib/python3.8/site-packages/h11/_readers.py", line 72, in maybe_read_from_IDLE_client
    matches = validate(
  File "/home/partner_portal/virtual_env/lib/python3.8/site-packages/h11/_util.py", line 88, in validate
    raise LocalProtocolError(msg)
h11._util.RemoteProtocolError: illegal request line: bytearray(b'OPTIONS / RTSP/1.0')
INFO:     45.33.65.249:0 - "GET / HTTP/1.1" 200 OK
INFO:     45.33.65.249:0 - "OPTIONS / HTTP/1.1" 405 Method Not Allowed
WARNING:  Invalid HTTP request received.
Traceback (most recent call last):
  File "/home/partner_portal/virtual_env/lib/python3.8/site-packages/uvicorn/protocols/http/h11_impl.py", line 136, in handle_events
    event = self.conn.next_event()
  File "/home/partner_portal/virtual_env/lib/python3.8/site-packages/h11/_connection.py", line 443, in next_event
    exc._reraise_as_remote_protocol_error()
  File "/home/partner_portal/virtual_env/lib/python3.8/site-packages/h11/_util.py", line 76, in _reraise_as_remote_protocol_error
    raise self
  File "/home/partner_portal/virtual_env/lib/python3.8/site-packages/h11/_connection.py", line 425, in next_event
    event = self._extract_next_receive_event()
  File "/home/partner_portal/virtual_env/lib/python3.8/site-packages/h11/_connection.py", line 367, in _extract_next_receive_event
    event = self._reader(self._receive_buffer)
  File "/home/partner_portal/virtual_env/lib/python3.8/site-packages/h11/_readers.py", line 68, in maybe_read_from_IDLE_client
    raise LocalProtocolError("illegal request line")
h11._util.RemoteProtocolError: illegal request line
INFO:     45.33.65.249:0 - "GET /nice%20ports%2C/Trinity.txt.bak HTTP/1.1" 404 Not Found
WARNING:  Invalid HTTP request received.
Traceback (most recent call last):
  File "/home/partner_portal/virtual_env/lib/python3.8/site-packages/uvicorn/protocols/http/h11_impl.py", line 136, in handle_events
    event = self.conn.next_event()
  File "/home/partner_portal/virtual_env/lib/python3.8/site-packages/h11/_connection.py", line 443, in next_event
    exc._reraise_as_remote_protocol_error()
  File "/home/partner_portal/virtual_env/lib/python3.8/site-packages/h11/_util.py", line 76, in _reraise_as_remote_protocol_error
    raise self
  File "/home/partner_portal/virtual_env/lib/python3.8/site-packages/h11/_connection.py", line 425, in next_event
    event = self._extract_next_receive_event()
  File "/home/partner_portal/virtual_env/lib/python3.8/site-packages/h11/_connection.py", line 367, in _extract_next_receive_event
    event = self._reader(self._receive_buffer)
  File "/home/partner_portal/virtual_env/lib/python3.8/site-packages/h11/_readers.py", line 68, in maybe_read_from_IDLE_client
    raise LocalProtocolError("illegal request line")
h11._util.RemoteProtocolError: illegal request line
WARNING:  Invalid HTTP request received.
Traceback (most recent call last):
  File "/home/partner_portal/virtual_env/lib/python3.8/site-packages/uvicorn/protocols/http/h11_impl.py", line 136, in handle_events
    event = self.conn.next_event()
  File "/home/partner_portal/virtual_env/lib/python3.8/site-packages/h11/_connection.py", line 443, in next_event
    exc._reraise_as_remote_protocol_error()
  File "/home/partner_portal/virtual_env/lib/python3.8/site-packages/h11/_util.py", line 76, in _reraise_as_remote_protocol_error
    raise self
  File "/home/partner_portal/virtual_env/lib/python3.8/site-packages/h11/_connection.py", line 425, in next_event
    event = self._extract_next_receive_event()
  File "/home/partner_portal/virtual_env/lib/python3.8/site-packages/h11/_connection.py", line 367, in _extract_next_receive_event
    event = self._reader(self._receive_buffer)
  File "/home/partner_portal/virtual_env/lib/python3.8/site-packages/h11/_readers.py", line 68, in maybe_read_from_IDLE_client
    raise LocalProtocolError("illegal request line")
h11._util.RemoteProtocolError: illegal request line
WARNING:  Invalid HTTP request received.
Traceback (most recent call last):
  File "/home/partner_portal/virtual_env/lib/python3.8/site-packages/uvicorn/protocols/http/h11_impl.py", line 136, in handle_events
    event = self.conn.next_event()
  File "/home/partner_portal/virtual_env/lib/python3.8/site-packages/h11/_connection.py", line 443, in next_event
    exc._reraise_as_remote_protocol_error()
  File "/home/partner_portal/virtual_env/lib/python3.8/site-packages/h11/_util.py", line 76, in _reraise_as_remote_protocol_error
    raise self
  File "/home/partner_portal/virtual_env/lib/python3.8/site-packages/h11/_connection.py", line 425, in next_event
    event = self._extract_next_receive_event()
  File "/home/partner_portal/virtual_env/lib/python3.8/site-packages/h11/_connection.py", line 367, in _extract_next_receive_event
    event = self._reader(self._receive_buffer)
  File "/home/partner_portal/virtual_env/lib/python3.8/site-packages/h11/_readers.py", line 68, in maybe_read_from_IDLE_client
    raise LocalProtocolError("illegal request line")
h11._util.RemoteProtocolError: illegal request line
WARNING:  Invalid HTTP request received.
Traceback (most recent call last):
  File "/home/partner_portal/virtual_env/lib/python3.8/site-packages/uvicorn/protocols/http/h11_impl.py", line 136, in handle_events
    event = self.conn.next_event()
  File "/home/partner_portal/virtual_env/lib/python3.8/site-packages/h11/_connection.py", line 443, in next_event
    exc._reraise_as_remote_protocol_error()
  File "/home/partner_portal/virtual_env/lib/python3.8/site-packages/h11/_util.py", line 76, in _reraise_as_remote_protocol_error
    raise self
  File "/home/partner_portal/virtual_env/lib/python3.8/site-packages/h11/_connection.py", line 425, in next_event
    event = self._extract_next_receive_event()
  File "/home/partner_portal/virtual_env/lib/python3.8/site-packages/h11/_connection.py", line 367, in _extract_next_receive_event
    event = self._reader(self._receive_buffer)
  File "/home/partner_portal/virtual_env/lib/python3.8/site-packages/h11/_readers.py", line 68, in maybe_read_from_IDLE_client
    raise LocalProtocolError("illegal request line")
h11._util.RemoteProtocolError: illegal request line
WARNING:  Invalid HTTP request received.
Traceback (most recent call last):
  File "/home/partner_portal/virtual_env/lib/python3.8/site-packages/uvicorn/protocols/http/h11_impl.py", line 136, in handle_events
    event = self.conn.next_event()
  File "/home/partner_portal/virtual_env/lib/python3.8/site-packages/h11/_connection.py", line 443, in next_event
    exc._reraise_as_remote_protocol_error()
  File "/home/partner_portal/virtual_env/lib/python3.8/site-packages/h11/_util.py", line 76, in _reraise_as_remote_protocol_error
    raise self
  File "/home/partner_portal/virtual_env/lib/python3.8/site-packages/h11/_connection.py", line 425, in next_event
    event = self._extract_next_receive_event()
  File "/home/partner_portal/virtual_env/lib/python3.8/site-packages/h11/_connection.py", line 367, in _extract_next_receive_event
    event = self._reader(self._receive_buffer)
  File "/home/partner_portal/virtual_env/lib/python3.8/site-packages/h11/_readers.py", line 72, in maybe_read_from_IDLE_client
    matches = validate(
  File "/home/partner_portal/virtual_env/lib/python3.8/site-packages/h11/_util.py", line 88, in validate
    raise LocalProtocolError(msg)
h11._util.RemoteProtocolError: illegal request line: bytearray(b'OPTIONS sip:nm SIP/2.0')
INFO:     45.33.65.249:0 - "POST /scripts/WPnBr.dll HTTP/1.1" 404 Not Found
INFO:     45.33.65.249:0 - "GET / HTTP/1.1" 200 OK
INFO:     45.33.65.249:0 - "GET /docs/cplugError.html/ HTTP/1.1" 404 Not Found
INFO:     45.33.65.249:0 - "GET /Portal0000.htm HTTP/1.1" 404 Not Found
INFO:     45.33.65.249:0 - "GET / HTTP/1.1" 200 OK
INFO:     45.33.65.249:0 - "GET / HTTP/1.1" 200 OK
INFO:     45.33.65.249:0 - "GET /__Additional HTTP/1.1" 404 Not Found
INFO:     45.33.65.249:0 - "POST /sdk HTTP/1.1" 404 Not Found
INFO:     45.33.65.249:0 - "GET /favicon.ico HTTP/1.1" 404 Not Found
INFO:     109.237.103.38:0 - "GET /.env HTTP/1.1" 404 Not Found
INFO:     45.146.165.37:0 - "POST /mifs/.%3B/services/LogService HTTP/1.1" 404 Not Found
INFO:     178.73.215.171:0 - "GET / HTTP/1.1" 200 OK
INFO:     172.70.6.26:0 - "GET / HTTP/1.1" 200 OK
INFO:     172.70.6.26:0 - "GET / HTTP/1.1" 200 OK
INFO:     172.70.6.26:0 - "GET / HTTP/1.1" 200 OK
WARNING:  Invalid HTTP request received.
Traceback (most recent call last):
  File "/home/partner_portal/virtual_env/lib/python3.8/site-packages/uvicorn/protocols/http/h11_impl.py", line 136, in handle_events
    event = self.conn.next_event()
  File "/home/partner_portal/virtual_env/lib/python3.8/site-packages/h11/_connection.py", line 443, in next_event
    exc._reraise_as_remote_protocol_error()
  File "/home/partner_portal/virtual_env/lib/python3.8/site-packages/h11/_util.py", line 76, in _reraise_as_remote_protocol_error
    raise self
  File "/home/partner_portal/virtual_env/lib/python3.8/site-packages/h11/_connection.py", line 425, in next_event
    event = self._extract_next_receive_event()
  File "/home/partner_portal/virtual_env/lib/python3.8/site-packages/h11/_connection.py", line 367, in _extract_next_receive_event
    event = self._reader(self._receive_buffer)
  File "/home/partner_portal/virtual_env/lib/python3.8/site-packages/h11/_readers.py", line 68, in maybe_read_from_IDLE_client
    raise LocalProtocolError("illegal request line")
h11._util.RemoteProtocolError: illegal request line
INFO:     45.146.165.37:0 - "GET /_ignition/execute-solution HTTP/1.1" 404 Not Found
INFO:     192.241.217.228:0 - "GET /actuator/health HTTP/1.1" 404 Not Found
INFO:     45.154.255.147:0 - "GET / HTTP/1.1" 200 OK
INFO:     185.220.100.252:0 - "GET /favicon.ico HTTP/1.1" 404 Not Found
INFO:     45.148.10.241:52112 - "GET http%3A//example.com/ HTTP/1.1" 404 Not Found
INFO:     74.82.47.4:0 - "GET / HTTP/1.1" 200 OK
INFO:     45.146.165.37:0 - "GET / HTTP/1.1" 200 OK
INFO:     192.241.219.71:0 - "GET /owa/auth/x.js HTTP/1.1" 404 Not Found
INFO:     192.241.206.119:0 - "GET /owa/auth/logon.aspx HTTP/1.1" 404 Not Found
INFO:     192.241.217.91:0 - "GET /ecp/Current/exporttool/microsoft.exchange.ediscovery.exporttool.application HTTP/1.1" 404 Not Found
INFO:     20.37.7.26:0 - "GET /.env HTTP/1.1" 404 Not Found
INFO:     20.37.7.26:0 - "POST / HTTP/1.1" 405 Method Not Allowed
INFO:     103.39.242.253:0 - "OPTIONS /login HTTP/1.1" 200 OK
{'sub': 'd52f5c80-6ab4-489f-b2c4-c6bddd873da0'}
INFO:     103.39.242.253:0 - "POST /login HTTP/1.1" 200 OK
{'sub': 'd52f5c80-6ab4-489f-b2c4-c6bddd873da0'}
INFO:     103.39.242.253:0 - "POST /login HTTP/1.1" 200 OK
INFO:     188.166.87.67:0 - "GET / HTTP/1.1" 200 OK
INFO:     45.134.144.108:0 - "GET /remote/fgt_lang?lang=/../../../..//////////dev/ HTTP/1.1" 404 Not Found
INFO:     183.136.226.3:0 - "GET / HTTP/1.1" 200 OK
INFO:     183.136.226.3:0 - "GET /favicon.ico HTTP/1.1" 404 Not Found
INFO:     183.136.226.3:0 - "GET /robots.txt HTTP/1.1" 404 Not Found
